Workbook

Sheet サマリー
A1: SuguDesk 開発工数見積もり
A2: 2026年4月時点
D3: 0.6
A5: フェーズ | B5: 機能ID | C5: 機能名 | D5: 基礎工数 | E5: 工数 (人日) | F5: 備考
A6: P1 | B6: INF | C6: インフラ & 基盤 | D6: 11 | E6: =D6*$D$3 -> 6.6 | F6: GCP構築、CI/CD、DBスキーマ、監視、開発環境
A7: P1 | B7: F1-1 | C7: チャットWidget | D7: 30 | E7: =D7*$D$3 -> 18 | F7: RAGパイプライン、Widget UI、グループ院、会話分類
A8: P1 | B8: F1-2 | C8: テナント管理画面 | D8: 22 | E8: =D8*$D$3 -> 13.2 | F8: ダッシュボード、会話ログ、FAQ管理、Widget設定
A9: P1 | B9: F1-3 | C9: 社内管理画面 | D9: 12 | E9: =D9*$D$3 -> 7.2 | F9: テナント管理、クロステナント検索、プロンプト管理
A10: P1 | B10: F1-4 | C10: データ移行 | D10: 8 | E10: =D10*$D$3 -> 4.8 | F10: Dify→新基盤、カナリアリリース
A11: P1 | B11: EMB | C11: Embedding精度検証 | D11: 3 | E11: =D11*$D$3 -> 1.8 | F11: 新旧Embeddingモデル比較評価
A12: P1 | B12: QA | C12: テスト（IT・手動） | D12: 13 | E12: =D12*$D$3 -> 7.8 | F12: 統合テスト（Playwright E2E + バックエンドIT）、手動テスト
A13: P1 | B13: DOC | C13: ドキュメント | D13: 5 | E13: =D13*$D$3 -> 3 | F13: API仕様書（Swagger）、DBスキーマ、運用マニュアル、テスト報告
C14: Phase 1 合計 | D14: =SUM(D6:D13) -> 104 | E14: =D14*$D$3 -> 62.4
A16: P2 | B16: F2-1 | C16: セルフ改善アシスタント | D16: 12 | E16: =D16*$D$3 -> 7.2 | F16: 未回答リスト、AI推薦、効果可視化
A17: P2 | B17: F2-2 | C17: 品質改善パイプライン | D17: 13 | E17: =D17*$D$3 -> 7.8 | F17: 改善候補UI、ステータス管理、トレンド分析
A18: P2 | B18: F2-3 | C18: HPクロール→ベクトル化 | D18: 9 | E18: =D18*$D$3 -> 5.4 | F18: クロール方式3案から選定、レビュー・承認UI
A19: P2 | B19: F2-4 | C19: 自動レポートメール | D19: 6.5 | E19: =D19*$D$3 -> 3.9 | F19: Resend、Outbox配信管理、月次サマリー
A20: P2 | B20: F2-5 | C20: FAQページ自動生成 | D20: 8 | E20: =D20*$D$3 -> 4.8 | F20: 質問頻度ランキング、埋め込みHTML生成
A21: P2 | B21: QA | C21: テスト（IT・手動） | D21: 8 | E21: =D21*$D$3 -> 4.8 | F21: 統合テスト（Playwright E2E + バックエンドIT）、手動テスト
A22: P2 | B22: DOC | C22: ドキュメント更新 | D22: 1 | E22: =D22*$D$3 -> 0.6 | F22: Phase 2追加分のAPI仕様書・運用マニュアル追記
C23: Phase 2 合計 | D23: =SUM(D16:D22) -> 57.5 | E23: =D23*$D$3 -> 34.5
C25: 総合計 | D25: =D14+D23 -> 161.5 | E25: =E14+E23 -> 96.9
C26: 期間（1名） | D26: =TEXT(D25/20,"0.0")&"ヶ月" -> 8.1ヶ月 | E26: =TEXT(E25/20,"0.0")&"ヶ月" -> 4.8ヶ月
A28: 前提条件
A29: 1名のシニアフルスタックエンジニアによる開発（AI活用前提）
A30: バックエンド: C# (ASP.NET) on Cloud Run / フロントエンド: Next.js (TypeScript) on Vercel
A31: DB: Cloud SQL (PostgreSQL + pgvector) / 認証: Firebase Auth / AI: Vertex AI (Gemini Flash + Embedding)
A32: F1-2（テナント管理画面）とF1-3（社内管理画面）は1つのNext.jsアプリとして統合実装（impersonation方式）
A33: 成果物の最終スコープはクライアントと協議の上確定

Sheet Phase 1
A1: フェーズ | B1: 機能ID | C1: 機能名 | D1: 概要 | E1: 基礎工数 | F1: 工数 (人日) | G1: 要件との差分 | H1: リスク | I1: 備考
A2: P1 | C2: 共通基盤
A3: P1 | B3: INF | C3: インフラ & 基盤 | E3: 11 | F3: =E3*'サマリー'!$D$3 -> 6.6
A4: P1 | B4: INF-1 | C4: GCPプロジェクト設定 | D4: Cloud Run, Cloud SQL (PostgreSQL + pgvector), Cloud Load Balancing, Cloud Armor, Firebase Auth の構築 | E4: 3 | F4: 2
A5: P1 | B5: INF-2 | C5: CI/CD | D5: GitHub Actions → Cloud Run デプロイ、Vercel自動デプロイ。ステージング・本番の2環境 | E5: 2 | F5: 1
A6: P1 | B6: INF-3 | C6: DBスキーマ設計 | D6: マルチテナント対応スキーマ設計（Drizzle ORM）。テナント、クリニック、FAQ、会話ログ、分類結果、システムプロンプト、Widget設定等。pgvector拡張セットアップ | E6: 3 | F6: 2
A7: P1 | B7: INF-4 | C7: 監視設定 | D7: Sentry統合（エラートラッキング）、Cloud Monitoring / Logging、Uptime Check（死活監視） | E7: 1.5 | F7: 0.5
A8: P1 | B8: INF-5 | C8: ローカル開発環境 | D8: Docker Compose: PostgreSQL + pgvector のローカル環境構築 | E8: 1.5 | F8: 1
A9: P1 | C9: F1-1: チャットWidget
A10: P1 | B10: F1-1 | C10: チャットWidget | E10: 30 | F10: =E10*'サマリー'!$D$3 -> 18
A11: P1 | B11: F1-1-1 | C11: チャットAPI（RAGパイプライン） | D11: Vertex AI Embeddingによるベクトル検索、Gemini Flashによる回答生成、SSEストリーミング、会話履歴管理（直近3-5ターン）、診断ログ記録（normalized_query, retrieved_faqs, selected_faq_id, is_phone_escalation, escalation_reason）、テナント認証（widget_key）、レート制限（テナント/IP単位）、フォールバック処理（FAQ未ヒット時の電話誘導）、システムプロンプト適用（診療科テンプレート+テナント別カスタマイズ） | E11: 14 | F11: =E11*'サマリー'!$D$3 -> 8.4 | G11: ① 2段階LLM→1段階に変更。理由: 正規化LLM呼び出しで200-500msのレイテンシ増+APIコスト増。Embeddingモデルの性能上、生クエリで十分な検索精度が見込める。必要時に後追加可能 ② セッション管理→クライアントメモリ方式（サーバーステートレス）。理由: 医療系のため患者入力がlocalStorage等に残るリスクを回避。業界標準方式（Intercom/Tidio等） | H11: SSE + Cloud LB + Cloud Armorの組み合わせでタイムアウト・バッファリング問題が発生する可能性あり（+2-3日） | I11: Vertex AI Embedding精度検証は別途計上
A12: P1 | B12: F1-1-2 | C12: チャットWidget UI | D12: scriptタグ+iframeによる埋め込み（CSS完全分離）、フローティングボタン→チャット画面展開、メッセージリスト+入力エリア、SSEストリーミング表示、テーマカスタマイズ（テーマカラー・アイコン画像）、クイックリプライボタン（初回表示の選択肢）、オープニングメッセージ、AI免責文・利用規約・プライバシーポリシー表示、フォールバック時の電話番号表示、モバイル対応 | E12: 10 | F12: =E12*'サマリー'!$D$3 -> 6 | G12: 「Shadow DOM or iframe」→ scriptタグ+iframeハイブリッド方式に決定。理由: Intercom/Drift/Crisp等の業界標準方式。CSS分離が完全でクリニックサイト（WordPress/Wix/独自CMS等）との干渉リスクがゼロ。設置もscriptタグ1行で完了 | H12: 一部CMSのiframe制限、モバイルでのposition:fixed挙動差、z-index競合等の環境依存問題（+1-2日） | I12: 3-5件のクリニックサイトでの実機検証が必要
A13: P1 | B13: F1-1-3 | C13: グループ院対応 | D13: チャット開始時に院選択フロー（ボタン形式）、選択された院に応じてFAQ検索対象を切り替え、院未選択の場合は共通FAQで回答または院選択を促す | E13: 3 | F13: =E13*'サマリー'!$D$3 -> 1.8 | I13: 既存テナントで稼働中のためPhase 1必須
A14: P1 | B14: F1-1-4 | C14: 会話分類（自動） | D14: 回答生成後にLLMで自動分類: トピック、メニューカテゴリ、改善アクション（正常回答/FAQ追加/FAQ修正/対応不要/診察誘導）、優先度（high/medium/low）、メモ。Outboxテーブルに書き込み→Cloud Scheduler + Cloud Run Jobsでバッチ分類 | E14: 3 | F14: =E14*'サマリー'!$D$3 -> 1.8 | G14: 要件ではPhase 2（F2-2）の範囲だが、Phase 1に移動。理由: 現行Difyワークフロー内でLLMが実行中の機能であり、Phase 1は現行リプレイスのため必須。ダッシュボードの集計・会話ログの分類結果表示に使用 | I14: 分類プロンプトは既存Difyワークフローのロジックを移植。分類タイミング（都度/会話終了時）は要クライアント確認
A15: P1 | C15: F1-2: テナント管理画面（顧客向け）
A16: P1 | B16: F1-2 | C16: テナント管理画面 | E16: 22 | F16: =E16*'サマリー'!$D$3 -> 13.2
A17: P1 | B17: F1-2-1 | C17: 認証 + マルチテナント | D17: Firebase Auth（メールアドレス+パスワード）、ログイン/ログアウト/セッション管理、RBAC（Admin/Tenant Admin/Tenant User）、impersonation機能（exmoreがテナントとして閲覧） | E17: 3 | F17: 2 | G17: F1-2とF1-3を1つのNext.jsアプリに統合（impersonation方式）。理由: 共通コンポーネント（ログ閲覧、FAQ表示等）の二重実装を回避。exmoreがテナントと同じ画面で確認可能 | I17: テナント側Admin/Userの権限区分は要クライアント確認
A18: P1 | B18: F1-2-2 | C18: ダッシュボード | D18: KPIカード（利用人数、総チャット件数、電話誘導件数、自己解決率）、日別会話数チャート、時間別会話数チャート、トピック分布、メニューカテゴリ分布、院別会話数、改善アクション内訳、優先度分布、期間フィルタ（直近7日/14日/30日/全期間） | E18: 6 | F18: 3 | I18: 既存Google Sheets管理画面の再現。データソースをCloud SQLに変更
A19: P1 | B19: F1-2-3 | C19: 会話ログ閲覧 | D19: 会話一覧（日付・クリニック名・質問プレビュー）、キーワード検索、フィルタ（すべて/電話誘導/要改善/正常）、会話詳細表示（ユーザー質問+ボット回答）、分類結果パネル（トピック/メニュー/メモ/電話誘導/改善アクション/優先度）、CSVエクスポート、期間フィルタ | E19: 5 | F19: =E19*'サマリー'!$D$3 -> 3 | I19: 既存管理画面の会話ログ画面を再現
A20: P1 | B20: F1-2-4 | C20: FAQ管理 | D20: FAQ一覧表示（質問・回答・ソース・更新日時）、FAQ追加（質問+回答入力→保存時にベクトル自動生成→DB即反映）、FAQ編集（保存時にベクトル再生成）、FAQ削除（論理削除）、ソース区別（crawled/manual）、CSVインポート・エクスポート | E20: 5 | F20: =E20*'サマリー'!$D$3 -> 3 | I20: ベクトル生成はVertex AI Embedding API呼び出し（保存時2-3秒）
A21: P1 | B21: F1-2-5 | C21: Widget設定 | D21: オープニングメッセージ、アイコン画像アップロード、テーマカラー、選択肢ボタン（クイックリプライ）設定、フォールバック電話番号、グループ院の場合: 院選択フローの選択肢設定 | E21: 3 | F21: =E21*'サマリー'!$D$3 -> 1.8
A22: P1 | C22: F1-3: 社内管理画面（exmore向け）
A23: P1 | B23: F1-3 | C23: 社内管理画面 | E23: 12 | F23: =E23*'サマリー'!$D$3 -> 7.2
A24: P1 | B24: F1-3-1 | C24: テナント管理 | D24: テナント新規作成・編集・一覧・検索、プラン変更、Widget Key発行、埋め込みタグコピー、グループ院: 親テナントの下に子テナントを作成・管理 | E24: 4 | F24: 3
A25: P1 | B25: F1-3-2 | C25: クロステナントログ検索 | D25: 全テナントのチャットログを横断検索（診断情報・分類結果付き）、CSVエクスポート | E25: 3 | F25: =E25*'サマリー'!$D$3 -> 1.8
A26: P1 | B26: F1-3-3 | C26: システムプロンプト管理 | D26: 診療科別テンプレートの追加・編集（産婦人科/皮膚科/歯科等）、テンプレート変更時に影響するテナント一覧の表示、テナントごとの設定: テンプレート選択、テナント情報の入力（クリニック名・営業時間・電話番号等）→自動挿入、テナント個別指示の編集（自由記述）、テナント個別指示の横断検索 | E26: 5 | F26: =E26*'サマリー'!$D$3 -> 3 | I26: テンプレートの具体的な内容（診療科ごとの差分）は要クライアント確認
A27: P1 | C27: F1-4: データ移行
A28: P1 | B28: F1-4 | C28: データ移行 | E28: 8 | F28: =E28*'サマリー'!$D$3 -> 4.8
A29: P1 | B29: F1-4-1 | C29: 移行スクリプト開発 | D29: 対象: 既存院のFAQデータ、チャットログ（分類結果含む）、システムプロンプト。方法: Difyエクスポート→CSV/JSON→新DB投入スクリプト。プロンプト移植: 既存プロンプト設計を新基盤テンプレートとして移植 | E29: 3 | F29: =E29*'サマリー'!$D$3 -> 1.8 | I29: Difyアクセス権取得後に調査開始
A30: P1 | B30: F1-4-2 | C30: データ検証・テスト | D30: 移行データの整合性チェック（FAQ件数一致、ベクトル再生成、分類データ照合）、移行後の回答品質テスト | E30: 2 | F30: =E30*'サマリー'!$D$3 -> 1.2
A31: P1 | B31: F1-4-3 | C31: Widget切り替え（カナリアリリース） | D31: 1院で新基盤のWidgetに切り替え→数日〜1週間の品質確認→問題なければ残りの院も順次展開 | E31: 3 | F31: =E31*'サマリー'!$D$3 -> 1.8 | G31: 要件では「並行稼働の要否→要検討」だが、院単位のカナリアリリースを必須とする。理由: サービス中のクリニックがあり、一発切り替えは品質・安定性のリスクが高い
A32: P1 | C32: その他
A33: P1 | B33: EMB | C33: Embedding精度検証 | E33: 3 | F33: =E33*'サマリー'!$D$3 -> 1.8
A34: P1 | B34: EMB-1 | C34: 新旧Embedding比較評価 | D34: 既存FAQデータ+会話ログを使用し、Dify（OpenAI Embedding）→ Vertex AI Embedding (text-embedding-004)への移行で検索精度がどう変化するかを評価。top-k結果の比較、類似度閾値の最適化 | E34: 3 | F34: =E34*'サマリー'!$D$3 -> 1.8 | H34: Embedding精度が想定以下の場合、チューニング工数が追加で発生（+5-10日）
A35: P1 | C35: テスト
A36: P1 | B36: QA | C36: テスト | E36: 13 | F36: =E36*'サマリー'!$D$3 -> 7.8
A37: P1 | B37: QA-1 | C37: 統合テスト（IT） | D37: Playwright E2E: Widget（ロード・送信・SSE受信・クイックリプライ・グループ院選択・モバイル）、ダッシュボード、会話ログ、FAQ管理、Widget設定、管理画面（テナントCRUD・impersonation・プロンプト管理）、認証/RBACフロー バックエンドIT: RAGパイプライン一気通貫、SSEストリーミング、テナント間データ分離、分類パイプライン（Outbox→分類） | E37: 8 | F37: =E37*'サマリー'!$D$3 -> 4.8 | I37: UTは各機能の工数に含む
A38: P1 | B38: QA-2 | C38: 手動テスト | D38: クロスブラウザ（Chrome/Safari/Edge）、モバイル（iOS/Android）、クリニックサイト実機検証（3-5件）、データ移行後の回答品質テスト | E38: 5 | F38: =E38*'サマリー'!$D$3 -> 3
A39: P1 | C39: 成果物（ドキュメント）
A40: P1 | B40: DOC | C40: ドキュメント | E40: 5 | F40: =E40*'サマリー'!$D$3 -> 3
...

Sheet Phase 2
A1: フェーズ | B1: 機能ID | C1: 機能名 | D1: 概要 | E1: 基礎工数 | F1: 工数 (人日) | G1: 要件との差分 | H1: リスク | I1: 備考
A2: P2 | C2: F2-1: セルフ改善アシスタント（顧客向け）
A3: P2 | B3: F2-1 | C3: セルフ改善アシスタント | E3: 12 | F3: =E3*'サマリー'!$D$3 -> 7.2
A4: P2 | B4: F2-1-1 | C4: 未回答質問リスト | D4: 電話誘導になった質問の一覧を自動表示。is_phone_escalationフラグによる自動検出、escalation_reason別の表示、フィルタ・ソート・ページネーション | E4: 3 | F4: =E4*'サマリー'!$D$3 -> 1.8
A5: P2 | B5: F2-1-2 | C5: AI推薦エンジン + ワンクリック導線 | D5: 各未回答質問にAIが推奨アクションを自動判定:「このFAQを追加」（回答ドラフト付き）/「既存FAQを修正」（修正案付き）/「対応不要（電話が正しい）」。ワンクリックでFAQ追加/編集画面へ遷移（ドラフト入力済み） | E5: 5 | F5: =E5*'サマリー'!$D$3 -> 3 | H5: AI判定の精度はプロンプトチューニングに依存。反復的な改善工数が発生する可能性あり | I5: Phase 1の分類エンジン（chat_logs診断情報）を基盤として利用
A6: P2 | B6: F2-1-3 | C6: 改善効果の可視化 | D6: 先月と今月の自己解決率の比較チャート、FAQ追加後に同じ質問が解決されるようになったかのトラッキング（embedding類似度による同種質問追跡） | E6: 4 | F6: =E6*'サマリー'!$D$3 -> 2.4 | H6: 同種質問の判定精度（embedding類似度閾値）のチューニングが必要
A7: P2 | C7: F2-2: 品質改善パイプライン（exmore向け）
A8: P2 | B8: F2-2 | C8: 品質改善パイプライン | E8: 13 | F8: =E8*'サマリー'!$D$3 -> 7.8
A9: P2 | B9: F2-2-1 | C9: 改善候補一覧UI | D9: 改善候補一覧（フィルタ: 未対応/対応済み、優先度、アクション種別、テナント）、一括操作、FAQ追加/修正→FAQ管理画面へ遷移、プロンプト修正→プロンプト設定画面へ遷移 | E9: 4 | F9: =E9*'サマリー'!$D$3 -> 2.4 | G9: 分類エンジンはPhase 1で実装済み（F1-1-4）のため、Phase 2ではUI+ワークフローのみ
A10: P2 | B10: F2-2-2 | C10: ステータスワークフロー | D10: ステータス管理（未対応→CS対応中→先方確認中→実施済み/対応不要）、ステータス遷移の権限管理 | E10: 3 | F10: =E10*'サマリー'!$D$3 -> 1.8
A11: P2 | B11: F2-2-3 | C11: クロステナントトレンド分析 | D11: 全テナント横断で傾向を把握（どの診療科でどんな質問が多く電話誘導されているか）、集計チャート・ダッシュボード | E11: 3 | F11: =E11*'サマリー'!$D$3 -> 1.8
A12: P2 | B12: F2-2-4 | C12: バッチ処理基盤 | D12: Cloud Scheduler + Cloud Run Jobsによる日次/週次の集計バッチ。ダッシュボード用の集計データ更新、未対応件数の通知等 | E12: 3 | F12: =E12*'サマリー'!$D$3 -> 1.8
A13: P2 | C13: F2-3: HPクロール→ベクトル化（exmore向け）
A14: P2 | B14: F2-3 | C14: HPクロール→ベクトル化 | E14: 9 | F14: =E14*'サマリー'!$D$3 -> 5.4
A15: P2 | B15: F2-3-1 | C15: クロールパイプライン | D15: HP URL→ページ内容取得→FAQ候補を自動生成。方式は以下3案から選定: ① Firecrawl + Gemini: 開発工数最小（2日）、SPA対応、メンテ不要。外部依存あり、月500ページ超は$0.01/ページ ② 自前Playwright: 外部依存なし、ランニングコスト安い。開発・メンテ工数大（5-7日）、SPA対応チューニングが手間 ③ Claude Code CLI + Skill: サブスク内で完結、追加コストなし、AI活用で精度高い。手動実行、CLI環境が必要（3-4日） | E15: 3 | F15: =E15*'サマリー'!$D$3 -> 1.8 | G15: カスタムクローラー（Playwright等）ではなく、SaaS or CLIベースの方式を推奨。理由: クリニックサイトの多様性（WordPress/Wix/SPA等）への対応力が高い | H15: 方式選定により工数が2-7日の幅で変動 | I15: 方式はPhase 2開始時に確定
A16: P2 | B16: F2-3-2 | C16: FAQレビュー・承認UI | D16: 自動生成されたFAQ候補の一覧表示、承認/編集/却下の操作、承認時にFAQとして登録（ベクトル自動生成）。LLMの信頼度スコアによる自動承認も導入可能（高信頼度→自動登録、中→人間レビュー、低→自動却下） | E16: 3 | F16: =E16*'サマリー'!$D$3 -> 1.8 | G16: 要件に生成FAQのレビュー・承認フローの記載がないが追加。理由: 自動生成をそのまま公開するのは品質リスクが高い | I16: 信頼度閾値は運用しながら調整
A17: P2 | B17: F2-3-3 | C17: 再クロール・差分検出 | D17: 定期的な再クロール（月次等）、コンテンツ変更の差分検出、既存FAQとの整合性管理、変更があった場合の通知 | E17: 3 | F17: =E17*'サマリー'!$D$3 -> 1.8
A18: P2 | C18: F2-4: 自動レポートメール（顧客向け）
A19: P2 | B19: F2-4 | C19: 自動レポートメール | E19: 6.5 | F19: =E19*'サマリー'!$D$3 -> 3.9
A20: P2 | B20: F2-4-1 | C20: メール配信基盤 | D20: Resendセットアップ、SPF/DKIM/DMARC設定 | E20: 1 | F20: =E20*'サマリー'!$D$3 -> 0.6
A21: P2 | B21: F2-4-2 | C21: 月次集計バッチ | D21: チャット件数、解決率、TOP5質問、未回答リストのサマリーを月次で集計 | E21: 1.5 | F21: =E21*'サマリー'!$D$3 -> 0.9
A22: P2 | B22: F2-4-3 | C22: HTMLメールテンプレート | D22: Resendにテンプレート登録、メールクライアント互換性対応 | E22: 2 | F22: =E22*'サマリー'!$D$3 -> 1.2 | I22: HTMLメールのレンダリング互換性テストに工数がかかる傾向あり
A23: P2 | B23: F2-4-4 | C23: 配信管理 | D23: Outboxパターンによる配信管理（pending→sent/failed）、Resend Webhook連携（email.delivered/email.bounced）による到達確認、失敗時リトライ、Cloud Schedulerによる月次スケジュール実行、セルフ改善アシスタント（F2-1）へのディープリンク | E23: 2 | F23: =E23*'サマリー'!$D$3 -> 1.2
A24: P2 | C24: F2-5: よくある質問ページ自動生成（顧客向け）
A25: P2 | B25: F2-5 | C25: FAQページ自動生成 | E25: 8 | F25: =E25*'サマリー'!$D$3 -> 4.8
A26: P2 | B26: F2-5-1 | C26: 質問頻度ランキング | D26: チャットログの質問頻度で集計、embedding類似度による同義質問の名寄せ（クラスタリング）、上位10-20問を抽出 | E26: 3 | F26: =E26*'サマリー'!$D$3 -> 1.8
A27: P2 | B27: F2-5-2 | C27: HTML生成 | D27: テンプレートエンジンによるFAQページHTML生成、FAQ Schema（構造化データ）対応、テナント別デザインカスタマイズ | E27: 2.5 | F27: =E27*'サマリー'!$D$3 -> 1.5 | I27: SEO効果の測定は別途検討が必要
A28: P2 | B28: F2-5-3 | C28: 埋め込み出力 | D28: クリニックHPに埋め込み可能なJavaScriptローダー方式（Phase 1チャットWidgetと同様のパターン）で配信 | E28: 1.5 | F28: =E28*'サマリー'!$D$3 -> 0.9
A29: P2 | B29: F2-5-4 | C29: バッチ + 手動トリガー | D29: 月次バッチまたは手動トリガーで再生成 | E29: 1 | F29: =E29*'サマリー'!$D$3 -> 0.6
A30: P2 | C30: テスト
A31: P2 | B31: QA | C31: テスト | E31: 8 | F31: =E31*'サマリー'!$D$3 -> 4.8
A32: P2 | B32: QA-1 | C32: 統合テスト（IT） | D32: Playwright E2E: セルフ改善アシスタント↔FAQ CRUD連携、品質パイプラインのステータスワークフロー、メール配信フロー、FAQページ生成 バックエンドIT: バッチ処理、Outbox→Resend連携、Webhook受信 | E32: 5 | F32: =E32*'サマリー'!$D$3 -> 3 | I32: UTは各機能の工数に含む
A33: P2 | B33: QA-2 | C33: 手動テスト | D33: AI推薦の精度検証、クロステナント分析の正確性確認、メールクライアント互換性テスト、FAQページのSEO構造化データ検証 | E33: 3 | F33: 3
A34: P2 | C34: 成果物（ドキュメント）
A35: P2 | B35: DOC | C35: ドキュメント更新 | E35: 1 | F35: =E35*'サマリー'!$D$3 -> 0.6
A36: P2 | B36: DOC-1 | C36: 既存ドキュメント更新 | D36: Phase 2追加機能分のAPI仕様書・運用マニュアル追記 | E36: 1 | F36: =E36*'サマリー'!$D$3 -> 0.6
C38: Phase 2 合計 | E38: 57.5 | F38: =E38*'サマリー'!$D$3 -> 34.5

Sheet 技術スタック
A1: カテゴリ | B1: 技術 | C1: 用途・備考
A2: バックエンド | B2: C# / ASP.NET | C2: チャットAPI（Cloud Run上で稼働）、RAGパイプライン、SSEストリーミング
A3: フロントエンド | B3: Next.js / TypeScript | C3: テナント管理画面 + 社内管理画面（Vercel上で稼働）
A4: チャットWidget | B4: TypeScript | C4: scriptタグ+iframeハイブリッド方式（CDN配信）
A5: データベース | B5: Cloud SQL (PostgreSQL) | C5: FAQ、会話ログ、テナント情報、分類結果等
A6: ベクトル検索 | B6: pgvector | C6: PostgreSQL拡張。FAQのベクトル格納・類似度検索
A7: LLM（回答生成） | B7: Vertex AI Gemini Flash | C7: RAG回答生成、会話分類
A8: Embedding | B8: Vertex AI Embedding (text-embedding-004) | C8: FAQベクトル化、クエリベクトル化。将来的にRuri移行の可能性あり
A9: 認証 | B9: Firebase Authentication | C9: メール+パスワード認証、RBAC（Admin/Tenant Admin/Tenant User）
A10: WAF / DDoS対策 | B10: Cloud Armor | C10: Cloud LB前段に配置、WAFルール適用
A11: ロードバランサー | B11: Cloud Load Balancing | C11: Cloud Armor適用の前提、SSL終端
A12: UIライブラリ | B12: shadcn/ui + Tailwind CSS | C12: 管理画面のUIコンポーネント
... A22: 非同期処理 | B22: Cloud Scheduler + Cloud Run Jobs | C22: 会話分類バッチ、月次集計、レポート配信

Sheet 確認事項
A1: # | B1: 関連機能 | C1: 確認事項 | D1: 背景・理由 | E1: ステータス | F1: 回答
A2: 1 | B2: F1-2-1 | C2: テナント側Admin/Userの権限区分 | D2: テナント側で複数ユーザーが操作する前提だが、Admin/Userで権限をどう分けるか（閲覧のみ？FAQ編集可？）が未定義。RBACの設計に影響 | E2: 未確認
A3: 2 | B3: F1-2-2 | C3: 既存Google Sheets管理画面の項目網羅性 | D3: 現行ダッシュボードのスクリーンショットは取得済みだが、見えていない画面・機能がないか確認が必要 | E3: 未確認
A4: 3 | B4: F1-1-4 | C4: 会話分類のタイミング（都度 or 会話終了時） | D4: 現行Difyでは回答の都度か会話終了時か。タイミングによりOutboxバッチの設計が変わる。会話終了時ならOutbox+バッチ方式が最適 | E4: 未確認
A5: 4 | B5: F1-3-3 | C5: システムプロンプトテンプレートの具体的な内容（診療科ごとの差分） | D5: 産婦人科以外のテンプレートは未作成の可能性あり。現時点でどの診療科のテンプレートが必要か、差分の具体的な内容を確認 | E5: 未確認
A6: 5 | B6: F1-3-1 | C6: 決済・請求の仕組み | D6: 要件に決済・請求の記載がない。プラン変更はDBフラグ変更のみの想定。Stripe等のシステム化が必要な場合は別途見積もり | E6: 未確認
A7: 6 | B7: F1-4 | C7: 会話ログの移行範囲 | D7: 全期間のログを移行するか、直近Nヶ月に絞るか。データ量により移行スクリプトの工数・Cloud SQLのストレージコストに影響 | E7: 未確認
A8: 7 | B8: 全体 | C8: レスポンスタイム・可用性のSLA目標 | D8: First Token までの目標時間、月間稼働率（99.9%等）、RPO/RTOが未定義。Cloud Runの常時起動（コスト増）vsコールドスタート許容の判断に影響 | E8: 未確認
A9: 8 | B9: F1-1-1 | C9: テナントあたりの月間リクエスト上限（プラン別） | D9: 公開APIのレート制限設計に必要。Lite/Standard/Premiumで上限を分けるか。上限なしだとVertex AI課金爆発リスクあり | E9: 未確認
A10: 9 | B10: F1-1-2 | C10: Widget埋め込み先クリニックサイトの技術スタック | D10: WordPress/Wix/独自CMS等。iframe方式で基本的には問題ないが、一部CMSのiframe制限を事前に把握したい | E10: 未確認
A11: 10 | B11: F1-2-1 | C11: 既存Next.jsコードベースのアクセス権 | D11: 非エンジニアがバイブコーディングで作成したもの。参考として活用可能かコード品質を確認したい | E11: 未確認
A12: 11 | B12: F2-5 | C12: FAQページ自動生成の目的と期待効果 | D12: SEO目的の場合、埋め込みスクリプト（iframe）では検索エンジンにインデックスされにくく効果が限定的。目的に応じて実装方式を検討 | E12: 未確認
A13: 12 | B13: F1-1-1 | C13: ログ保持期間・データ削除ポリシー | D13: 医療系チャットボットのため患者の症状記述がログに残る可能性あり。保持期間・PII取り扱いポリシーの確認が必要。Cloud SQLストレージコストにも影響 | E13: 未確認
A14: 13 | B14: 全体 | C14: 非機能要件（同時接続数の想定） | D14: ピーク時の同時接続数によりCloud Runのインスタンス数・スペック設定が変わる。コスト試算にも影響 | E14: 未確認
