Workbook

Sheet 前提
A1: SuguDesk 事業計画 前提条件
A3: 【価格前提】
A4: SuguDesk ARPA（月額） | B4: 11500 | C4: チャットボット基本（ライトとスタンダードの平均）
A5: SuguDesk 導入費（初期） | B5: 225000 | C5: 1院あたり（ライトとスタンダードの平均）
A6: BPO事務長代行 ARPA（月額） | B6: 150000 | C6: 算定業務＋事務長代行
A7: BPO採用/集患 ARPA（月額） | B7: 50000 | C7: BPO#2。M13以降
A8: SuguDeskチャーン率（月次） | B8: 0.02
A9: BPOチャーン率（月次） | B9: 0.01 | C9: 粘着性高い
A10: BPOアップセル率（月次） | B10: 0.05 | C10: SuguDesk→BPO転換率。M7以降
A12: 【営業前提：月間新規SuguDesk契約数】
A13: Phase1（M1-M6） | B13: 2 | C13: 直販
A14: Phase2（M7-M12） | B14: 5 | C14: v2リリース後 ギミックとの提携加速
A15: Phase3（M13-M18） | B15: 5
A16: Phase4（M19-M24） | B16: 6 | C16: Series A前
A17: Phase5（M25-M36） | B17: 8 | C17: Series A後
A18: Phase6（M37-M48） | B18: 10 | C18: スケール期
A19: Phase7（M49-M60） | B19: 12 | C19: 成熟期
A21: 【コスト前提：人件費（月額）】
A22: CEO報酬 | B22: 300000
A23: エンジニア時給 | B23: 5000 | C23: 業務委託
A24: エンジニア月間稼働h（Phase1） | B24: 64.5 | C24: 3h/日×5日×4.3週
A25: エンジニア月間稼働h（Phase2+） | B25: 40 | C25: メンテナンスモード
A26: エンジニア正社員 単価/人（月額） | B26: 700000
A27: BPO事務長 単価/人（月額） | B27: 400000
A28: BPOオペ 単価/人（月額） | B28: 200000
A29: 営業サポート 単価/人（月額） | B29: 200000 | C29: 業務委託
A30: CS 単価/人（月額） | B30: 350000 | C30: 業務委託
A31: 営業/GTM費（月額基準） | B31: 100000
A32: その他固定費 | B32: 200000 | C32: 法務・会計・雑費
A34: 【コスト前提：インフラ（実績ベース）】
A35: LLM API変動費/院（月額） | B35: 12 | C35: Vertex AI Gemini Flash実績
A36: Cloud SQL 基本料金（月額） | B36: 8000 | C36: 〜50院
A37: Cloud SQL 拡張料金（月額） | B37: 15000 | C37: 50〜200院
A38: Cloud SQL 大規模料金（月額） | B38: 25000 | C38: 200院超
A39: Cloud Run 基本料金（月額） | B39: 2000 | C39: 〜50院
A40: Cloud Run 拡張料金（月額） | B40: 5000 | C40: 50〜200院
A41: Cloud Run 大規模料金（月額） | B41: 15000 | C41: 200院超
A43: 【人員スケーリング前提】
A44: CS 1人あたり担当SuguDesk院数上限 | B44: 30
A46: 【エンジニア人員計画（人数）】 | B46: エンジニア
...

Sheet 月次事業計画
A1: 月次事業計画（5年）
A2: フェーズ | B2: =IF(1<=6,"P1",IF(1<=12,"P2",IF(1<=18,"P3",IF(1<=24,"P4",IF(1<=36,"P5",IF(1<=48,"P6","P7")))))) -> P1 | C2: =IF(2<=6,"P1",IF(2<=12,"P2",IF(2<=18,"P3",IF(2<=24,"P4",IF(2<=36,"P5",IF(2<=48,"P6","P7")))))) -> P1 | D2: =IF(3<=6,"P1",IF(3<=12,"P2",IF(3<=18,"P3",IF(3<=24,"P4",IF(3<=36,"P5",IF(3<=48,"P6","P7")))))) -> P1 | E2: =IF(4<=6,"P1",IF(4<=12,"P2",IF(4<=18,"P3",IF(4<=24,"P4",IF(4<=36,"P5",IF(4<=48,"P6","P7")))))) -> P1 | F2: =IF(5<=6,"P1",IF(5<=12,"P2",IF(5<=18,"P3",IF(5<=24,"P4",IF(5<=36,"P5",IF(5<=48,"P6","P7")))))) -> P1 | G2: =IF(6<=6,"P1",IF(6<=12,"P2",IF(6<=18,"P3",IF(6<=24,"P4",IF(6<=36,"P5",IF(6<=48,"P6","P7")))))) -> P1 | H2: =IF(7<=6,"P1",IF(7<=12,"P2",IF(7<=18,"P3",IF(7<=24,"P4",IF(7<=36,"P5",IF(7<=48,"P6","P7")))))) -> P2 | I2: =IF(8<=6,"P1",IF(8<=12,"P2",IF(8<=18,"P3",IF(8<=24,"P4",IF(8<=36,"P5",IF(8<=48,"P6","P7")))))) -> P2 | J2: =IF(9<=6,"P1",IF(9<=12,"P2",IF(9<=18,"P3",IF(9<=24,"P4",IF(9<=36,"P5",IF(9<=48,"P6","P7")))))) -> P2 | K2: =IF(10<=6,"P1",IF(10<=12,"P2",IF(10<=18,"P3",IF(10<=24,"P4",IF(10<=36,"P5",IF(10<=48,"P6","P7")))))) -> P2 | L2: =IF(11<=6,"P1",IF(11<=12,"P2",IF(11<=18,"P3",IF(11<=24,"P4",IF(11<=36,"P5",IF(11<=48,"P6","P7")))))) -> P2 | M2: =IF(12<=6,"P1",IF(12<=12,"P2",IF(12<=18,"P3",IF(12<=24,"P4",IF(12<=36,"P5",IF(12<=48,"P6","P7")))))) -> P2 | N2: =IF(13<=6,"P1",IF(13<=12,"P2",IF(13<=18,"P3",IF(13<=24,"P4",IF(13<=36,"P5",IF(13<=48,"P6","P7")))))) -> P3 | O2: =IF(14<=6,"P1",IF(14<=12,"P2",IF(14<=18,"P3",IF(14<=24,"P4",IF(14<=36,"P5",IF(14<=48,"P6","P7")))))) -> P3 | P2: =IF(15<=6,"P1",IF(15<=12,"P2",IF(15<=18,"P3",IF(15<=24,"P4",IF(15<=36,"P5",IF(15<=48,"P6","P7")))))) -> P3 | Q2: =IF(16<=6,"P1",IF(16<=12,"P2",IF(16<=18,"P3",IF(16<=24,"P4",IF(16<=36,"P5",IF(16<=48,"P6","P7")))))) -> P3 | R2: =IF(17<=6,"P1",IF(17<=12,"P2",IF(17<=18,"P3",IF(17<=24,"P4",IF(17<=36,"P5",IF(17<=48,"P6","P7")))))) -> P3 | S2: =IF(18<=6,"P1",IF(18<=12,"P2",IF(18<=18,"P3",IF(18<=24,"P4",IF(18<=36,"P5",IF(18<=48,"P6","P7")))))) -> P3 | T2: =IF(19<=6,"P1",IF(19<=12,"P2",IF(19<=18,"P3",IF(19<=24,"P4",IF(19<=36,"P5",IF(19<=48,"P6","P7")))))) -> P4 | U2: =IF(20<=6,"P1",IF(20<=12,"P2",IF(20<=18,"P3",IF(20<=24,"P4",IF(20<=36,"P5",IF(20<=48,"P6","P7")))))) -> P4 | V2: =IF(21<=6,"P1",IF(21<=12,"P2",IF(21<=18,"P3",IF(21<=24,"P4",IF(21<=36,"P5",IF(21<=48,"P6","P7")))))) -> P4 | W2: =IF(22<=6,"P1",IF(22<=12,"P2",IF(22<=18,"P3",IF(22<=24,"P4",IF(22<=36,"P5",IF(22<=48,"P6","P7")))))) -> P4 | X2: =IF(23<=6,"P1",IF(23<=12,"P2",IF(23<=18,"P3",IF(23<=24,"P4",IF(23<=36,"P5",IF(23<=48,"P6","P7")))))) -> P4 | Y2: =IF(24<=6,"P1",IF(24<=12,"P2",IF(24<=18,"P3",IF(24<=24,"P4",IF(24<=36,"P5",IF(24<=48,"P6","P7")))))) -> P4 | Z2: =IF(25<=6,"P1",IF(25<=12,"P2",IF(25<=18,"P3",IF(25<=24,"P4",IF(25<=36,"P5",IF(25<=48,"P6","P7")))))) -> P5 | AA2: =IF(26<=6,"P1",IF(26<=12,"P2",IF(26<=18,"P3",IF(26<=24,"P4",IF(26<=36,"P5",IF(26<=48,"P6","P7")))))) -> P5 | AB2: =IF(27<=6,"P1",IF(27<=12,"P2",IF(27<=18,"P3",IF(27<=24,"P4",IF(27<=36,"P5",IF(27<=48,"P6","P7")))))) -> P5 | AC2: =IF(28<=6,"P1",IF(28<=12,"P2",IF(28<=18,"P3",IF(28<=24,"P4",IF(28<=36,"P5",IF(28<=48,"P6","P7")))))) -> P5 | AD2: =IF(29<=6,"P1",IF(29<=12,"P2",IF(29<=18,"P3",IF(29<=24,"P4",IF(29<=36,"P5",IF(29<=48,"P6","P7")))))) -> P5 | AE2: =IF(30<=6,"P1",IF(30<=12,"P2",IF(30<=18,"P3",IF(30<=24,"P4",IF(30<=36,"P5",IF(30<=48,"P6","P7")))))) -> P5 | AF2: =IF(31<=6,"P1",IF(31<=12,"P2",IF(31<=18,"P3",IF(31<=24,"P4",IF(31<=36,"P5",IF(31<=48,"P6","P7")))))) -> P5 | AG2: =IF(32<=6,"P1",IF(32<=12,"P2",IF(32<=18,"P3",IF(32<=24,"P4",IF(32<=36,"P5",IF(32<=48,"P6","P7")))))) -> P5 | AH2: =IF(33<=6,"P1",IF(33<=12,"P2",IF(33<=18,"P3",IF(33<=24,"P4",IF(33<=36,"P5",IF(33<=48,"P6","P7")))))) -> P5 | AI2: =IF(34<=6,"P1",IF(34<=12,"P2",IF(34<=18,"P3",IF(34<=24,"P4",IF(34<=36,"P5",IF(34<=48,"P6","P7")))))) -> P5 | AJ2: =IF(35<=6,"P1",IF(35<=12,"P2",IF(35<=18,"P3",IF(35<=24,"P4",IF(35<=36,"P5",IF(35<=48,"P6","P7")))))) -> P5 | AK2: =IF(36<=6,"P1",IF(36<=12,"P2",IF(36<=18,"P3",IF(36<=24,"P4",IF(36<=36,"P5",IF(36<=48,"P6","P7")))))) -> P5 | AL2: =IF(37<=6,"P1",IF(37<=12,"P2",IF(37<=18,"P3",IF(37<=24,"P4",IF(37<=36,"P5",IF(37<=48,"P6","P7")))))) -> P6 | AM2: =IF(38<=6,"P1",IF(38<=12,"P2",IF(38<=18,"P3",IF(38<=24,"P4",IF(38<=36,"P5",IF(38<=48,"P6","P7")))))) -> P6 | AN2: =IF(39<=6,"P1",IF(39<=12,"P2",IF(39<=18,"P3",IF(39<=24,"P4",IF(39<=36,"P5",IF(39<=48,"P6","P7")))))) -> P6 | AO2: =IF(40<=6,"P1",IF(40<=12,"P2",IF(40<=18,"P3",IF(40<=24,"P4",IF(40<=36,"P5",IF(40<=48,"P6","P7")))))) -> P6 | AP2: =IF(41<=6,"P1",IF(41<=12,"P2",IF(41<=18,"P3",IF(41<=24,"P4",IF(41<=36,"P5",IF(41<=48,"P6","P7")))))) -> P6 | AQ2: =IF(42<=6,"P1",IF(42<=12,"P2",IF(42<=18,"P3",IF(42<=24,"P4",IF(42<=36,"P5",IF(42<=48,"P6","P7")))))) -> P6 | AR2: =IF(43<=6,"P1",IF(43<=12,"P2",IF(43<=18,"P3",IF(43<=24,"P4",IF(43<=36,"P5",IF(43<=48,"P6","P7")))))) -> P6 | AS2: =IF(44<=6,"P1",IF(44<=12,"P2",IF(44<=18,"P3",IF(44<=24,"P4",IF(44<=36,"P5",IF(44<=48,"P6","P7")))))) -> P6 | AT2: =IF(45<=6,"P1",IF(45<=12,"P2",IF(45<=18,"P3",IF(45<=24,"P4",IF(45<=36,"P5",IF(45<=48,"P6","P7")))))) -> P6 | AU2: =IF(46<=6,"P1",IF(46<=12,"P2",IF(46<=18,"P3",IF(46<=24,"P4",IF(46<=36,"P5",IF(46<=48,"P6","P7")))))) -> P6 | AV2: =IF(47<=6,"P1",IF(47<=12,"P2",IF(47<=18,"P3",IF(47<=24,"P4",IF(47<=36,"P5",IF(47<=48,"P6","P7")))))) -> P6 | AW2: =IF(48<=6,"P1",IF(48<=12,"P2",IF(48<=18,"P3",IF(48<=24,"P4",IF(48<=36,"P5",IF(48<=48,"P6","P7")))))) -> P6 | AX2: =IF(49<=6,"P1",IF(49<=12,"P2",IF(49<=18,"P3",IF(49<=24,"P4",IF(49<=36,"P5",IF(49<=48,"P6","P7")))))) -> P7 | AY2: =IF(50<=6,"P1",IF(50<=12,"P2",IF(50<=18,"P3",IF(50<=24,"P4",IF(50<=36,"P5",IF(50<=48,"P6","P7")))))) -> P7 | AZ2: =IF(51<=6,"P1",IF(51<=12,"P2",IF(51<=18,"P3",IF(51<=24,"P4",IF(51<=36,"P5",IF(51<=48,"P6","P7")))))) -> P7 | BA2: =IF(52<=6,"P1",IF(52<=12,"P2",IF(52<=18,"P3",IF(52<=24,"P4",IF(52<=36,"P5",IF(52<=48,"P6","P7")))))) -> P7 | BB2: =IF(53<=6,"P1",IF(53<=12,"P2",IF(53<=18,"P3",IF(53<=24,"P4",IF(53<=36,"P5",IF(53<=48,"P6","P7")))))) -> P7 | BC2: =IF(54<=6,"P1",IF(54<=12,"P2",IF(54<=18,"P3",IF(54<=24,"P4",IF(54<=36,"P5",IF(54<=48,"P6","P7")))))) -> P7 | BD2: =IF(55<=6,"P1",IF(55<=12,"P2",IF(55<=18,"P3",IF(55<=24,"P4",IF(55<=36,"P5",IF(55<=48,"P6","P7")))))) -> P7 | BE2: =IF(56<=6,"P1",IF(56<=12,"P2",IF(56<=18,"P3",IF(56<=24,"P4",IF(56<=36,"P5",IF(56<=48,"P6","P7")))))) -> P7 | BF2: =IF(57<=6,"P1",IF(57<=12,"P2",IF(57<=18,"P3",IF(57<=24,"P4",IF(57<=36,"P5",IF(57<=48,"P6","P7")))))) -> P7 | BG2: =IF(58<=6,"P1",IF(58<=12,"P2",IF(58<=18,"P3",IF(58<=24,"P4",IF(58<=36,"P5",IF(58<=48,"P6","P7")))))) -> P7 | BH2: =IF(59<=6,"P1",IF(59<=12,"P2",IF(59<=18,"P3",IF(59<=24,"P4",IF(59<=36,"P5",IF(59<=48,"P6","P7")))))) -> P7 | BI2: =IF(60<=6,"P1",IF(60<=12,"P2",IF(60<=18,"P3",IF(60<=24,"P4",IF(60<=36,"P5",IF(60<=48,"P6","P7")))))) -> P7
A3: 月 | B3: M1 | C3: M2 | D3: M3 | E3: M4 | F3: M5 | G3: M6 | H3: M7 | I3: M8 | J3: M9 | K3: M10 | L3: M11 | M3: M12 | N3: M13 | O3: M14 | P3: M15 | Q3: M16 | R3: M17 | S3: M18 | T3: M19 | U3: M20 | V3: M21 | W3: M22 | X3: M23 | Y3: M24 | Z3: M25 | AA3: M26 | AB3: M27 | AC3: M28 | AD3: M29 | AE3: M30 | AF3: M31 | AG3: M32 | AH3: M33 | AI3: M34 | AJ3: M35 | AK3: M36 | AL3: M37 | AM3: M38 | AN3: M39 | AO3: M40 | AP3: M41 | AQ3: M42 | AR3: M43 | AS3: M44 | AT3: M45 | AU3: M46 | AV3: M47 | AW3: M48 | AX3: M49 | AY3: M50 | AZ3: M51 | BA3: M52 | BB3: M53 | BC3: M54 | BD3: M55 | BE3: M56 | BF3: M57 | BG3: M58 | BH3: M59 | BI3: M60
A4: 【営業活動】
A5: 月間新規SuguDesk契約数 | B5: 0 | C5: =IF(2<=6,'前提'!$B$13,IF(2<=12,'前提'!$B$14,IF(2<=18,'前提'!$B$15,IF(2<=24,'前提'!$B$16,IF(2<=36,'前提'!$B$17,IF(2<=48,'前提'!$B$18,'前提'!$B$19)))))) -> 2 | D5: =IF(3<=6,'前提'!$B$13,IF(3<=12,'前提'!$B$14,IF(3<=18,'前提'!$B$15,IF(3<=24,'前提'!$B$16,IF(3<=36,'前提'!$B$17,IF(3<=48,'前提'!$B$18,'前提'!$B$19)))))) -> 2 | E5: =IF(4<=6,'前提'!$B$13,IF(4<=12,'前提'!$B$14,IF(4<=18,'前提'!$B$15,IF(4<=24,'前提'!$B$16,IF(4<=36,'前提'!$B$17,IF(4<=48,'前提'!$B$18,'前提'!$B$19)))))) -> 2 | F5: =IF(5<=6,'前提'!$B$13,IF(5<=12,'前提'!$B$14,IF(5<=18,'前提'!$B$15,IF(5<=24,'前提'!$B$16,IF(5<=36,'前提'!$B$17,IF(5<=48,'前提'!$B$18,'前提'!$B$19)))))) -> 2 | G5: =IF(6<=6,'前提'!$B$13,IF(6<=12,'前提'!$B$14,IF(6<=18,'前提'!$B$15,IF(6<=24,'前提'!$B$16,IF(6<=36,'前提'!$B$17,IF(6<=48,'前提'!$B$18,'前提'!$B$19)))))) -> 2 | H5: =IF(7<=6,'前提'!$B$13,IF(7<=12,'前提'!$B$14,IF(7<=18,'前提'!$B$15,IF(7<=24,'前提'!$B$16,IF(7<=36,'前提'!$B$17,IF(7<=48,'前提'!$B$18,'前提'!$B$19)))))) -> 5 | I5: =IF(8<=6,'前提'!$B$13,IF(8<=12,'前提'!$B$14,IF(8<=18,'前提'!$B$15,IF(8<=24,'前提'!$B$16,IF(8<=36,'前提'!$B$17,IF(8<=48,'前提'!$B$18,'前提'!$B$19)))))) -> 5 | J5: =IF(9<=6,'前提'!$B$13,IF(9<=12,'前提'!$B$14,IF(9<=18,'前提'!$B$15,IF(9<=24,'前提'!$B$16,IF(9<=36,'前提'!$B$17,IF(9<=48,'前提'!$B$18,'前提'!$B$19)))))) -> 5 | K5: =IF(10<=6,'前提'!$B$13,IF(10<=12,'前提'!$B$14,IF(10<=18,'前提'!$B$15,IF(10<=24,'前提'!$B$16,IF(10<=36,'前提'!$B$17,IF(10<=48,'前提'!$B$18,'前提'!$B$19)))))) -> 5 | L5: =IF(11<=6,'前提'!$B$13,IF(11<=12,'前提'!$B$14,IF(11<=18,'前提'!$B$15,IF(11<=24,'前提'!$B$16,IF(11<=36,'前提'!$B$17,IF(11<=48,'前提'!$B$18,'前提'!$B$19)))))) -> 5 | M5: =IF(12<=6,'前提'!$B$13,IF(12<=12,'前提'!$B$14,IF(12<=18,'前提'!$B$15,IF(12<=24,'前提'!$B$16,IF(12<=36,'前提'!$B$17,IF(12<=48,'前提'!$B$18,'前提'!$B$19)))))) -> 5 | N5: =IF(13<=6,'前提'!$B$13,IF(13<=12,'前提'!$B$14,IF(13<=18,'前提'!$B$15,IF(13<=24,'前提'!$B$16,IF(13<=36,'前提'!$B$17,IF(13<=48,'前提'!$B$18,'前提'!$B$19)))))) -> 5 | O5: =IF(14<=6,'前提'!$B$13,IF(14<=12,'前提'!$B$14,IF(14<=18,'前提'!$B$15,IF(14<=24,'前提'!$B$16,IF(14<=36,'前提'!$B$17,IF(14<=48,'前提'!$B$18,'前提'!$B$19)))))) -> 5 | P5: =IF(15<=6,'前提'!$B$13,IF(15<=12,'前提'!$B$14,IF(15<=18,'前提'!$B$15,IF(15<=24,'前提'!$B$16,IF(15<=36,'前提'!$B$17,IF(15<=48,'前提'!$B$18,'前提'!$B$19)))))) -> 5 | Q5: =IF(16<=6,'前提'!$B$13,IF(16<=12,'前提'!$B$14,IF(16<=18,'前提'!$B$15,IF(16<=24,'前提'!$B$16,IF(16<=36,'前提'!$B$17,IF(16<=48,'前提'!$B$18,'前提'!$B$19)))))) -> 5 | R5: =IF(17<=6,'前提'!$B$13,IF(17<=12,'前提'!$B$14,IF(17<=18,'前提'!$B$15,IF(17<=24,'前提'!$B$16,IF(17<=36,'前提'!$B$17,IF(17<=48,'前提'!$B$18,'前提'!$B$19)))))) -> 5 | S5: =IF(18<=6,'前提'!$B$13,IF(18<=12,'前提'!$B$14,IF(18<=18,'前提'!$B$15,IF(18<=24,'前提'!$B$16,IF(18<=36,'前提'!$B$17,IF(18<=48,'前提'!$B$18,'前提'!$B$19)))))) -> 5 | T5: =IF(19<=6,'前提'!$B$13,IF(19<=12,'前提'!$B$14,IF(19<=18,'前提'!$B$15,IF(19<=24,'前提'!$B$16,IF(19<=36,'前提'!$B$17,IF(19<=48,'前提'!$B$18,'前提'!$B$19)))))) -> 6 | U5: =IF(20<=6,'前提'!$B$13,IF(20<=12,'前提'!$B$14,IF(20<=18,'前提'!$B$15,IF(20<=24,'前提'!$B$16,IF(20<=36,'前提'!$B$17,IF(20<=48,'前提'!$B$18,'前提'!$B$19)))))) -> 6 | V5: =IF(21<=6,'前提'!$B$13,IF(21<=12,'前提'!$B$14,IF(21<=18,'前提'!$B$15,IF(21<=24,'前提'!$B$16,IF(21<=36,'前提'!$B$17,IF(21<=48,'前提'!$B$18,'前提'!$B$19)))))) -> 6 | W5: =IF(22<=6,'前提'!$B$13,IF(22<=12,'前提'!$B$14,IF(22<=18,'前提'!$B$15,IF(22<=24,'前提'!$B$16,IF(22<=36,'前提'!$B$17,IF(22<=48,'前提'!$B$18,'前提'!$B$19)))))) -> 6 | X5: =IF(23<=6,'前提'!$B$13,IF(23<=12,'前提'!$B$14,IF(23<=18,'前提'!$B$15,IF(23<=24,'前提'!$B$16,IF(23<=36,'前提'!$B$17,IF(23<=48,'前提'!$B$18,'前提'!$B$19)))))) -> 6 | Y5: =IF(24<=6,'前提'!$B$13,IF(24<=12,'前提'!$B$14,IF(24<=18,'前提'!$B$15,IF(24<=24,'前提'!$B$16,IF(24<=36,'前提'!$B$17,IF(24<=48,'前提'!$B$18,'前提'!$B$19)))))) -> 6 | Z5: =IF(25<=6,'前提'!$B$13,IF(25<=12,'前提'!$B$14,IF(25<=18,'前提'!$B$15,IF(25<=24,'前提'!$B$16,IF(25<=36,'前提'!$B$17,IF(25<=48,'前提'!$B$18,'前提'!$B$19)))))) -> 8 | AA5: =IF(26<=6,'前提'!$B$13,IF(26<=12,'前提'!$B$14,IF(26<=18,'前提'!$B$15,IF(26<=24,'前提'!$B$16,IF(26<=36,'前提'!$B$17,IF(26<=48,'前提'!$B$18,'前提'!$B$19)))))) -> 8 | AB5: =IF(27<=6,'前提'!$B$13,IF(27<=12,'前提'!$B$14,IF(27<=18,'前提'!$B$15,IF(27<=24,'前提'!$B$16,IF(27<=36,'前提'!$B$17,IF(27<=48,'前提'!$B$18,'前提'!$B$19)))))) -> 8 | AC5: =IF(28<=6,'前提'!$B$13,IF(28<=12,'前提'!$B$14,IF(28<=18,'前提'!$B$15,IF(28<=24,'前提'!$B$16,IF(28<=36,'前提'!$B$17,IF(28<=48,'前提'!$B$18,'前提'!$B$19)))))) -> 8 | AD5: =IF(29<=6,'前提'!$B$13,IF(29<=12,'前提'!$B$14,IF(29<=18,'前提'!$B$15,IF(29<=24,'前提'!$B$16,IF(29<=36,'前提'!$B$17,IF(29<=48,'前提'!$B$18,'前提'!$B$19)))))) -> 8 | AE5: =IF(30<=6,'前提'!$B$13,IF(30<=12,'前提'!$B$14,IF(30<=18,'前提'!$B$15,IF(30<=24,'前提'!$B$16,IF(30<=36,'前提'!$B$17,IF(30<=48,'前提'!$B$18,'前提'!$B$19)))))) -> 8 | AF5: =IF(31<=6,'前提'!$B$13,IF(31<=12,'前提'!$B$14,IF(31<=18,'前提'!$B$15,IF(31<=24,'前提'!$B$16,IF(31<=36,'前提'!$B$17,IF(31<=48,'前提'!$B$18,'前提'!$B$19)))))) -> 8 | AG5: =IF(32<=6,'前提'!$B$13,IF(32<=12,'前提'!$B$14,IF(32<=18,'前提'!$B$15,IF(32<=24,'前提'!$B$16,IF(32<=36,'前提'!$B$17,IF(32<=48,'前提'!$B$18,'前提'!$B$19)))))) -> 8 | AH5: =IF(33<=6,'前提'!$B$13,IF(33<=12,'前提'!$B$14,IF(33<=18,'前提'!$B$15,IF(33<=24,'前提'!$B$16,IF(33<=36,'前提'!$B$17,IF(33<=48,'前提'!$B$18,'前提'!$B$19)))))) -> 8 | AI5: =IF(34<=6,'前提'!$B$13,IF(34<=12,'前提'!$B$14,IF(34<=18,'前提'!$B$15,IF(34<=24,'前提'!$B$16,IF(34<=36,'前提'!$B$17,IF(34<=48,'前提'!$B$18,'前提'!$B$19)))))) -> 8 | AJ5: =IF(35<=6,'前提'!$B$13,IF(35<=12,'前提'!$B$14,IF(35<=18,'前提'!$B$15,IF(35<=24,'前提'!$B$16,IF(35<=36,'前提'!$B$17,IF(35<=48,'前提'!$B$18,'前提'!$B$19)))))) -> 8 | AK5: =IF(36<=6,'前提'!$B$13,IF(36<=12,'前提'!$B$14,IF(36<=18,'前提'!$B$15,IF(36<=24,'前提'!$B$16,IF(36<=36,'前提'!$B$17,IF(36<=48,'前提'!$B$18,'前提'!$B$19)))))) -> 8 | AL5: =IF(37<=6,'前提'!$B$13,IF(37<=12,'前提'!$B$14,IF(37<=18,'前提'!$B$15,IF(37<=24,'前提'!$B$16,IF(37<=36,'前提'!$B$17,IF(37<=48,'前提'!$B$18,'前提'!$B$19)))))) -> 10 | AM5: =IF(38<=6,'前提'!$B$13,IF(38<=12,'前提'!$B$14,IF(38<=18,'前提'!$B$15,IF(38<=24,'前提'!$B$16,IF(38<=36,'前提'!$B$17,IF(38<=48,'前提'!$B$18,'前提'!$B$19)))))) -> 10 | AN5: =IF(39<=6,'前提'!$B$13,IF(39<=12,'前提'!$B$14,IF(39<=18,'前提'!$B$15,IF(39<=24,'前提'!$B$16,IF(39<=36,'前提'!$B$17,IF(39<=48,'前提'!$B$18,'前提'!$B$19)))))) -> 10 | AO5: =IF(40<=6,'前提'!$B$13,IF(40<=12,'前提'!$B$14,IF(40<=18,'前提'!$B$15,IF(40<=24,'前提'!$B$16,IF(40<=36,'前提'!$B$17,IF(40<=48,'前提'!$B$18,'前提'!$B$19)))))) -> 10 | AP5: =IF(41<=6,'前提'!$B$13,IF(41<=12,'前提'!$B$14,IF(41<=18,'前提'!$B$15,IF(41<=24,'前提'!$B$16,IF(41<=36,'前提'!$B$17,IF(41<=48,'前提'!$B$18,'前提'!$B$19)))))) -> 10 | AQ5: =IF(42<=6,'前提'!$B$13,IF(42<=12,'前提'!$B$14,IF(42<=18,'前提'!$B$15,IF(42<=24,'前提'!$B$16,IF(42<=36,'前提'!$B$17,IF(42<=48,'前提'!$B$18,'前提'!$B$19)))))) -> 10 | AR5: =IF(43<=6,'前提'!$B$13,IF(43<=12,'前提'!$B$14,IF(43<=18,'前提'!$B$15,IF(43<=24,'前提'!$B$16,IF(43<=36,'前提'!$B$17,IF(43<=48,'前提'!$B$18,'前提'!$B$19)))))) -> 10 | AS5: =IF(44<=6,'前提'!$B$13,IF(44<=12,'前提'!$B$14,IF(44<=18,'前提'!$B$15,IF(44<=24,'前提'!$B$16,IF(44<=36,'前提'!$B$17,IF(44<=48,'前提'!$B$18,'前提'!$B$19)))))) -> 10 | AT5: =IF(45<=6,'前提'!$B$13,IF(45<=12,'前提'!$B$14,IF(45<=18,'前提'!$B$15,IF(45<=24,'前提'!$B$16,IF(45<=36,'前提'!$B$17,IF(45<=48,'前提'!$B$18,'前提'!$B$19)))))) -> 10 | AU5: =IF(46<=6,'前提'!$B$13,IF(46<=12,'前提'!$B$14,IF(46<=18,'前提'!$B$15,IF(46<=24,'前提'!$B$16,IF(46<=36,'前提'!$B$17,IF(46<=48,'前提'!$B$18,'前提'!$B$19)))))) -> 10 | AV5: =IF(47<=6,'前提'!$B$13,IF(47<=12,'前提'!$B$14,IF(47<=18,'前提'!$B$15,IF(47<=24,'前提'!$B$16,IF(47<=36,'前提'!$B$17,IF(47<=48,'前提'!$B$18,'前提'!$B$19)))))) -> 10 | AW5: =IF(48<=6,'前提'!$B$13,IF(48<=12,'前提'!$B$14,IF(48<=18,'前提'!$B$15,IF(48<=24,'前提'!$B$16,IF(48<=36,'前提'!$B$17,IF(48<=48,'前提'!$B$18,'前提'!$B$19)))))) -> 10 | AX5: =IF(49<=6,'前提'!$B$13,IF(49<=12,'前提'!$B$14,IF(49<=18,'前提'!$B$15,IF(49<=24,'前提'!$B$16,IF(49<=36,'前提'!$B$17,IF(49<=48,'前提'!$B$18,'前提'!$B$19)))))) -> 12 | AY5: =IF(50<=6,'前提'!$B$13,IF(50<=12,'前提'!$B$14,IF(50<=18,'前提'!$B$15,IF(50<=24,'前提'!$B$16,IF(50<=36,'前提'!$B$17,IF(50<=48,'前提'!$B$18,'前提'!$B$19)))))) -> 12 | AZ5: =IF(51<=6,'前提'!$B$13,IF(51<=12,'前提'!$B$14,IF(51<=18,'前提'!$B$15,IF(51<=24,'前提'!$B$16,IF(51<=36,'前提'!$B$17,IF(51<=48,'前提'!$B$18,'前提'!$B$19)))))) -> 12 | BA5: =IF(52<=6,'前提'!$B$13,IF(52<=12,'前提'!$B$14,IF(52<=18,'前提'!$B$15,IF(52<=24,'前提'!$B$16,IF(52<=36,'前提'!$B$17,IF(52<=48,'前提'!$B$18,'前提'!$B$19)))))) -> 12 | BB5: =IF(53<=6,'前提'!$B$13,IF(53<=12,'前提'!$B$14,IF(53<=18,'前提'!$B$15,IF(53<=24,'前提'!$B$16,IF(53<=36,'前提'!$B$17,IF(53<=48,'前提'!$B$18,'前提'!$B$19)))))) -> 12 | BC5: =IF(54<=6,'前提'!$B$13,IF(54<=12,'前提'!$B$14,IF(54<=18,'前提'!$B$15,IF(54<=24,'前提'!$B$16,IF(54<=36,'前提'!$B$17,IF(54<=48,'前提'!$B$18,'前提'!$B$19)))))) -> 12 | BD5: =IF(55<=6,'前提'!$B$13,IF(55<=12,'前提'!$B$14,IF(55<=18,'前提'!$B$15,IF(55<=24,'前提'!$B$16,IF(55<=36,'前提'!$B$17,IF(55<=48,'前提'!$B$18,'前提'!$B$19)))))) -> 12 | BE5: =IF(56<=6,'前提'!$B$13,IF(56<=12,'前提'!$B$14,IF(56<=18,'前提'!$B$15,IF(56<=24,'前提'!$B$16,IF(56<=36,'前提'!$B$17,IF(56<=48,'前提'!$B$18,'前提'!$B$19)))))) -> 12 | BF5: =IF(57<=6,'前提'!$B$13,IF(57<=12,'前提'!$B$14,IF(57<=18,'前提'!$B$15,IF(57<=24,'前提'!$B$16,IF(57<=36,'前提'!$B$17,IF(57<=48,'前提'!$B$18,'前提'!$B$19)))))) -> 12 | BG5: =IF(58<=6,'前提'!$B$13,IF(58<=12,'前提'!$B$14,IF(58<=18,'前提'!$B$15,IF(58<=24,'前提'!$B$16,IF(58<=36,'前提'!$B$17,IF(58<=48,'前提'!$B$18,'前提'!$B$19)))))) -> 12 | BH5: =IF(59<=6,'前提'!$B$13,IF(59<=12,'前提'!$B$14,IF(59<=18,'前提'!$B$15,IF(59<=24,'前提'!$B$16,IF(59<=36,'前提'!$B$17,IF(59<=48,'前提'!$B$18,'前提'!$B$19)))))) -> 12 | BI5: =IF(60<=6,'前提'!$B$13,IF(60<=12,'前提'!$B$14,IF(60<=18,'前提'!$B$15,IF(60<=24,'前提'!$B$16,IF(60<=36,'前提'!$B$17,IF(60<=48,'前提'!$B$18,'前提'!$B$19)))))) -> 12
A7: 【顧客数】
A8: SuguDesk期首顧客数 | B8: 1 | C8: =B10 -> 1 | D8: =C10 -> 3 | E8: =D10 -> 5 | F8: =E10 -> 7 | G8: =F10 -> 9 | H8: =G10 -> 11 | I8: =H10 -> 16 | J8: =I10 -> 21 | ... BI8: =BH10 -> 319
A9: SuguDesk解約数 | B9: =ROUNDDOWN(B8*'前提'!$B$8,0) -> 0 | C9: =ROUNDDOWN(C8*'前提'!$B$8,0) -> 0 | D9: =ROUNDDOWN(D8*'前提'!$B$8,0) -> 0 | E9: =ROUNDDOWN(E8*'前提'!$B$8,0) -> 0 | F9: =ROUNDDOWN(F8*'前提'!$B$8,0) -> 0 | G9: =ROUNDDOWN(G8*'前提'!$B$8,0) -> 0 | H9: =ROUNDDOWN(H8*'前提'!$B$8,0) -> 0 | I9: =ROUNDDOWN(I8*'前提'!$B$8,0) -> 0 | ... BI9: =ROUNDDOWN(BI8*'前提'!$B$8,0) -> 6
A10: SuguDesk期末顧客数 | B10: =B8+B5-B9 -> 1 | C10: =C8+C5-C9 -> 3 | D10: =D8+D5-D9 -> 5 | E10: =E8+E5-E9 -> 7 | F10: =F8+F5-F9 -> 9 | G10: =G8+G5-G9 -> 11 | H10: =H8+H5-H9 -> 16 | I10: =I8+I5-I9 -> 21 | ... BI10: =BI8+BI5-BI9 -> 325
A11: BPO新規転換数 | B11: =IF(1>=7,ROUNDDOWN(B10*'前提'!$B$10,0),0) -> 0 | C11: =IF(2>=7,ROUNDDOWN(C10*'前提'!$B$10,0),0) -> 0 | D11: =IF(3>=7,ROUNDDOWN(D10*'前提'!$B$10,0),0) -> 0 | E11: =IF(4>=7,ROUNDDOWN(E10*'前提'!$B$10,0),0) -> 0 | F11: =IF(5>=7,ROUNDDOWN(F10*'前提'!$B$10,0),0) -> 0 | G11: =IF(6>=7,ROUNDDOWN(G10*'前提'!$B$10,0),0) -> 0 | H11: =IF(7>=7,ROUNDDOWN(H10*'前提'!$B$10,0),0) -> 0 | I11: =IF(8>=7,ROUNDDOWN(I10*'前提'!$B$10,0),0) -> 1 | J11: =IF(9>=7,ROUNDDOWN(J10*'前提'!$B$10,0),0) -> 1 | K11: =IF(10>=7,ROUNDDOWN(K10*'前提'!$B$10,0),0) -> 1 | L11: =IF(11>=7,ROUNDDOWN(L10*'前提'!$B$10,0),0) -> 1 | M11: =IF(12>=7,ROUNDDOWN(M10*'前提'!$B$10,0),0) -> 2 | N11: =IF(13>=7,ROUNDDOWN(N10*'前提'!$B$10,0),0) -> 2 | O11: =IF(14>=7,ROUNDDOWN(O10*'前提'!$B$10,0),0) -> 2 | P11: =IF(15>=7,ROUNDDOWN(P10*'前提'!$B$10,0),0) -> 2 | Q11: =IF(16>=7,ROUNDDOWN(Q10*'前提'!$B$10,0),0) -> 2 | R11: =IF(17>=7,ROUNDDOWN(R10*'前提'!$B$10,0),0) -> 3 | S11: =IF(18>=7,ROUNDDOWN(S10*'前提'!$B$10,0),0) -> 3 | T11: =IF(19>=7,ROUNDDOWN(T10*'前提'!$B$10,0),0) -> 3 | U11: =IF(20>=7,ROUNDDOWN(U10*'前提'!$B$10,0),0) -> 3 | V11: =IF(21>=7,ROUNDDOWN(V10*'前提'!$B$10,0),0) -> 4 | W11: =IF(22>=7,ROUNDDOWN(W10*'前提'!$B$10,0),0) -> 4 | X11: =IF(23>=7,ROUNDDOWN(X10*'前提'!$B$10,0),0) -> 4 | Y11: =IF(24>=7,ROUNDDOWN(Y10*'前提'!$B$10,0),0) -> 4 | Z11: =IF(25>=7,ROUNDDOWN(Z10*'前提'!$B$10,0),0) -> 5 | AA11: =IF(26>=7,ROUNDDOWN(AA10*'前提'!$B$10,0),0) -> 5 | AB11: =IF(27>=7,ROUNDDOWN(AB10*'前提'!$B$10,0),0) -> 5 | AC11: =IF(28>=7,ROUNDDOWN(AC10*'前提'!$B$10,0),0) -> 6 | AD11: =IF(29>=7,ROUNDDOWN(AD10*'前提'!$B$10,0),0) -> 6 | AE11: =IF(30>=7,ROUNDDOWN(AE10*'前提'!$B$10,0),0) -> 6 | AF11: =IF(31>=7,ROUNDDOWN(AF10*'前提'!$B$10,0),0) -> 7 | AG11: =IF(32>=7,ROUNDDOWN(AG10*'前提'!$B$10,0),0) -> 7 | AH11: =IF(33>=7,ROUNDDOWN(AH10*'前提'!$B$10,0),0) -> 7 | AI11: =IF(34>=7,ROUNDDOWN(AI10*'前提'!$B$10,0),0) -> 7 | AJ11: =IF(35>=7,ROUNDDOWN(AJ10*'前提'!$B$10,0),0) -> 8 | AK11: =IF(36>=7,ROUNDDOWN(AK10*'前提'!$B$10,0),0) -> 8 | AL11: =IF(37>=7,ROUNDDOWN(AL10*'前提'!$B$10,0),0) -> 8 | AM11: =IF(38>=7,ROUNDDOWN(AM10*'前提'!$B$10,0),0) -> 9 | AN11: =IF(39>=7,ROUNDDOWN(AN10*'前提'!$B$10,0),0) -> 9 | AO11: =IF(40>=7,ROUNDDOWN(AO10*'前提'!$B$10,0),0) -> 9 | AP11: =IF(41>=7,ROUNDDOWN(AP10*'前提'!$B$10,0),0) -> 10 | AQ11: =IF(42>=7,ROUNDDOWN(AQ10*'前提'!$B$10,0),0) -> 10 | AR11: =IF(43>=7,ROUNDDOWN(AR10*'前提'!$B$10,0),0) -> 10 | AS11: =IF(44>=7,ROUNDDOWN(AS10*'前提'!$B$10,0),0) -> 11 | AT11: =IF(45>=7,ROUNDDOWN(AT10*'前提'!$B$10,0),0) -> 11 | AU11: =IF(46>=7,ROUNDDOWN(AU10*'前提'!$B$10,0),0) -> 11 | AV11: =IF(47>=7,ROUNDDOWN(AV10*'前提'!$B$10,0),0) -> 11 | AW11: =IF(48>=7,ROUNDDOWN(AW10*'前提'!$B$10,0),0) -> 12 | AX11: =IF(49>=7,ROUNDDOWN(AX10*'前提'!$B$10,0),0) -> 12 | AY11: =IF(50>=7,ROUNDDOWN(AY10*'前提'!$B$10,0),0) -> 12 | AZ11: =IF(51>=7,ROUNDDOWN(AZ10*'前提'!$B$10,0),0) -> 13 | BA11: =IF(52>=7,ROUNDDOWN(BA10*'前提'!$B$10,0),0) -> 13 | BB11: =IF(53>=7,ROUNDDOWN(BB10*'前提'!$B$10,0),0) -> 14 | BC11: =IF(54>=7,ROUNDDOWN(BC10*'前提'!$B$10,0),0) -> 14 | BD11: =IF(55>=7,ROUNDDOWN(BD10*'前提'!$B$10,0),0) -> 14 | BE11: =IF(56>=7,ROUNDDOWN(BE10*'前提'!$B$10,0),0) -> 15 | BF11: =IF(57>=7,ROUNDDOWN(BF10*'前提'!$B$10,0),0) -> 15 | BG11: =IF(58>=7,ROUNDDOWN(BG10*'前提'!$B$10,0),0) -> 15 | BH11: =IF(59>=7,ROUNDDOWN(BH10*'前提'!$B$10,0),0) -> 15 | BI11: =IF(60>=7,ROUNDDOWN(BI10*'前提'!$B$10,0),0) -> 16
A12: BPO解約数 | B12: =ROUNDDOWN(B13*'前提'!$B$9,0) -> 0 | C12: =ROUNDDOWN(C13*'前提'!$B$9,0) -> 0 | D12: =ROUNDDOWN(D13*'前提'!$B$9,0) -> 0 | E12: =ROUNDDOWN(E13*'前提'!$B$9,0) -> 0 | F12: =ROUNDDOWN(F13*'前提'!$B$9,0) -> 0 | G12: =ROUNDDOWN(G13*'前提'!$B$9,0) -> 0 | H12: =ROUNDDOWN(H13*'前提'!$B$9,0) -> 0 | I12: =ROUNDDOWN(I13*'前提'!$B$9,0) -> 0 | ... BI12: =ROUNDDOWN(BI13*'前提'!$B$9,0) -> 3
A13: BPO期首顧客数 | B13: 0 | C13: =B14 -> 0 | D13: =C14 -> 0 | E13: =D14 -> 0 | F13: =E14 -> 0 | G13: =F14 -> 0 | H13: =G14 -> 0 | I13: =H14 -> 0 | J13: =I14 -> 1 | ... BI13: =BH14 -> 350
A14: BPO期末顧客数 | B14: =B13+B11-B12 -> 0 | C14: =C13+C11-C12 -> 0 | D14: =D13+D11-D12 -> 0 | E14: =E13+E11-E12 -> 0 | F14: =F13+F11-F12 -> 0 | G14: =G13+G11-G12 -> 0 | H14: =H13+H11-H12 -> 0 | I14: =I13+I11-I12 -> 1 | ... BI14: =BI13+BI11-BI12 -> 363
A16: 【売上】
A17: SuguDesk月額売上 | B17: =B10*'前提'!$B$4 -> 11500 | C17: =C10*'前提'!$B$4 -> 34500 | D17: =D10*'前提'!$B$4 -> 57500 | E17: =E10*'前提'!$B$4 -> 80500 | F17: =F10*'前提'!$B$4 -> 103500 | G17: =G10*'前提'!$B$4 -> 126500 | H17: =H10*'前提'!$B$4 -> 184000 | I17: =I10*'前提'!$B$4 -> 241500 | ... BI17: =BI10*'前提'!$B$4 -> 3737500
A18: BPO事務長代行売上 | B18: =B14*'前提'!$B$6 -> 0 | C18: =C14*'前提'!$B$6 -> 0 | D18: =D14*'前提'!$B$6 -> 0 | E18: =E14*'前提'!$B$6 -> 0 | F18: =F14*'前提'!$B$6 -> 0 | G18: =G14*'前提'!$B$6 -> 0 | H18: =H14*'前提'!$B$6 -> 0 | I18: =I14*'前提'!$B$6 -> 150000 | ... BI18: =BI14*'前提'!$B$6 -> 54450000
A19: BPO採用/集患売上 | B19: =IF(1>=13,B14*'前提'!$B$7,0) -> 0 | C19: =IF(2>=13,C14*'前提'!$B$7,0) -> 0 | D19: =IF(3>=13,D14*'前提'!$B$7,0) -> 0 | E19: =IF(4>=13,E14*'前提'!$B$7,0) -> 0 | F19: =IF(5>=13,F14*'前提'!$B$7,0) -> 0 | G19: =IF(6>=13,G14*'前提'!$B$7,0) -> 0 | H19: =IF(7>=13,H14*'前提'!$B$7,0) -> 0 | I19: =IF(8>=13,I14*'前提'!$B$7,0) -> 0 | J19: =IF(9>=13,J14*'前提'!$B$7,0) -> 0 | K19: =IF(10>=13,K14*'前提'!$B$7,0) -> 0 | L19: =IF(11>=13,L14*'前提'!$B$7,0) -> 0 | M19: =IF(12>=13,M14*'前提'!$B$7,0) -> 0 | N19: =IF(13>=13,N14*'前提'!$B$7,0) -> 400000 | O19: =IF(14>=13,O14*'前提'!$B$7,0) -> 500000 | P19: =IF(15>=13,P14*'前提'!$B$7,0) -> 600000 | Q19: =IF(16>=13,Q14*'前提'!$B$7,0) -> 700000 | R19: =IF(17>=13,R14*'前提'!$B$7,0) -> 850000 | S19: =IF(18>=13,S14*'前提'!$B$7,0) -> 1000000 | T19: =IF(19>=13,T14*'前提'!$B$7,0) -> 1150000 | U19: =IF(20>=13,U14*'前提'!$B$7,0) -> 1300000 | V19: =IF(21>=13,V14*'前提'!$B$7,0) -> 1500000 | W19: =IF(22>=13,W14*'前提'!$B$7,0) -> 1700000 | X19: =IF(23>=13,X14*'前提'!$B$7,0) -> 1900000 | Y19: =IF(24>=13,Y14*'前提'!$B$7,0) -> 2100000 | Z19: =IF(25>=13,Z14*'前提'!$B$7,0) -> 2350000 | AA19: =IF(26>=13,AA14*'前提'!$B$7,0) -> 2600000 | AB19: =IF(27>=13,AB14*'前提'!$B$7,0) -> 2850000 | AC19: =IF(28>=13,AC14*'前提'!$B$7,0) -> 3150000 | AD19: =IF(29>=13,AD14*'前提'!$B$7,0) -> 3450000 | AE19: =IF(30>=13,AE14*'前提'!$B$7,0) -> 3750000 | AF19: =IF(31>=13,AF14*'前提'!$B$7,0) -> 4100000 | AG19: =IF(32>=13,AG14*'前提'!$B$7,0) -> 4450000 | AH19: =IF(33>=13,AH14*'前提'!$B$7,0) -> 4800000 | AI19: =IF(34>=13,AI14*'前提'!$B$7,0) -> 5150000 | AJ19: =IF(35>=13,AJ14*'前提'!$B$7,0) -> 5500000 | AK19: =IF(36>=13,AK14*'前提'!$B$7,0) -> 5850000 | AL19: =IF(37>=13,AL14*'前提'!$B$7,0) -> 6200000 | AM19: =IF(38>=13,AM14*'前提'!$B$7,0) -> 6600000 | AN19: =IF(39>=13,AN14*'前提'!$B$7,0) -> 7000000 | AO19: =IF(40>=13,AO14*'前提'!$B$7,0) -> 7400000 | AP19: =IF(41>=13,AP14*'前提'!$B$7,0) -> 7850000 | AQ19: =IF(42>=13,AQ14*'前提'!$B$7,0) -> 8300000 | AR19: =IF(43>=13,AR14*'前提'!$B$7,0) -> 8750000 | AS19: =IF(44>=13,AS14*'前提'!$B$7,0) -> 9250000 | AT19: =IF(45>=13,AT14*'前提'!$B$7,0) -> 9750000 | AU19: =IF(46>=13,AU14*'前提'!$B$7,0) -> 10250000 | AV19: =IF(47>=13,AV14*'前提'!$B$7,0) -> 10700000 | AW19: =IF(48>=13,AW14*'前提'!$B$7,0) -> 11200000 | AX19: =IF(49>=13,AX14*'前提'!$B$7,0) -> 11700000 | AY19: =IF(50>=13,AY14*'前提'!$B$7,0) -> 12200000 | AZ19: =IF(51>=13,AZ14*'前提'!$B$7,0) -> 12750000 | BA19: =IF(52>=13,BA14*'前提'!$B$7,0) -> 13300000 | BB19: =IF(53>=13,BB14*'前提'!$B$7,0) -> 13900000 | BC19: =IF(54>=13,BC14*'前提'!$B$7,0) -> 14500000 | BD19: =IF(55>=13,BD14*'前提'!$B$7,0) -> 15100000 | BE19: =IF(56>=13,BE14*'前提'!$B$7,0) -> 15700000 | BF19: =IF(57>=13,BF14*'前提'!$B$7,0) -> 16300000 | BG19: =IF(58>=13,BG14*'前提'!$B$7,0) -> 16900000 | BH19: =IF(59>=13,BH14*'前提'!$B$7,0) -> 17500000 | BI19: =IF(60>=13,BI14*'前提'!$B$7,0) -> 18150000
A20: 導入費用 | B20: =B5*'前提'!$B$5 -> 0 | C20: =C5*'前提'!$B$5 -> 450000 | D20: =D5*'前提'!$B$5 -> 450000 | E20: =E5*'前提'!$B$5 -> 450000 | F20: =F5*'前提'!$B$5 -> 450000 | G20: =G5*'前提'!$B$5 -> 450000 | H20: =H5*'前提'!$B$5 -> 1125000 | I20: =I5*'前提'!$B$5 -> 1125000 | ... BI20: =BI5*'前提'!$B$5 -> 2700000
A21: MRR | B21: =B17+B18+B19 -> 11500 | C21: =C17+C18+C19 -> 34500 | D21: =D17+D18+D19 -> 57500 | E21: =E17+E18+E19 -> 80500 | F21: =F17+F18+F19 -> 103500 | G21: =G17+G18+G19 -> 126500 | H21: =H17+H18+H19 -> 184000 | I21: =I17+I18+I19 -> 391500 | ... BI21: =BI17+BI18+BI19 -> 76337500
A22: 売上合計 | B22: =B21+B20 -> 11500 | C22: =C21+C20 -> 484500 | D22: =D21+D20 -> 507500 | E22: =E21+E20 -> 530500 | F22: =F21+F20 -> 553500 | G22: =G21+G20 -> 576500 | H22: =H21+H20 -> 1309000 | I22: =I21+I20 -> 1516500 | ... BI22: =BI21+BI20 -> 79037500
A24: 【コスト】
A25: CEO報酬 | B25: ='前提'!$B$22 -> 300000 | C25: ='前提'!$B$22 -> 300000 | D25: ='前提'!$B$22 -> 300000 | E25: ='前提'!$B$22 -> 300000 | F25: ='前提'!$B$22 -> 300000 | G25: ='前提'!$B$22 -> 300000 | H25: ='前提'!$B$22 -> 300000 | I25: ='前提'!$B$22 -> 300000 | ... BI25: ='前提'!$B$22 -> 300000
A26: エンジニア | B26: =IF(1<=6,'前提'!$B$23*'前提'!$B$24,IF(1<=12,'前提'!$B$23*'前提'!$B$25,'前提'!$B$26*IF(1<=18,'前提'!$B$49,IF(1<=24,'前提'!$B$50,IF(1<=36,'前提'!$B$51,IF(1<=48,'前提'!$B$52,'前提'!$B$53)))))) -> 322500 | C26: =IF(2<=6,'前提'!$B$23*'前提'!$B$24,IF(2<=12,'前提'!$B$23*'前提'!$B$25,'前提'!$B$26*IF(2<=18,'前提'!$B$49,IF(2<=24,'前提'!$B$50,IF(2<=36,'前提'!$B$51,IF(2<=48,'前提'!$B$52,'前提'!$B$53)))))) -> 322500 | D26: =IF(3<=6,'前提'!$B$23*'前提'!$B$24,IF(3<=12,'前提'!$B$23*'前提'!$B$25,'前提'!$B$26*IF(3<=18,'前提'!$B$49,IF(3<=24,'前提'!$B$50,IF(3<=36,'前提'!$B$51,IF(3<=48,'前提'!$B$52,'前提'!$B$53)))))) -> 322500 | E26: =IF(4<=6,'前提'!$B$23*'前提'!$B$24,IF(4<=12,'前提'!$B$23*'前提'!$B$25,'前提'!$B$26*IF(4<=18,'前提'!$B$49,IF(4<=24,'前提'!$B$50,IF(4<=36,'前提'!$B$51,IF(4<=48,'前提'!$B$52,'前提'!$B$53)))))) -> 322500 | F26: =IF(5<=6,'前提'!$B$23*'前提'!$B$24,IF(5<=12,'前提'!$B$23*'前提'!$B$25,'前提'!$B$26*IF(5<=18,'前提'!$B$49,IF(5<=24,'前提'!$B$50,IF(5<=36,'前提'!$B$51,IF(5<=48,'前提'!$B$52,'前提'!$B$53)))))) -> 322500 | G26: =IF(6<=6,'前提'!$B$23*'前提'!$B$24,IF(6<=12,'前提'!$B$23*'前提'!$B$25,'前提'!$B$26*IF(6<=18,'前提'!$B$49,IF(6<=24,'前提'!$B$50,IF(6<=36,'前提'!$B$51,IF(6<=48,'前提'!$B$52,'前提'!$B$53)))))) -> 322500 | H26: =IF(7<=6,'前提'!$B$23*'前提'!$B$24,IF(7<=12,'前提'!$B$23*'前提'!$B$25,'前提'!$B$26*IF(7<=18,'前提'!$B$49,IF(7<=24,'前提'!$B$50,IF(7<=36,'前提'!$B$51,IF(7<=48,'前提'!$B$52,'前提'!$B$53)))))) -> 200000 | I26: =IF(8<=6,'前提'!$B$23*'前提'!$B$24,IF(8<=12,'前提'!$B$23*'前提'!$B$25,'前提'!$B$26*IF(8<=18,'前提'!$B$49,IF(8<=24,'前提'!$B$50,IF(8<=36,'前提'!$B$51,IF(8<=48,'前提'!$B$52,'前提'!$B$53)))))) -> 200000 | J26: =IF(9<=6,'前提'!$B$23*'前提'!$B$24,IF(9<=12,'前提'!$B$23*'前提'!$B$25,'前提'!$B$26*IF(9<=18,'前提'!$B$49,IF(9<=24,'前提'!$B$50,IF(9<=36,'前提'!$B$51,IF(9<=48,'前提'!$B$52,'前提'!$B$53)))))) -> 200000 | K26: =IF(10<=6,'前提'!$B$23*'前提'!$B$24,IF(10<=12,'前提'!$B$23*'前提'!$B$25,'前提'!$B$26*IF(10<=18,'前提'!$B$49,IF(10<=24,'前提'!$B$50,IF(10<=36,'前提'!$B$51,IF(10<=48,'前提'!$B$52,'前提'!$B$53)))))) -> 200000 | L26: =IF(11<=6,'前提'!$B$23*'前提'!$B$24,IF(11<=12,'前提'!$B$23*'前提'!$B$25,'前提'!$B$26*IF(11<=18,'前提'!$B$49,IF(11<=24,'前提'!$B$50,IF(11<=36,'前提'!$B$51,IF(11<=48,'前提'!$B$52,'前提'!$B$53)))))) -> 200000 | M26: =IF(12<=6,'前提'!$B$23*'前提'!$B$24,IF(12<=12,'前提'!$B$23*'前提'!$B$25,'前提'!$B$26*IF(12<=18,'前提'!$B$49,IF(12<=24,'前提'!$B$50,IF(12<=36,'前提'!$B$51,IF(12<=48,'前提'!$B$52,'前提'!$B$53)))))) -> 200000 | N26: =IF(13<=6,'前提'!$B$23*'前提'!$B$24,IF(13<=12,'前提'!$B$23*'前提'!$B$25,'前提'!$B$26*IF(13<=18,'前提'!$B$49,IF(13<=24,'前提'!$B$50,IF(13<=36,'前提'!$B$51,IF(13<=48,'前提'!$B$52,'前提'!$B$53)))))) -> 700000 | O26: =IF(14<=6,'前提'!$B$23*'前提'!$B$24,IF(14<=12,'前提'!$B$23*'前提'!$B$25,'前提'!$B$26*IF(14<=18,'前提'!$B$49,IF(14<=24,'前提'!$B$50,IF(14<=36,'前提'!$B$51,IF(14<=48,'前提'!$B$52,'前提'!$B$53)))))) -> 700000 | P26: =IF(15<=6,'前提'!$B$23*'前提'!$B$24,IF(15<=12,'前提'!$B$23*'前提'!$B$25,'前提'!$B$26*IF(15<=18,'前提'!$B$49,IF(15<=24,'前提'!$B$50,IF(15<=36,'前提'!$B$51,IF(15<=48,'前提'!$B$52,'前提'!$B$53)))))) -> 700000 | Q26: =IF(16<=6,'前提'!$B$23*'前提'!$B$24,IF(16<=12,'前提'!$B$23*'前提'!$B$25,'前提'!$B$26*IF(16<=18,'前提'!$B$49,IF(16<=24,'前提'!$B$50,IF(16<=36,'前提'!$B$51,IF(16<=48,'前提'!$B$52,'前提'!$B$53)))))) -> 700000 | R26: =IF(17<=6,'前提'!$B$23*'前提'!$B$24,IF(17<=12,'前提'!$B$23*'前提'!$B$25,'前提'!$B$26*IF(17<=18,'前提'!$B$49,IF(17<=24,'前提'!$B$50,IF(17<=36,'前提'!$B$51,IF(17<=48,'前提'!$B$52,'前提'!$B$53)))))) -> 700000 | S26: =IF(18<=6,'前提'!$B$23*'前提'!$B$24,IF(18<=12,'前提'!$B$23*'前提'!$B$25,'前提'!$B$26*IF(18<=18,'前提'!$B$49,IF(18<=24,'前提'!$B$50,IF(18<=36,'前提'!$B$51,IF(18<=48,'前提'!$B$52,'前提'!$B$53)))))) -> 700000 | T26: =IF(19<=6,'前提'!$B$23*'前提'!$B$24,IF(19<=12,'前提'!$B$23*'前提'!$B$25,'前提'!$B$26*IF(19<=18,'前提'!$B$49,IF(19<=24,'前提'!$B$50,IF(19<=36,'前提'!$B$51,IF(19<=48,'前提'!$B$52,'前提'!$B$53)))))) -> 700000 | U26: =IF(20<=6,'前提'!$B$23*'前提'!$B$24,IF(20<=12,'前提'!$B$23*'前提'!$B$25,'前提'!$B$26*IF(20<=18,'前提'!$B$49,IF(20<=24,'前提'!$B$50,IF(20<=36,'前提'!$B$51,IF(20<=48,'前提'!$B$52,'前提'!$B$53)))))) -> 700000 | V26: =IF(21<=6,'前提'!$B$23*'前提'!$B$24,IF(21<=12,'前提'!$B$23*'前提'!$B$25,'前提'!$B$26*IF(21<=18,'前提'!$B$49,IF(21<=24,'前提'!$B$50,IF(21<=36,'前提'!$B$51,IF(21<=48,'前提'!$B$52,'前提'!$B$53)))))) -> 700000 | W26: =IF(22<=6,'前提'!$B$23*'前提'!$B$24,IF(22<=12,'前提'!$B$23*'前提'!$B$25,'前提'!$B$26*IF(22<=18,'前提'!$B$49,IF(22<=24,'前提'!$B$50,IF(22<=36,'前提'!$B$51,IF(22<=48,'前提'!$B$52,'前提'!$B$53)))))) -> 700000 | X26: =IF(23<=6,'前提'!$B$23*'前提'!$B$24,IF(23<=12,'前提'!$B$23*'前提'!$B$25,'前提'!$B$26*IF(23<=18,'前提'!$B$49,IF(23<=24,'前提'!$B$50,IF(23<=36,'前提'!$B$51,IF(23<=48,'前提'!$B$52,'前提'!$B$53)))))) -> 700000 | Y26: =IF(24<=6,'前提'!$B$23*'前提'!$B$24,IF(24<=12,'前提'!$B$23*'前提'!$B$25,'前提'!$B$26*IF(24<=18,'前提'!$B$49,IF(24<=24,'前提'!$B$50,IF(24<=36,'前提'!$B$51,IF(24<=48,'前提'!$B$52,'前提'!$B$53)))))) -> 700000 | Z26: =IF(25<=6,'前提'!$B$23*'前提'!$B$24,IF(25<=12,'前提'!$B$23*'前提'!$B$25,'前提'!$B$26*IF(25<=18,'前提'!$B$49,IF(25<=24,'前提'!$B$50,IF(25<=36,'前提'!$B$51,IF(25<=48,'前提'!$B$52,'前提'!$B$53)))))) -> 1400000 | AA26: =IF(26<=6,'前提'!$B$23*'前提'!$B$24,IF(26<=12,'前提'!$B$23*'前提'!$B$25,'前提'!$B$26*IF(26<=18,'前提'!$B$49,IF(26<=24,'前提'!$B$50,IF(26<=36,'前提'!$B$51,IF(26<=48,'前提'!$B$52,'前提'!$B$53)))))) -> 1400000 | AB26: =IF(27<=6,'前提'!$B$23*'前提'!$B$24,IF(27<=12,'前提'!$B$23*'前提'!$B$25,'前提'!$B$26*IF(27<=18,'前提'!$B$49,IF(27<=24,'前提'!$B$50,IF(27<=36,'前提'!$B$51,IF(27<=48,'前提'!$B$52,'前提'!$B$53)))))) -> 1400000 | AC26: =IF(28<=6,'前提'!$B$23*'前提'!$B$24,IF(28<=12,'前提'!$B$23*'前提'!$B$25,'前提'!$B$26*IF(28<=18,'前提'!$B$49,IF(28<=24,'前提'!$B$50,IF(28<=36,'前提'!$B$51,IF(28<=48,'前提'!$B$52,'前提'!$B$53)))))) -> 1400000 | AD26: =IF(29<=6,'前提'!$B$23*'前提'!$B$24,IF(29<=12,'前提'!$B$23*'前提'!$B$25,'前提'!$B$26*IF(29<=18,'前提'!$B$49,IF(29<=24,'前提'!$B$50,IF(29<=36,'前提'!$B$51,IF(29<=48,'前提'!$B$52,'前提'!$B$53)))))) -> 1400000 | AE26: =IF(30<=6,'前提'!$B$23*'前提'!$B$24,IF(30<=12,'前提'!$B$23*'前提'!$B$25,'前提'!$B$26*IF(30<=18,'前提'!$B$49,IF(30<=24,'前提'!$B$50,IF(30<=36,'前提'!$B$51,IF(30<=48,'前提'!$B$52,'前提'!$B$53)))))) -> 1400000 | AF26: =IF(31<=6,'前提'!$B$23*'前提'!$B$24,IF(31<=12,'前提'!$B$23*'前提'!$B$25,'前提'!$B$26*IF(31<=18,'前提'!$B$49,IF(31<=24,'前提'!$B$50,IF(31<=36,'前提'!$B$51,IF(31<=48,'前提'!$B$52,'前提'!$B$53)))))) -> 1400000 | AG26: =IF(32<=6,'前提'!$B$23*'前提'!$B$24,IF(32<=12,'前提'!$B$23*'前提'!$B$25,'前提'!$B$26*IF(32<=18,'前提'!$B$49,IF(32<=24,'前提'!$B$50,IF(32<=36,'前提'!$B$51,IF(32<=48,'前提'!$B$52,'前提'!$B$53)))))) -> 1400000 | AH26: =IF(33<=6,'前提'!$B$23*'前提'!$B$24,IF(33<=12,'前提'!$B$23*'前提'!$B$25,'前提'!$B$26*IF(33<=18,'前提'!$B$49,IF(33<=24,'前提'!$B$50,IF(33<=36,'前提'!$B$51,IF(33<=48,'前提'!$B$52,'前提'!$B$53)))))) -> 1400000 | AI26: =IF(34<=6,'前提'!$B$23*'前提'!$B$24,IF(34<=12,'前提'!$B$23*'前提'!$B$25,'前提'!$B$26*IF(34<=18,'前提'!$B$49,IF(34<=24,'前提'!$B$50,IF(34<=36,'前提'!$B$51,IF(34<=48,'前提'!$B$52,'前提'!$B$53)))))) -> 1400000 | AJ26: =IF(35<=6,'前提'!$B$23*'前提'!$B$24,IF(35<=12,'前提'!$B$23*'前提'!$B$25,'前提'!$B$26*IF(35<=18,'前提'!$B$49,IF(35<=24,'前提'!$B$50,IF(35<=36,'前提'!$B$51,IF(35<=48,'前提'!$B$52,'前提'!$B$53)))))) -> 1400000 | AK26: =IF(36<=6,'前提'!$B$23*'前提'!$B$24,IF(36<=12,'前提'!$B$23*'前提'!$B$25,'前提'!$B$26*IF(36<=18,'前提'!$B$49,IF(36<=24,'前提'!$B$50,IF(36<=36,'前提'!$B$51,IF(36<=48,'前提'!$B$52,'前提'!$B$53)))))) -> 1400000 | AL26: =IF(37<=6,'前提'!$B$23*'前提'!$B$24,IF(37<=12,'前提'!$B$23*'前提'!$B$25,'前提'!$B$26*IF(37<=18,'前提'!$B$49,IF(37<=24,'前提'!$B$50,IF(37<=36,'前提'!$B$51,IF(37<=48,'前提'!$B$52,'前提'!$B$53)))))) -> 1400000 | AM26: =IF(38<=6,'前提'!$B$23*'前提'!$B$24,IF(38<=12,'前提'!$B$23*'前提'!$B$25,'前提'!$B$26*IF(38<=18,'前提'!$B$49,IF(38<=24,'前提'!$B$50,IF(38<=36,'前提'!$B$51,IF(38<=48,'前提'!$B$52,'前提'!$B$53)))))) -> 1400000 | AN26: =IF(39<=6,'前提'!$B$23*'前提'!$B$24,IF(39<=12,'前提'!$B$23*'前提'!$B$25,'前提'!$B$26*IF(39<=18,'前提'!$B$49,IF(39<=24,'前提'!$B$50,IF(39<=36,'前提'!$B$51,IF(39<=48,'前提'!$B$52,'前提'!$B$53)))))) -> 1400000 | AO26: =IF(40<=6,'前提'!$B$23*'前提'!$B$24,IF(40<=12,'前提'!$B$23*'前提'!$B$25,'前提'!$B$26*IF(40<=18,'前提'!$B$49,IF(40<=24,'前提'!$B$50,IF(40<=36,'前提'!$B$51,IF(40<=48,'前提'!$B$52,'前提'!$B$53)))))) -> 1400000 | AP26: =IF(41<=6,'前提'!$B$23*'前提'!$B$24,IF(41<=12,'前提'!$B$23*'前提'!$B$25,'前提'!$B$26*IF(41<=18,'前提'!$B$49,IF(41<=24,'前提'!$B$50,IF(41<=36,'前提'!$B$51,IF(41<=48,'前提'!$B$52,'前提'!$B$53)))))) -> 1400000 | AQ26: =IF(42<=6,'前提'!$B$23*'前提'!$B$24,IF(42<=12,'前提'!$B$23*'前提'!$B$25,'前提'!$B$26*IF(42<=18,'前提'!$B$49,IF(42<=24,'前提'!$B$50,IF(42<=36,'前提'!$B$51,IF(42<=48,'前提'!$B$52,'前提'!$B$53)))))) -> 1400000 | AR26: =IF(43<=6,'前提'!$B$23*'前提'!$B$24,IF(43<=12,'前提'!$B$23*'前提'!$B$25,'前提'!$B$26*IF(43<=18,'前提'!$B$49,IF(43<=24,'前提'!$B$50,IF(43<=36,'前提'!$B$51,IF(43<=48,'前提'!$B$52,'前提'!$B$53)))))) -> 1400000 | AS26: =IF(44<=6,'前提'!$B$23*'前提'!$B$24,IF(44<=12,'前提'!$B$23*'前提'!$B$25,'前提'!$B$26*IF(44<=18,'前提'!$B$49,IF(44<=24,'前提'!$B$50,IF(44<=36,'前提'!$B$51,IF(44<=48,'前提'!$B$52,'前提'!$B$53)))))) -> 1400000 | AT26: =IF(45<=6,'前提'!$B$23*'前提'!$B$24,IF(45<=12,'前提'!$B$23*'前提'!$B$25,'前提'!$B$26*IF(45<=18,'前提'!$B$49,IF(45<=24,'前提'!$B$50,IF(45<=36,'前提'!$B$51,IF(45<=48,'前提'!$B$52,'前提'!$B$53)))))) -> 1400000 | AU26: =IF(46<=6,'前提'!$B$23*'前提'!$B$24,IF(46<=12,'前提'!$B$23*'前提'!$B$25,'前提'!$B$26*IF(46<=18,'前提'!$B$49,IF(46<=24,'前提'!$B$50,IF(46<=36,'前提'!$B$51,IF(46<=48,'前提'!$B$52,'前提'!$B$53)))))) -> 1400000 | AV26: =IF(47<=6,'前提'!$B$23*'前提'!$B$24,IF(47<=12,'前提'!$B$23*'前提'!$B$25,'前提'!$B$26*IF(47<=18,'前提'!$B$49,IF(47<=24,'前提'!$B$50,IF(47<=36,'前提'!$B$51,IF(47<=48,'前提'!$B$52,'前提'!$B$53)))))) -> 1400000 | AW26: =IF(48<=6,'前提'!$B$23*'前提'!$B$24,IF(48<=12,'前提'!$B$23*'前提'!$B$25,'前提'!$B$26*IF(48<=18,'前提'!$B$49,IF(48<=24,'前提'!$B$50,IF(48<=36,'前提'!$B$51,IF(48<=48,'前提'!$B$52,'前提'!$B$53)))))) -> 1400000 | AX26: =IF(49<=6,'前提'!$B$23*'前提'!$B$24,IF(49<=12,'前提'!$B$23*'前提'!$B$25,'前提'!$B$26*IF(49<=18,'前提'!$B$49,IF(49<=24,'前提'!$B$50,IF(49<=36,'前提'!$B$51,IF(49<=48,'前提'!$B$52,'前提'!$B$53)))))) -> 1400000 | AY26: =IF(50<=6,'前提'!$B$23*'前提'!$B$24,IF(50<=12,'前提'!$B$23*'前提'!$B$25,'前提'!$B$26*IF(50<=18,'前提'!$B$49,IF(50<=24,'前提'!$B$50,IF(50<=36,'前提'!$B$51,IF(50<=48,'前提'!$B$52,'前提'!$B$53)))))) -> 1400000 | AZ26: =IF(51<=6,'前提'!$B$23*'前提'!$B$24,IF(51<=12,'前提'!$B$23*'前提'!$B$25,'前提'!$B$26*IF(51<=18,'前提'!$B$49,IF(51<=24,'前提'!$B$50,IF(51<=36,'前提'!$B$51,IF(51<=48,'前提'!$B$52,'前提'!$B$53)))))) -> 1400000 | BA26: =IF(52<=6,'前提'!$B$23*'前提'!$B$24,IF(52<=12,'前提'!$B$23*'前提'!$B$25,'前提'!$B$26*IF(52<=18,'前提'!$B$49,IF(52<=24,'前提'!$B$50,IF(52<=36,'前提'!$B$51,IF(52<=48,'前提'!$B$52,'前提'!$B$53)))))) -> 1400000 | BB26: =IF(53<=6,'前提'!$B$23*'前提'!$B$24,IF(53<=12,'前提'!$B$23*'前提'!$B$25,'前提'!$B$26*IF(53<=18,'前提'!$B$49,IF(53<=24,'前提'!$B$50,IF(53<=36,'前提'!$B$51,IF(53<=48,'前提'!$B$52,'前提'!$B$53)))))) -> 1400000 | BC26: =IF(54<=6,'前提'!$B$23*'前提'!$B$24,IF(54<=12,'前提'!$B$23*'前提'!$B$25,'前提'!$B$26*IF(54<=18,'前提'!$B$49,IF(54<=24,'前提'!$B$50,IF(54<=36,'前提'!$B$51,IF(54<=48,'前提'!$B$52,'前提'!$B$53)))))) -> 1400000 | BD26: =IF(55<=6,'前提'!$B$23*'前提'!$B$24,IF(55<=12,'前提'!$B$23*'前提'!$B$25,'前提'!$B$26*IF(55<=18,'前提'!$B$49,IF(55<=24,'前提'!$B$50,IF(55<=36,'前提'!$B$51,IF(55<=48,'前提'!$B$52,'前提'!$B$53)))))) -> 1400000 | BE26: =IF(56<=6,'前提'!$B$23*'前提'!$B$24,IF(56<=12,'前提'!$B$23*'前提'!$B$25,'前提'!$B$26*IF(56<=18,'前提'!$B$49,IF(56<=24,'前提'!$B$50,IF(56<=36,'前提'!$B$51,IF(56<=48,'前提'!$B$52,'前提'!$B$53)))))) -> 1400000 | BF26: =IF(57<=6,'前提'!$B$23*'前提'!$B$24,IF(57<=12,'前提'!$B$23*'前提'!$B$25,'前提'!$B$26*IF(57<=18,'前提'!$B$49,IF(57<=24,'前提'!$B$50,IF(57<=36,'前提'!$B$51,IF(57<=48,'前提'!$B$52,'前提'!$B$53)))))) -> 1400000 | BG26: =IF(58<=6,'前提'!$B$23*'前提'!$B$24,IF(58<=12,'前提'!$B$23*'前提'!$B$25,'前提'!$B$26*IF(58<=18,'前提'!$B$49,IF(58<=24,'前提'!$B$50,IF(58<=36,'前提'!$B$51,IF(58<=48,'前提'!$B$52,'前提'!$B$53)))))) -> 1400000 | BH26: =IF(59<=6,'前提'!$B$23*'前提'!$B$24,IF(59<=12,'前提'!$B$23*'前提'!$B$25,'前提'!$B$26*IF(59<=18,'前提'!$B$49,IF(59<=24,'前提'!$B$50,IF(59<=36,'前提'!$B$51,IF(59<=48,'前提'!$B$52,'前提'!$B$53)))))) -> 1400000 | BI26: =IF(60<=6,'前提'!$B$23*'前提'!$B$24,IF(60<=12,'前提'!$B$23*'前提'!$B$25,'前提'!$B$26*IF(60<=18,'前提'!$B$49,IF(60<=24,'前提'!$B$50,IF(60<=36,'前提'!$B$51,IF(60<=48,'前提'!$B$52,'前提'!$B$53)))))) -> 1400000
A27: CS人件費 | B27: =IF(1<=6,0,CEILING(B10/'前提'!$B$44,1)*'前提'!$B$30) -> 0 | C27: =IF(2<=6,0,CEILING(C10/'前提'!$B$44,1)*'前提'!$B$30) -> 0 | D27: =IF(3<=6,0,CEILING(D10/'前提'!$B$44,1)*'前提'!$B$30) -> 0 | E27: =IF(4<=6,0,CEILING(E10/'前提'!$B$44,1)*'前提'!$B$30) -> 0 | F27: =IF(5<=6,0,CEILING(F10/'前提'!$B$44,1)*'前提'!$B$30) -> 0 | G27: =IF(6<=6,0,CEILING(G10/'前提'!$B$44,1)*'前提'!$B$30) -> 0 | H27: =IF(7<=6,0,CEILING(H10/'前提'!$B$44,1)*'前提'!$B$30) -> 350000 | I27: =IF(8<=6,0,CEILING(I10/'前提'!$B$44,1)*'前提'!$B$30) -> 350000 | J27: =IF(9<=6,0,CEILING(J10/'前提'!$B$44,1)*'前提'!$B$30) -> 350000 | K27: =IF(10<=6,0,CEILING(K10/'前提'!$B$44,1)*'前提'!$B$30) -> 700000 | L27: =IF(11<=6,0,CEILING(L10/'前提'!$B$44,1)*'前提'!$B$30) -> 700000 | M27: =IF(12<=6,0,CEILING(M10/'前提'!$B$44,1)*'前提'!$B$30) -> 700000 | N27: =IF(13<=6,0,CEILING(N10/'前提'!$B$44,1)*'前提'!$B$30) -> 700000 | O27: =IF(14<=6,0,CEILING(O10/'前提'!$B$44,1)*'前提'!$B$30) -> 700000 | P27: =IF(15<=6,0,CEILING(P10/'前提'!$B$44,1)*'前提'!$B$30) -> 700000 | Q27: =IF(16<=6,0,CEILING(Q10/'前提'!$B$44,1)*'前提'!$B$30) -> 700000 | R27: =IF(17<=6,0,CEILING(R10/'前提'!$B$44,1)*'前提'!$B$30) -> 1050000 | S27: =IF(18<=6,0,CEILING(S10/'前提'!$B$44,1)*'前提'!$B$30) -> 1050000 | T27: =IF(19<=6,0,CEILING(T10/'前提'!$B$44,1)*'前提'!$B$30) -> 1050000 | U27: =IF(20<=6,0,CEILING(U10/'前提'!$B$44,1)*'前提'!$B$30) -> 1050000 | V27: =IF(21<=6,0,CEILING(V10/'前提'!$B$44,1)*'前提'!$B$30) -> 1050000 | W27: =IF(22<=6,0,CEILING(W10/'前提'!$B$44,1)*'前提'!$B$30) -> 1050000 | X27: =IF(23<=6,0,CEILING(X10/'前提'!$B$44,1)*'前提'!$B$30) -> 1400000 | Y27: =IF(24<=6,0,CEILING(Y10/'前提'!$B$44,1)*'前提'!$B$30) -> 1400000 | Z27: =IF(25<=6,0,CEILING(Z10/'前提'!$B$44,1)*'前提'!$B$30) -> 1400000 | AA27: =IF(26<=6,0,CEILING(AA10/'前提'!$B$44,1)*'前提'!$B$30) -> 1400000 | AB27: =IF(27<=6,0,CEILING(AB10/'前提'!$B$44,1)*'前提'!$B$30) -> 1400000 | AC27: =IF(28<=6,0,CEILING(AC10/'前提'!$B$44,1)*'前提'!$B$30) -> 1750000 | AD27: =IF(29<=6,0,CEILING(AD10/'前提'!$B$44,1)*'前提'!$B$30) -> 1750000 | AE27: =IF(30<=6,0,CEILING(AE10/'前提'!$B$44,1)*'前提'!$B$30) -> 1750000 | AF27: =IF(31<=6,0,CEILING(AF10/'前提'!$B$44,1)*'前提'!$B$30) -> 1750000 | AG27: =IF(32<=6,0,CEILING(AG10/'前提'!$B$44,1)*'前提'!$B$30) -> 1750000 | AH27: =IF(33<=6,0,CEILING(AH10/'前提'!$B$44,1)*'前提'!$B$30) -> 2100000 | AI27: =IF(34<=6,0,CEILING(AI10/'前提'!$B$44,1)*'前提'!$B$30) -> 2100000 | AJ27: =IF(35<=6,0,CEILING(AJ10/'前提'!$B$44,1)*'前提'!$B$30) -> 2100000 | AK27: =IF(36<=6,0,CEILING(AK10/'前提'!$B$44,1)*'前提'!$B$30) -> 2100000 | AL27: =IF(37<=6,0,CEILING(AL10/'前提'!$B$44,1)*'前提'!$B$30) -> 2100000 | AM27: =IF(38<=6,0,CEILING(AM10/'前提'!$B$44,1)*'前提'!$B$30) -> 2450000 | AN27: =IF(39<=6,0,CEILING(AN10/'前提'!$B$44,1)*'前提'!$B$30) -> 2450000 | AO27: =IF(40<=6,0,CEILING(AO10/'前提'!$B$44,1)*'前提'!$B$30) -> 2450000 | AP27: =IF(41<=6,0,CEILING(AP10/'前提'!$B$44,1)*'前提'!$B$30) -> 2450000 | AQ27: =IF(42<=6,0,CEILING(AQ10/'前提'!$B$44,1)*'前提'!$B$30) -> 2450000 | AR27: =IF(43<=6,0,CEILING(AR10/'前提'!$B$44,1)*'前提'!$B$30) -> 2800000 | AS27: =IF(44<=6,0,CEILING(AS10/'前提'!$B$44,1)*'前提'!$B$30) -> 2800000 | AT27: =IF(45<=6,0,CEILING(AT10/'前提'!$B$44,1)*'前提'!$B$30) -> 2800000 | AU27: =IF(46<=6,0,CEILING(AU10/'前提'!$B$44,1)*'前提'!$B$30) -> 2800000 | AV27: =IF(47<=6,0,CEILING(AV10/'前提'!$B$44,1)*'前提'!$B$30) -> 2800000 | AW27: =IF(48<=6,0,CEILING(AW10/'前提'!$B$44,1)*'前提'!$B$30) -> 3150000 | AX27: =IF(49<=6,0,CEILING(AX10/'前提'!$B$44,1)*'前提'!$B$30) -> 3150000 | AY27: =IF(50<=6,0,CEILING(AY10/'前提'!$B$44,1)*'前提'!$B$30) -> 3150000 | AZ27: =IF(51<=6,0,CEILING(AZ10/'前提'!$B$44,1)*'前提'!$B$30) -> 3150000 | BA27: =IF(52<=6,0,CEILING(BA10/'前提'!$B$44,1)*'前提'!$B$30) -> 3500000 | BB27: =IF(53<=6,0,CEILING(BB10/'前提'!$B$44,1)*'前提'!$B$30) -> 3500000 | BC27: =IF(54<=6,0,CEILING(BC10/'前提'!$B$44,1)*'前提'!$B$30) -> 3500000 | BD27: =IF(55<=6,0,CEILING(BD10/'前提'!$B$44,1)*'前提'!$B$30) -> 3500000 | BE27: =IF(56<=6,0,CEILING(BE10/'前提'!$B$44,1)*'前提'!$B$30) -> 3850000 | BF27: =IF(57<=6,0,CEILING(BF10/'前提'!$B$44,1)*'前提'!$B$30) -> 3850000 | BG27: =IF(58<=6,0,CEILING(BG10/'前提'!$B$44,1)*'前提'!$B$30) -> 3850000 | BH27: =IF(59<=6,0,CEILING(BH10/'前提'!$B$44,1)*'前提'!$B$30) -> 3850000 | BI27: =IF(60<=6,0,CEILING(BI10/'前提'!$B$44,1)*'前提'!$B$30) -> 3850000
A28: 営業サポート | B28: ='前提'!$B$29*IF(1<=6,'前提'!$B$65,IF(1<=12,'前提'!$B$66,IF(1<=18,'前提'!$B$67,IF(1<=24,'前提'!$B$68,IF(1<=36,'前提'!$B$69,IF(1<=48,'前提'!$B$70,'前提'!$B$71)))))) -> 200000 | C28: ='前提'!$B$29*IF(2<=6,'前提'!$B$65,IF(2<=12,'前提'!$B$66,IF(2<=18,'前提'!$B$67,IF(2<=24,'前提'!$B$68,IF(2<=36,'前提'!$B$69,IF(2<=48,'前提'!$B$70,'前提'!$B$71)))))) -> 200000 | D28: ='前提'!$B$29*IF(3<=6,'前提'!$B$65,IF(3<=12,'前提'!$B$66,IF(3<=18,'前提'!$B$67,IF(3<=24,'前提'!$B$68,IF(3<=36,'前提'!$B$69,IF(3<=48,'前提'!$B$70,'前提'!$B$71)))))) -> 200000 | E28: ='前提'!$B$29*IF(4<=6,'前提'!$B$65,IF(4<=12,'前提'!$B$66,IF(4<=18,'前提'!$B$67,IF(4<=24,'前提'!$B$68,IF(4<=36,'前提'!$B$69,IF(4<=48,'前提'!$B$70,'前提'!$B$71)))))) -> 200000 | F28: ='前提'!$B$29*IF(5<=6,'前提'!$B$65,IF(5<=12,'前提'!$B$66,IF(5<=18,'前提'!$B$67,IF(5<=24,'前提'!$B$68,IF(5<=36,'前提'!$B$69,IF(5<=48,'前提'!$B$70,'前提'!$B$71)))))) -> 200000 | G28: ='前提'!$B$29*IF(6<=6,'前提'!$B$65,IF(6<=12,'前提'!$B$66,IF(6<=18,'前提'!$B$67,IF(6<=24,'前提'!$B$68,IF(6<=36,'前提'!$B$69,IF(6<=48,'前提'!$B$70,'前提'!$B$71)))))) -> 200000 | H28: ='前提'!$B$29*IF(7<=6,'前提'!$B$65,IF(7<=12,'前提'!$B$66,IF(7<=18,'前提'!$B$67,IF(7<=24,'前提'!$B$68,IF(7<=36,'前提'!$B$69,IF(7<=48,'前提'!$B$70,'前提'!$B$71)))))) -> 200000 | I28: ='前提'!$B$29*IF(8<=6,'前提'!$B$65,IF(8<=12,'前提'!$B$66,IF(8<=18,'前提'!$B$67,IF(8<=24,'前提'!$B$68,IF(8<=36,'前提'!$B$69,IF(8<=48,'前提'!$B$70,'前提'!$B$71)))))) -> 200000 | J28: ='前提'!$B$29*IF(9<=6,'前提'!$B$65,IF(9<=12,'前提'!$B$66,IF(9<=18,'前提'!$B$67,IF(9<=24,'前提'!$B$68,IF(9<=36,'前提'!$B$69,IF(9<=48,'前提'!$B$70,'前提'!$B$71)))))) -> 200000 | K28: ='前提'!$B$29*IF(10<=6,'前提'!$B$65,IF(10<=12,'前提'!$B$66,IF(10<=18,'前提'!$B$67,IF(10<=24,'前提'!$B$68,IF(10<=36,'前提'!$B$69,IF(10<=48,'前提'!$B$70,'前提'!$B$71)))))) -> 200000 | L28: ='前提'!$B$29*IF(11<=6,'前提'!$B$65,IF(11<=12,'前提'!$B$66,IF(11<=18,'前提'!$B$67,IF(11<=24,'前提'!$B$68,IF(11<=36,'前提'!$B$69,IF(11<=48,'前提'!$B$70,'前提'!$B$71)))))) -> 200000 | M28: ='前提'!$B$29*IF(12<=6,'前提'!$B$65,IF(12<=12,'前提'!$B$66,IF(12<=18,'前提'!$B$67,IF(12<=24,'前提'!$B$68,IF(12<=36,'前提'!$B$69,IF(12<=48,'前提'!$B$70,'前提'!$B$71)))))) -> 200000 | N28: ='前提'!$B$29*IF(13<=6,'前提'!$B$65,IF(13<=12,'前提'!$B$66,IF(13<=18,'前提'!$B$67,IF(13<=24,'前提'!$B$68,IF(13<=36,'前提'!$B$69,IF(13<=48,'前提'!$B$70,'前提'!$B$71)))))) -> 200000 | O28: ='前提'!$B$29*IF(14<=6,'前提'!$B$65,IF(14<=12,'前提'!$B$66,IF(14<=18,'前提'!$B$67,IF(14<=24,'前提'!$B$68,IF(14<=36,'前提'!$B$69,IF(14<=48,'前提'!$B$70,'前提'!$B$71)))))) -> 200000 | P28: ='前提'!$B$29*IF(15<=6,'前提'!$B$65,IF(15<=12,'前提'!$B$66,IF(15<=18,'前提'!$B$67,IF(15<=24,'前提'!$B$68,IF(15<=36,'前提'!$B$69,IF(15<=48,'前提'!$B$70,'前提'!$B$71)))))) -> 200000 | Q28: ='前提'!$B$29*IF(16<=6,'前提'!$B$65,IF(16<=12,'前提'!$B$66,IF(16<=18,'前提'!$B$67,IF(16<=24,'前提'!$B$68,IF(16<=36,'前提'!$B$69,IF(16<=48,'前提'!$B$70,'前提'!$B$71)))))) -> 200000 | R28: ='前提'!$B$29*IF(17<=6,'前提'!$B$65,IF(17<=12,'前提'!$B$66,IF(17<=18,'前提'!$B$67,IF(17<=24,'前提'!$B$68,IF(17<=36,'前提'!$B$69,IF(17<=48,'前提'!$B$70,'前提'!$B$71)))))) -> 200000 | S28: ='前提'!$B$29*IF(18<=6,'前提'!$B$65,IF(18<=12,'前提'!$B$66,IF(18<=18,'前提'!$B$67,IF(18<=24,'前提'!$B$68,IF(18<=36,'前提'!$B$69,IF(18<=48,'前提'!$B$70,'前提'!$B$71)))))) -> 200000 | T28: ='前提'!$B$29*IF(19<=6,'前提'!$B$65,IF(19<=12,'前提'!$B$66,IF(19<=18,'前提'!$B$67,IF(19<=24,'前提'!$B$68,IF(19<=36,'前提'!$B$69,IF(19<=48,'前提'!$B$70,'前提'!$B$71)))))) -> 200000 | U28: ='前提'!$B$29*IF(20<=6,'前提'!$B$65,IF(20<=12,'前提'!$B$66,IF(20<=18,'前提'!$B$67,IF(20<=24,'前提'!$B$68,IF(20<=36,'前提'!$B$69,IF(20<=48,'前提'!$B$70,'前提'!$B$71)))))) -> 200000 | V28: ='前提'!$B$29*IF(21<=6,'前提'!$B$65,IF(21<=12,'前提'!$B$66,IF(21<=18,'前提'!$B$67,IF(21<=24,'前提'!$B$68,IF(21<=36,'前提'!$B$69,IF(21<=48,'前提'!$B$70,'前提'!$B$71)))))) -> 200000 | W28: ='前提'!$B$29*IF(22<=6,'前提'!$B$65,IF(22<=12,'前提'!$B$66,IF(22<=18,'前提'!$B$67,IF(22<=24,'前提'!$B$68,IF(22<=36,'前提'!$B$69,IF(22<=48,'前提'!$B$70,'前提'!$B$71)))))) -> 200000 | X28: ='前提'!$B$29*IF(23<=6,'前提'!$B$65,IF(23<=12,'前提'!$B$66,IF(23<=18,'前提'!$B$67,IF(23<=24,'前提'!$B$68,IF(23<=36,'前提'!$B$69,IF(23<=48,'前提'!$B$70,'前提'!$B$71)))))) -> 200000 | Y28: ='前提'!$B$29*IF(24<=6,'前提'!$B$65,IF(24<=12,'前提'!$B$66,IF(24<=18,'前提'!$B$67,IF(24<=24,'前提'!$B$68,IF(24<=36,'前提'!$B$69,IF(24<=48,'前提'!$B$70,'前提'!$B$71)))))) -> 200000 | Z28: ='前提'!$B$29*IF(25<=6,'前提'!$B$65,IF(25<=12,'前提'!$B$66,IF(25<=18,'前提'!$B$67,IF(25<=24,'前提'!$B$68,IF(25<=36,'前提'!$B$69,IF(25<=48,'前提'!$B$70,'前提'!$B$71)))))) -> 400000 | AA28: ='前提'!$B$29*IF(26<=6,'前提'!$B$65,IF(26<=12,'前提'!$B$66,IF(26<=18,'前提'!$B$67,IF(26<=24,'前提'!$B$68,IF(26<=36,'前提'!$B$69,IF(26<=48,'前提'!$B$70,'前提'!$B$71)))))) -> 400000 | AB28: ='前提'!$B$29*IF(27<=6,'前提'!$B$65,IF(27<=12,'前提'!$B$66,IF(27<=18,'前提'!$B$67,IF(27<=24,'前提'!$B$68,IF(27<=36,'前提'!$B$69,IF(27<=48,'前提'!$B$70,'前提'!$B$71)))))) -> 400000 | AC28: ='前提'!$B$29*IF(28<=6,'前提'!$B$65,IF(28<=12,'前提'!$B$66,IF(28<=18,'前提'!$B$67,IF(28<=24,'前提'!$B$68,IF(28<=36,'前提'!$B$69,IF(28<=48,'前提'!$B$70,'前提'!$B$71)))))) -> 400000 | AD28: ='前提'!$B$29*IF(29<=6,'前提'!$B$65,IF(29<=12,'前提'!$B$66,IF(29<=18,'前提'!$B$67,IF(29<=24,'前提'!$B$68,IF(29<=36,'前提'!$B$69,IF(29<=48,'前提'!$B$70,'前提'!$B$71)))))) -> 400000 | AE28: ='前提'!$B$29*IF(30<=6,'前提'!$B$65,IF(30<=12,'前提'!$B$66,IF(30<=18,'前提'!$B$67,IF(30<=24,'前提'!$B$68,IF(30<=36,'前提'!$B$69,IF(30<=48,'前提'!$B$70,'前提'!$B$71)))))) -> 400000 | AF28: ='前提'!$B$29*IF(31<=6,'前提'!$B$65,IF(31<=12,'前提'!$B$66,IF(31<=18,'前提'!$B$67,IF(31<=24,'前提'!$B$68,IF(31<=36,'前提'!$B$69,IF(31<=48,'前提'!$B$70,'前提'!$B$71)))))) -> 400000 | AG28: ='前提'!$B$29*IF(32<=6,'前提'!$B$65,IF(32<=12,'前提'!$B$66,IF(32<=18,'前提'!$B$67,IF(32<=24,'前提'!$B$68,IF(32<=36,'前提'!$B$69,IF(32<=48,'前提'!$B$70,'前提'!$B$71)))))) -> 400000 | AH28: ='前提'!$B$29*IF(33<=6,'前提'!$B$65,IF(33<=12,'前提'!$B$66,IF(33<=18,'前提'!$B$67,IF(33<=24,'前提'!$B$68,IF(33<=36,'前提'!$B$69,IF(33<=48,'前提'!$B$70,'前提'!$B$71)))))) -> 400000 | AI28: ='前提'!$B$29*IF(34<=6,'前提'!$B$65,IF(34<=12,'前提'!$B$66,IF(34<=18,'前提'!$B$67,IF(34<=24,'前提'!$B$68,IF(34<=36,'前提'!$B$69,IF(34<=48,'前提'!$B$70,'前提'!$B$71)))))) -> 400000 | AJ28: ='前提'!$B$29*IF(35<=6,'前提'!$B$65,IF(35<=12,'前提'!$B$66,IF(35<=18,'前提'!$B$67,IF(35<=24,'前提'!$B$68,IF(35<=36,'前提'!$B$69,IF(35<=48,'前提'!$B$70,'前提'!$B$71)))))) -> 400000 | AK28: ='前提'!$B$29*IF(36<=6,'前提'!$B$65,IF(36<=12,'前提'!$B$66,IF(36<=18,'前提'!$B$67,IF(36<=24,'前提'!$B$68,IF(36<=36,'前提'!$B$69,IF(36<=48,'前提'!$B$70,'前提'!$B$71)))))) -> 400000 | AL28: ='前提'!$B$29*IF(37<=6,'前提'!$B$65,IF(37<=12,'前提'!$B$66,IF(37<=18,'前提'!$B$67,IF(37<=24,'前提'!$B$68,IF(37<=36,'前提'!$B$69,IF(37<=48,'前提'!$B$70,'前提'!$B$71)))))) -> 400000 | AM28: ='前提'!$B$29*IF(38<=6,'前提'!$B$65,IF(38<=12,'前提'!$B$66,IF(38<=18,'前提'!$B$67,IF(38<=24,'前提'!$B$68,IF(38<=36,'前提'!$B$69,IF(38<=48,'前提'!$B$70,'前提'!$B$71)))))) -> 400000 | AN28: ='前提'!$B$29*IF(39<=6,'前提'!$B$65,IF(39<=12,'前提'!$B$66,IF(39<=18,'前提'!$B$67,IF(39<=24,'前提'!$B$68,IF(39<=36,'前提'!$B$69,IF(39<=48,'前提'!$B$70,'前提'!$B$71)))))) -> 400000 | AO28: ='前提'!$B$29*IF(40<=6,'前提'!$B$65,IF(40<=12,'前提'!$B$66,IF(40<=18,'前提'!$B$67,IF(40<=24,'前提'!$B$68,IF(40<=36,'前提'!$B$69,IF(40<=48,'前提'!$B$70,'前提'!$B$71)))))) -> 400000 | AP28: ='前提'!$B$29*IF(41<=6,'前提'!$B$65,IF(41<=12,'前提'!$B$66,IF(41<=18,'前提'!$B$67,IF(41<=24,'前提'!$B$68,IF(41<=36,'前提'!$B$69,IF(41<=48,'前提'!$B$70,'前提'!$B$71)))))) -> 400000 | AQ28: ='前提'!$B$29*IF(42<=6,'前提'!$B$65,IF(42<=12,'前提'!$B$66,IF(42<=18,'前提'!$B$67,IF(42<=24,'前提'!$B$68,IF(42<=36,'前提'!$B$69,IF(42<=48,'前提'!$B$70,'前提'!$B$71)))))) -> 400000 | AR28: ='前提'!$B$29*IF(43<=6,'前提'!$B$65,IF(43<=12,'前提'!$B$66,IF(43<=18,'前提'!$B$67,IF(43<=24,'前提'!$B$68,IF(43<=36,'前提'!$B$69,IF(43<=48,'前提'!$B$70,'前提'!$B$71)))))) -> 400000 | AS28: ='前提'!$B$29*IF(44<=6,'前提'!$B$65,IF(44<=12,'前提'!$B$66,IF(44<=18,'前提'!$B$67,IF(44<=24,'前提'!$B$68,IF(44<=36,'前提'!$B$69,IF(44<=48,'前提'!$B$70,'前提'!$B$71)))))) -> 400000 | AT28: ='前提'!$B$29*IF(45<=6,'前提'!$B$65,IF(45<=12,'前提'!$B$66,IF(45<=18,'前提'!$B$67,IF(45<=24,'前提'!$B$68,IF(45<=36,'前提'!$B$69,IF(45<=48,'前提'!$B$70,'前提'!$B$71)))))) -> 400000 | AU28: ='前提'!$B$29*IF(46<=6,'前提'!$B$65,IF(46<=12,'前提'!$B$66,IF(46<=18,'前提'!$B$67,IF(46<=24,'前提'!$B$68,IF(46<=36,'前提'!$B$69,IF(46<=48,'前提'!$B$70,'前提'!$B$71)))))) -> 400000 | AV28: ='前提'!$B$29*IF(47<=6,'前提'!$B$65,IF(47<=12,'前提'!$B$66,IF(47<=18,'前提'!$B$67,IF(47<=24,'前提'!$B$68,IF(47<=36,'前提'!$B$69,IF(47<=48,'前提'!$B$70,'前提'!$B$71)))))) -> 400000 | AW28: ='前提'!$B$29*IF(48<=6,'前提'!$B$65,IF(48<=12,'前提'!$B$66,IF(48<=18,'前提'!$B$67,IF(48<=24,'前提'!$B$68,IF(48<=36,'前提'!$B$69,IF(48<=48,'前提'!$B$70,'前提'!$B$71)))))) -> 400000 | AX28: ='前提'!$B$29*IF(49<=6,'前提'!$B$65,IF(49<=12,'前提'!$B$66,IF(49<=18,'前提'!$B$67,IF(49<=24,'前提'!$B$68,IF(49<=36,'前提'!$B$69,IF(49<=48,'前提'!$B$70,'前提'!$B$71)))))) -> 600000 | AY28: ='前提'!$B$29*IF(50<=6,'前提'!$B$65,IF(50<=12,'前提'!$B$66,IF(50<=18,'前提'!$B$67,IF(50<=24,'前提'!$B$68,IF(50<=36,'前提'!$B$69,IF(50<=48,'前提'!$B$70,'前提'!$B$71)))))) -> 600000 | AZ28: ='前提'!$B$29*IF(51<=6,'前提'!$B$65,IF(51<=12,'前提'!$B$66,IF(51<=18,'前提'!$B$67,IF(51<=24,'前提'!$B$68,IF(51<=36,'前提'!$B$69,IF(51<=48,'前提'!$B$70,'前提'!$B$71)))))) -> 600000 | BA28: ='前提'!$B$29*IF(52<=6,'前提'!$B$65,IF(52<=12,'前提'!$B$66,IF(52<=18,'前提'!$B$67,IF(52<=24,'前提'!$B$68,IF(52<=36,'前提'!$B$69,IF(52<=48,'前提'!$B$70,'前提'!$B$71)))))) -> 600000 | BB28: ='前提'!$B$29*IF(53<=6,'前提'!$B$65,IF(53<=12,'前提'!$B$66,IF(53<=18,'前提'!$B$67,IF(53<=24,'前提'!$B$68,IF(53<=36,'前提'!$B$69,IF(53<=48,'前提'!$B$70,'前提'!$B$71)))))) -> 600000 | BC28: ='前提'!$B$29*IF(54<=6,'前提'!$B$65,IF(54<=12,'前提'!$B$66,IF(54<=18,'前提'!$B$67,IF(54<=24,'前提'!$B$68,IF(54<=36,'前提'!$B$69,IF(54<=48,'前提'!$B$70,'前提'!$B$71)))))) -> 600000 | BD28: ='前提'!$B$29*IF(55<=6,'前提'!$B$65,IF(55<=12,'前提'!$B$66,IF(55<=18,'前提'!$B$67,IF(55<=24,'前提'!$B$68,IF(55<=36,'前提'!$B$69,IF(55<=48,'前提'!$B$70,'前提'!$B$71)))))) -> 600000 | BE28: ='前提'!$B$29*IF(56<=6,'前提'!$B$65,IF(56<=12,'前提'!$B$66,IF(56<=18,'前提'!$B$67,IF(56<=24,'前提'!$B$68,IF(56<=36,'前提'!$B$69,IF(56<=48,'前提'!$B$70,'前提'!$B$71)))))) -> 600000 | BF28: ='前提'!$B$29*IF(57<=6,'前提'!$B$65,IF(57<=12,'前提'!$B$66,IF(57<=18,'前提'!$B$67,IF(57<=24,'前提'!$B$68,IF(57<=36,'前提'!$B$69,IF(57<=48,'前提'!$B$70,'前提'!$B$71)))))) -> 600000 | BG28: ='前提'!$B$29*IF(58<=6,'前提'!$B$65,IF(58<=12,'前提'!$B$66,IF(58<=18,'前提'!$B$67,IF(58<=24,'前提'!$B$68,IF(58<=36,'前提'!$B$69,IF(58<=48,'前提'!$B$70,'前提'!$B$71)))))) -> 600000 | BH28: ='前提'!$B$29*IF(59<=6,'前提'!$B$65,IF(59<=12,'前提'!$B$66,IF(59<=18,'前提'!$B$67,IF(59<=24,'前提'!$B$68,IF(59<=36,'前提'!$B$69,IF(59<=48,'前提'!$B$70,'前提'!$B$71)))))) -> 600000 | BI28: ='前提'!$B$29*IF(60<=6,'前提'!$B$65,IF(60<=12,'前提'!$B$66,IF(60<=18,'前提'!$B$67,IF(60<=24,'前提'!$B$68,IF(60<=36,'前提'!$B$69,IF(60<=48,'前提'!$B$70,'前提'!$B$71)))))) -> 600000
