Workbook

Sheet 前提
A1: SuguDesk 事業計画 前提条件
A3: 【価格前提】
A4: 導入費用（初期） | B4: 400000 | C4: 1院あたり
A5: 月額ENTRY | B5: 25000 | C5: チャットボット基本
A6: 月額EXPAND | B6: 75000 | C6: FAQ+運用サポート
A7: 月額DEEPEN | B7: 250000 | C7: BPO込み
A8: 月次チャーン率 | B8: 0.03
A9: EXPANDアップセル率（月次） | B9: 0.15 | C9: 平均6.7ヶ月でEXPANDアップセル
A10: DEEPENアップセル率（月次） | B10: 0.05 | C10: EXPAND 20院で月1件アップセル
A12: 【営業前提（月間新規契約数）】
A13: Phase1（M1-M6） | B13: 2
A14: Phase2（M7-M12） | B14: 3
A15: Phase3（M13-M18） | B15: 8
A16: Phase4（M19-M36） | B16: 15
A17: Phase5（M37-M60） | B17: 25
A19: 【コスト前提（月額）】
A20: 代表報酬 | B20: 350000
A21: エンジニア（正社員） | B21: 700000 | C21: CTO / フルスタック
A22: CS（業務委託） | B22: 200000 | C22: FAQ構築・クライアント対応
A23: 営業人件費/人 | B23: 400000 | C23: 外注で検討
A24: LLM API変動費/院 | B24: 2000 | C24: Claude API等
A25: インフラ・ツール | B25: 100000 | C25: Dify API, AWS, SaaS
A26: その他固定費 | B26: 50000 | C26: 法務・会計・雑費
A27: 事務長 単価/人（月額） | B27: 300000 | C27: 提案・設計担当（業務委託）
A28: BPOオペ 単価/人（月額） | B28: 150000 | C28: 標準化業務の実行担当
A29: 【人員計画（人数）】
B30: エンジニア正社員 | C30: CS | D30: 営業
A31: Phase1（M1-M6） | B31: 0.5 | C31: 0 | D31: 0
A32: Phase2（M7-M12） | B32: 1 | C32: 1 | D32: 1
A33: Phase3（M13-M18） | B33: 1 | C33: 1 | D33: 1
A34: Phase4（M19-M36） | B34: 1 | C34: 2 | D34: 2
A35: Phase5（M37-M60） | B35: 1 | C35: 4 | D35: 4
A36: ※営業はPhase1内M7から1名開始
A38: 【営業ファネル前提】
A39: 商談→契約率（受注率） | B39: 0.25
A40: アプローチ→商談化率（アウトバウンド） | B40: 0.01
A41: アプローチ→商談化率（紹介） | B41: 0.3
A43: チャネル比率 | B43: Phase1 | C43: Phase2 | D43: Phase3以降
A44: 紹介比率 | B44: 0.5 | C44: 0.3 | D44: 0.2
A45: アウトバウンド比率 | B45: 0.5 | C45: 0.7 | D45: 0.8
...

Sheet 月次事業計画
A1: SuguDesk 月次事業計画
A2: フェーズ | B2: Phase1 | C2: Phase1 | D2: Phase1 | E2: Phase1 | F2: Phase1 | G2: Phase1 | H2: Phase1 | I2: Phase1 | J2: Phase1 | K2: Phase1 | L2: Phase1 | M2: Phase1 | N2: Phase2 | O2: Phase2 | P2: Phase2 | Q2: Phase2 | R2: Phase2 | S2: Phase2 | T2: Phase2 | U2: Phase2 | V2: Phase2 | W2: Phase2 | X2: Phase2 | Y2: Phase2 | Z2: Phase3 | AA2: Phase3 | AB2: Phase3 | AC2: Phase3 | AD2: Phase3 | AE2: Phase3 | AF2: Phase3 | AG2: Phase3 | AH2: Phase3 | AI2: Phase3 | AJ2: Phase3 | AK2: Phase3 | AL2: Phase4 | AM2: Phase4 | AN2: Phase4 | AO2: Phase4 | AP2: Phase4 | AQ2: Phase4 | AR2: Phase4 | AS2: Phase4 | AT2: Phase4 | AU2: Phase4 | AV2: Phase4 | AW2: Phase4 | AX2: Phase5 | AY2: Phase5 | AZ2: Phase5 | BA2: Phase5 | BB2: Phase5 | BC2: Phase5 | BD2: Phase5 | BE2: Phase5 | BF2: Phase5 | BG2: Phase5 | BH2: Phase5 | BI2: Phase5
A3: 月 | B3: M1 | C3: M2 | D3: M3 | E3: M4 | F3: M5 | G3: M6 | H3: M7 | I3: M8 | J3: M9 | K3: M10 | L3: M11 | M3: M12 | N3: M13 | O3: M14 | P3: M15 | Q3: M16 | R3: M17 | S3: M18 | T3: M19 | U3: M20 | V3: M21 | W3: M22 | X3: M23 | Y3: M24 | Z3: M25 | AA3: M26 | AB3: M27 | AC3: M28 | AD3: M29 | AE3: M30 | AF3: M31 | AG3: M32 | AH3: M33 | AI3: M34 | AJ3: M35 | AK3: M36 | AL3: M37 | AM3: M38 | AN3: M39 | AO3: M40 | AP3: M41 | AQ3: M42 | AR3: M43 | AS3: M44 | AT3: M45 | AU3: M46 | AV3: M47 | AW3: M48 | AX3: M49 | AY3: M50 | AZ3: M51 | BA3: M52 | BB3: M53 | BC3: M54 | BD3: M55 | BE3: M56 | BF3: M57 | BG3: M58 | BH3: M59 | BI3: M60
A4: 【営業活動】
A5: 月間必要契約数 | B5: ='前提'!$B$13 -> 2 | C5: ='前提'!$B$13 -> 2 | D5: ='前提'!$B$13 -> 2 | E5: ='前提'!$B$13 -> 2 | F5: ='前提'!$B$13 -> 2 | G5: ='前提'!$B$13 -> 2 | H5: ='前提'!$B$14 -> 3 | I5: ='前提'!$B$14 -> 3 | J5: ='前提'!$B$14 -> 3 | K5: ='前提'!$B$14 -> 3 | L5: ='前提'!$B$14 -> 3 | M5: ='前提'!$B$14 -> 3 | N5: ='前提'!$B$15 -> 8 | O5: ='前提'!$B$15 -> 8 | P5: ='前提'!$B$15 -> 8 | Q5: ='前提'!$B$15 -> 8 | R5: ='前提'!$B$15 -> 8 | S5: ='前提'!$B$15 -> 8 | T5: ='前提'!$B$16 -> 15 | U5: ='前提'!$B$16 -> 15 | V5: ='前提'!$B$16 -> 15 | W5: ='前提'!$B$16 -> 15 | X5: ='前提'!$B$16 -> 15 | Y5: ='前提'!$B$16 -> 15 | Z5: ='前提'!$B$16 -> 15 | AA5: ='前提'!$B$16 -> 15 | ... AK5: ='前提'!$B$16 -> 15 | AL5: ='前提'!$B$17 -> 25 | AM5: ='前提'!$B$17 -> 25 | AN5: ='前提'!$B$17 -> 25 | AO5: ='前提'!$B$17 -> 25 | AP5: ='前提'!$B$17 -> 25 | AQ5: ='前提'!$B$17 -> 25 | AR5: ='前提'!$B$17 -> 25 | AS5: ='前提'!$B$17 -> 25 | ... BI5: ='前提'!$B$17 -> 25
A6: 必要商談数 | B6: =ROUNDUP(B5/'前提'!$B$39,0) -> 8 | C6: =ROUNDUP(C5/'前提'!$B$39,0) -> 8 | D6: =ROUNDUP(D5/'前提'!$B$39,0) -> 8 | E6: =ROUNDUP(E5/'前提'!$B$39,0) -> 8 | F6: =ROUNDUP(F5/'前提'!$B$39,0) -> 8 | G6: =ROUNDUP(G5/'前提'!$B$39,0) -> 8 | H6: =ROUNDUP(H5/'前提'!$B$39,0) -> 12 | I6: =ROUNDUP(I5/'前提'!$B$39,0) -> 12 | ... BI6: =ROUNDUP(BI5/'前提'!$B$39,0) -> 100
A7: 必要アプローチ数 | B7: =IF('前提'!$B$46>0,ROUNDUP(B6/'前提'!$B$46,0),0) -> 52 | C7: =IF('前提'!$B$46>0,ROUNDUP(C6/'前提'!$B$46,0),0) -> 52 | D7: =IF('前提'!$B$46>0,ROUNDUP(D6/'前提'!$B$46,0),0) -> 52 | E7: =IF('前提'!$B$46>0,ROUNDUP(E6/'前提'!$B$46,0),0) -> 52 | F7: =IF('前提'!$B$46>0,ROUNDUP(F6/'前提'!$B$46,0),0) -> 52 | G7: =IF('前提'!$B$46>0,ROUNDUP(G6/'前提'!$B$46,0),0) -> 52 | H7: =IF('前提'!$B$46>0,ROUNDUP(H6/'前提'!$B$46,0),0) -> 78 | I7: =IF('前提'!$B$46>0,ROUNDUP(I6/'前提'!$B$46,0),0) -> 78 | ... S7: =IF('前提'!$B$46>0,ROUNDUP(S6/'前提'!$B$46,0),0) -> 207 | T7: =IF('前提'!$C$46>0,ROUNDUP(T6/'前提'!$C$46,0),0) -> 619 | U7: =IF('前提'!$C$46>0,ROUNDUP(U6/'前提'!$C$46,0),0) -> 619 | V7: =IF('前提'!$C$46>0,ROUNDUP(V6/'前提'!$C$46,0),0) -> 619 | W7: =IF('前提'!$C$46>0,ROUNDUP(W6/'前提'!$C$46,0),0) -> 619 | X7: =IF('前提'!$C$46>0,ROUNDUP(X6/'前提'!$C$46,0),0) -> 619 | Y7: =IF('前提'!$C$46>0,ROUNDUP(Y6/'前提'!$C$46,0),0) -> 619 | Z7: =IF('前提'!$C$46>0,ROUNDUP(Z6/'前提'!$C$46,0),0) -> 619 | AA7: =IF('前提'!$C$46>0,ROUNDUP(AA6/'前提'!$C$46,0),0) -> 619 | ... AK7: =IF('前提'!$C$46>0,ROUNDUP(AK6/'前提'!$C$46,0),0) -> 619 | AL7: =IF('前提'!$D$46>0,ROUNDUP(AL6/'前提'!$D$46,0),0) -> 1471 | AM7: =IF('前提'!$D$46>0,ROUNDUP(AM6/'前提'!$D$46,0),0) -> 1471 | AN7: =IF('前提'!$D$46>0,ROUNDUP(AN6/'前提'!$D$46,0),0) -> 1471 | AO7: =IF('前提'!$D$46>0,ROUNDUP(AO6/'前提'!$D$46,0),0) -> 1471 | AP7: =IF('前提'!$D$46>0,ROUNDUP(AP6/'前提'!$D$46,0),0) -> 1471 | AQ7: =IF('前提'!$D$46>0,ROUNDUP(AQ6/'前提'!$D$46,0),0) -> 1471 | AR7: =IF('前提'!$D$46>0,ROUNDUP(AR6/'前提'!$D$46,0),0) -> 1471 | AS7: =IF('前提'!$D$46>0,ROUNDUP(AS6/'前提'!$D$46,0),0) -> 1471 | ... BI7: =IF('前提'!$D$46>0,ROUNDUP(BI6/'前提'!$D$46,0),0) -> 1471
A8: 必要外注営業人月 | B8: =IF('前提'!$B$48>0,B7/'前提'!$B$48,0) -> 0.43333333 | C8: =IF('前提'!$B$48>0,C7/'前提'!$B$48,0) -> 0.43333333 | D8: =IF('前提'!$B$48>0,D7/'前提'!$B$48,0) -> 0.43333333 | E8: =IF('前提'!$B$48>0,E7/'前提'!$B$48,0) -> 0.43333333 | F8: =IF('前提'!$B$48>0,F7/'前提'!$B$48,0) -> 0.43333333 | G8: =IF('前提'!$B$48>0,G7/'前提'!$B$48,0) -> 0.43333333 | H8: =IF('前提'!$B$48>0,H7/'前提'!$B$48,0) -> 0.65 | I8: =IF('前提'!$B$48>0,I7/'前提'!$B$48,0) -> 0.65 | ... BI8: =IF('前提'!$B$48>0,BI7/'前提'!$B$48,0) -> 12.258333
A9: 営業外注コスト | B9: =ROUNDUP(B8,0)*'前提'!$B$49 -> 400000 | C9: =ROUNDUP(C8,0)*'前提'!$B$49 -> 400000 | D9: =ROUNDUP(D8,0)*'前提'!$B$49 -> 400000 | E9: =ROUNDUP(E8,0)*'前提'!$B$49 -> 400000 | F9: =ROUNDUP(F8,0)*'前提'!$B$49 -> 400000 | G9: =ROUNDUP(G8,0)*'前提'!$B$49 -> 400000 | H9: =ROUNDUP(H8,0)*'前提'!$B$49 -> 400000 | I9: =ROUNDUP(I8,0)*'前提'!$B$49 -> 400000 | ... BI9: =ROUNDUP(BI8,0)*'前提'!$B$49 -> 5200000
A11: 【顧客数】
A12: 新規契約数 | B12: ='前提'!$B$13 -> 2 | C12: ='前提'!$B$13 -> 2 | D12: ='前提'!$B$13 -> 2 | E12: ='前提'!$B$13 -> 2 | F12: ='前提'!$B$13 -> 2 | G12: ='前提'!$B$13 -> 2 | H12: ='前提'!$B$14 -> 3 | I12: ='前提'!$B$14 -> 3 | J12: ='前提'!$B$14 -> 3 | K12: ='前提'!$B$14 -> 3 | L12: ='前提'!$B$14 -> 3 | M12: ='前提'!$B$14 -> 3 | N12: ='前提'!$B$15 -> 8 | O12: ='前提'!$B$15 -> 8 | P12: ='前提'!$B$15 -> 8 | Q12: ='前提'!$B$15 -> 8 | R12: ='前提'!$B$15 -> 8 | S12: ='前提'!$B$15 -> 8 | T12: ='前提'!$B$16 -> 15 | U12: ='前提'!$B$16 -> 15 | V12: ='前提'!$B$16 -> 15 | W12: ='前提'!$B$16 -> 15 | X12: ='前提'!$B$16 -> 15 | Y12: ='前提'!$B$16 -> 15 | Z12: ='前提'!$B$16 -> 15 | AA12: ='前提'!$B$16 -> 15 | ... AK12: ='前提'!$B$16 -> 15 | AL12: ='前提'!$B$17 -> 25 | AM12: ='前提'!$B$17 -> 25 | AN12: ='前提'!$B$17 -> 25 | AO12: ='前提'!$B$17 -> 25 | AP12: ='前提'!$B$17 -> 25 | AQ12: ='前提'!$B$17 -> 25 | AR12: ='前提'!$B$17 -> 25 | AS12: ='前提'!$B$17 -> 25 | ... BI12: ='前提'!$B$17 -> 25
A13: 解約数 | B13: =ROUNDDOWN(B14*'前提'!$B$8,0) -> 0 | C13: =ROUNDDOWN(C14*'前提'!$B$8,0) -> 0 | D13: =ROUNDDOWN(D14*'前提'!$B$8,0) -> 0 | E13: =ROUNDDOWN(E14*'前提'!$B$8,0) -> 0 | F13: =ROUNDDOWN(F14*'前提'!$B$8,0) -> 0 | G13: =ROUNDDOWN(G14*'前提'!$B$8,0) -> 0 | H13: =ROUNDDOWN(H14*'前提'!$B$8,0) -> 0 | I13: =ROUNDDOWN(I14*'前提'!$B$8,0) -> 0 | ... BI13: =ROUNDDOWN(BI14*'前提'!$B$8,0) -> 16
A14: 期首顧客数 | B14: 1 | C14: =B15 -> 3 | D14: =C15 -> 5 | E14: =D15 -> 7 | F14: =E15 -> 9 | G14: =F15 -> 11 | H14: =G15 -> 13 | I14: =H15 -> 16 | J14: =I15 -> 19 | ... BI14: =BH15 -> 558
A15: 期末顧客数 | B15: =B14+B12-B13 -> 3 | C15: =C14+C12-C13 -> 5 | D15: =D14+D12-D13 -> 7 | E15: =E14+E12-E13 -> 9 | F15: =F14+F12-F13 -> 11 | G15: =G14+G12-G13 -> 13 | H15: =H14+H12-H13 -> 16 | I15: =I14+I12-I13 -> 19 | ... BI15: =BI14+BI12-BI13 -> 567
A16: ENTRY | B16: =B15 -> 3 | C16: =MAX(0,B16+C12-ROUNDDOWN(B16*'前提'!$B$8,0)-ROUNDDOWN(B16*'前提'!$B$9,0)) -> 5 | D16: =MAX(0,C16+D12-ROUNDDOWN(C16*'前提'!$B$8,0)-ROUNDDOWN(C16*'前提'!$B$9,0)) -> 7 | E16: =MAX(0,D16+E12-ROUNDDOWN(D16*'前提'!$B$8,0)-ROUNDDOWN(D16*'前提'!$B$9,0)) -> 8 | F16: =MAX(0,E16+F12-ROUNDDOWN(E16*'前提'!$B$8,0)-ROUNDDOWN(E16*'前提'!$B$9,0)) -> 9 | G16: =MAX(0,F16+G12-ROUNDDOWN(F16*'前提'!$B$8,0)-ROUNDDOWN(F16*'前提'!$B$9,0)) -> 10 | H16: =MAX(0,G16+H12-ROUNDDOWN(G16*'前提'!$B$8,0)-ROUNDDOWN(G16*'前提'!$B$9,0)) -> 12 | I16: =MAX(0,H16+I12-ROUNDDOWN(H16*'前提'!$B$8,0)-ROUNDDOWN(H16*'前提'!$B$9,0)) -> 14 | J16: =MAX(0,I16+J12-ROUNDDOWN(I16*'前提'!$B$8,0)-ROUNDDOWN(I16*'前提'!$B$9,0)) -> 15 | ... BI16: =MAX(0,BH16+BI12-ROUNDDOWN(BH16*'前提'!$B$8,0)-ROUNDDOWN(BH16*'前提'!$B$9,0)) -> 140
A17: EXPAND | B17: 0 | C17: =MAX(0,B17+ROUNDDOWN(B16*'前提'!$B$9,0)-ROUNDDOWN(B17*'前提'!$B$8,0)-ROUNDDOWN(B17*'前提'!$B$10,0)) -> 0 | D17: =MAX(0,C17+ROUNDDOWN(C16*'前提'!$B$9,0)-ROUNDDOWN(C17*'前提'!$B$8,0)-ROUNDDOWN(C17*'前提'!$B$10,0)) -> 0 | E17: =MAX(0,D17+ROUNDDOWN(D16*'前提'!$B$9,0)-ROUNDDOWN(D17*'前提'!$B$8,0)-ROUNDDOWN(D17*'前提'!$B$10,0)) -> 1 | F17: =MAX(0,E17+ROUNDDOWN(E16*'前提'!$B$9,0)-ROUNDDOWN(E17*'前提'!$B$8,0)-ROUNDDOWN(E17*'前提'!$B$10,0)) -> 2 | G17: =MAX(0,F17+ROUNDDOWN(F16*'前提'!$B$9,0)-ROUNDDOWN(F17*'前提'!$B$8,0)-ROUNDDOWN(F17*'前提'!$B$10,0)) -> 3 | H17: =MAX(0,G17+ROUNDDOWN(G16*'前提'!$B$9,0)-ROUNDDOWN(G17*'前提'!$B$8,0)-ROUNDDOWN(G17*'前提'!$B$10,0)) -> 4 | I17: =MAX(0,H17+ROUNDDOWN(H16*'前提'!$B$9,0)-ROUNDDOWN(H17*'前提'!$B$8,0)-ROUNDDOWN(H17*'前提'!$B$10,0)) -> 5 | J17: =MAX(0,I17+ROUNDDOWN(I16*'前提'!$B$9,0)-ROUNDDOWN(I17*'前提'!$B$8,0)-ROUNDDOWN(I17*'前提'!$B$10,0)) -> 7 | ... BI17: =MAX(0,BH17+ROUNDDOWN(BH16*'前提'!$B$9,0)-ROUNDDOWN(BH17*'前提'!$B$8,0)-ROUNDDOWN(BH17*'前提'!$B$10,0)) -> 245
A18: DEEPEN | B18: 0 | C18: =MAX(0,B18+ROUNDDOWN(B17*'前提'!$B$10,0)-ROUNDDOWN(B18*'前提'!$B$8,0)) -> 0 | D18: =MAX(0,C18+ROUNDDOWN(C17*'前提'!$B$10,0)-ROUNDDOWN(C18*'前提'!$B$8,0)) -> 0 | E18: =MAX(0,D18+ROUNDDOWN(D17*'前提'!$B$10,0)-ROUNDDOWN(D18*'前提'!$B$8,0)) -> 0 | F18: =MAX(0,E18+ROUNDDOWN(E17*'前提'!$B$10,0)-ROUNDDOWN(E18*'前提'!$B$8,0)) -> 0 | G18: =MAX(0,F18+ROUNDDOWN(F17*'前提'!$B$10,0)-ROUNDDOWN(F18*'前提'!$B$8,0)) -> 0 | H18: =MAX(0,G18+ROUNDDOWN(G17*'前提'!$B$10,0)-ROUNDDOWN(G18*'前提'!$B$8,0)) -> 0 | I18: =MAX(0,H18+ROUNDDOWN(H17*'前提'!$B$10,0)-ROUNDDOWN(H18*'前提'!$B$8,0)) -> 0 | J18: =MAX(0,I18+ROUNDDOWN(I17*'前提'!$B$10,0)-ROUNDDOWN(I18*'前提'!$B$8,0)) -> 0 | ... BI18: =MAX(0,BH18+ROUNDDOWN(BH17*'前提'!$B$10,0)-ROUNDDOWN(BH18*'前提'!$B$8,0)) -> 200
A20: 【売上】
A21: ENTRY月額売上 | B21: =B16*'前提'!$B$5 -> 75000 | C21: =C16*'前提'!$B$5 -> 125000 | D21: =D16*'前提'!$B$5 -> 175000 | E21: =E16*'前提'!$B$5 -> 200000 | F21: =F16*'前提'!$B$5 -> 225000 | G21: =G16*'前提'!$B$5 -> 250000 | H21: =H16*'前提'!$B$5 -> 300000 | I21: =I16*'前提'!$B$5 -> 350000 | ... BI21: =BI16*'前提'!$B$5 -> 3500000
A22: EXPAND月額売上 | B22: =B17*'前提'!$B$6 -> 0 | C22: =C17*'前提'!$B$6 -> 0 | D22: =D17*'前提'!$B$6 -> 0 | E22: =E17*'前提'!$B$6 -> 75000 | F22: =F17*'前提'!$B$6 -> 150000 | G22: =G17*'前提'!$B$6 -> 225000 | H22: =H17*'前提'!$B$6 -> 300000 | I22: =I17*'前提'!$B$6 -> 375000 | ... BI22: =BI17*'前提'!$B$6 -> 18375000
A23: DEEPEN月額売上 | B23: =B18*'前提'!$B$7 -> 0 | C23: =C18*'前提'!$B$7 -> 0 | D23: =D18*'前提'!$B$7 -> 0 | E23: =E18*'前提'!$B$7 -> 0 | F23: =F18*'前提'!$B$7 -> 0 | G23: =G18*'前提'!$B$7 -> 0 | H23: =H18*'前提'!$B$7 -> 0 | I23: =I18*'前提'!$B$7 -> 0 | ... BI23: =BI18*'前提'!$B$7 -> 50000000
A24: 月額売上小計 | B24: =B21+B22+B23 -> 75000 | C24: =C21+C22+C23 -> 125000 | D24: =D21+D22+D23 -> 175000 | E24: =E21+E22+E23 -> 275000 | F24: =F21+F22+F23 -> 375000 | G24: =G21+G22+G23 -> 475000 | H24: =H21+H22+H23 -> 600000 | I24: =I21+I22+I23 -> 725000 | ... BI24: =BI21+BI22+BI23 -> 71875000
A25: 導入費用 | B25: =B12*'前提'!$B$4 -> 800000 | C25: =C12*'前提'!$B$4 -> 800000 | D25: =D12*'前提'!$B$4 -> 800000 | E25: =E12*'前提'!$B$4 -> 800000 | F25: =F12*'前提'!$B$4 -> 800000 | G25: =G12*'前提'!$B$4 -> 800000 | H25: =H12*'前提'!$B$4 -> 1200000 | I25: =I12*'前提'!$B$4 -> 1200000 | ... BI25: =BI12*'前提'!$B$4 -> 10000000
A26: 売上合計 | B26: =B24+B25 -> 875000 | C26: =C24+C25 -> 925000 | D26: =D24+D25 -> 975000 | E26: =E24+E25 -> 1075000 | F26: =F24+F25 -> 1175000 | G26: =G24+G25 -> 1275000 | H26: =H24+H25 -> 1800000 | I26: =I24+I25 -> 1925000 | ... BI26: =BI24+BI25 -> 81875000
A27: MRR | B27: =B24 -> 75000 | C27: =C24 -> 125000 | D27: =D24 -> 175000 | E27: =E24 -> 275000 | F27: =F24 -> 375000 | G27: =G24 -> 475000 | H27: =H24 -> 600000 | I27: =I24 -> 725000 | ... BI27: =BI24 -> 71875000
A29: 【コスト】
A30: 代表報酬 | B30: ='前提'!$B$20 -> 350000 | C30: ='前提'!$B$20 -> 350000 | D30: ='前提'!$B$20 -> 350000 | E30: ='前提'!$B$20 -> 350000 | F30: ='前提'!$B$20 -> 350000 | G30: ='前提'!$B$20 -> 350000 | H30: ='前提'!$B$20 -> 350000 | I30: ='前提'!$B$20 -> 350000 | ... BI30: ='前提'!$B$20 -> 350000
A31: エンジニア（正社員） | B31: ='前提'!$B$21*'前提'!$B$31 -> 350000 | C31: ='前提'!$B$21*'前提'!$B$31 -> 350000 | D31: ='前提'!$B$21*'前提'!$B$31 -> 350000 | E31: ='前提'!$B$21*'前提'!$B$31 -> 350000 | F31: ='前提'!$B$21*'前提'!$B$31 -> 350000 | G31: ='前提'!$B$21*'前提'!$B$31 -> 350000 | H31: ='前提'!$B$21*'前提'!$B$32 -> 700000 | I31: ='前提'!$B$21*'前提'!$B$32 -> 700000 | J31: ='前提'!$B$21*'前提'!$B$32 -> 700000 | K31: ='前提'!$B$21*'前提'!$B$32 -> 700000 | L31: ='前提'!$B$21*'前提'!$B$32 -> 700000 | M31: ='前提'!$B$21*'前提'!$B$32 -> 700000 | N31: ='前提'!$B$21*'前提'!$B$33 -> 700000 | O31: ='前提'!$B$21*'前提'!$B$33 -> 700000 | P31: ='前提'!$B$21*'前提'!$B$33 -> 700000 | Q31: ='前提'!$B$21*'前提'!$B$33 -> 700000 | R31: ='前提'!$B$21*'前提'!$B$33 -> 700000 | S31: ='前提'!$B$21*'前提'!$B$33 -> 700000 | T31: ='前提'!$B$21*'前提'!$B$34 -> 700000 | U31: ='前提'!$B$21*'前提'!$B$34 -> 700000 | V31: ='前提'!$B$21*'前提'!$B$34 -> 700000 | W31: ='前提'!$B$21*'前提'!$B$34 -> 700000 | X31: ='前提'!$B$21*'前提'!$B$34 -> 700000 | Y31: ='前提'!$B$21*'前提'!$B$34 -> 700000 | Z31: ='前提'!$B$21*'前提'!$B$34 -> 700000 | AA31: ='前提'!$B$21*'前提'!$B$34 -> 700000 | ... AK31: ='前提'!$B$21*'前提'!$B$34 -> 700000 | AL31: ='前提'!$B$21*'前提'!$B$35 -> 700000 | AM31: ='前提'!$B$21*'前提'!$B$35 -> 700000 | AN31: ='前提'!$B$21*'前提'!$B$35 -> 700000 | AO31: ='前提'!$B$21*'前提'!$B$35 -> 700000 | AP31: ='前提'!$B$21*'前提'!$B$35 -> 700000 | AQ31: ='前提'!$B$21*'前提'!$B$35 -> 700000 | AR31: ='前提'!$B$21*'前提'!$B$35 -> 700000 | AS31: ='前提'!$B$21*'前提'!$B$35 -> 700000 | ... BI31: ='前提'!$B$21*'前提'!$B$35 -> 700000
A32: 開発外注 | B32: 0 | C32: 0 | D32: 0 | E32: 0 | F32: 0 | G32: 0 | H32: 0 | I32: 0 | J32: 0 | K32: 0 | L32: 0 | M32: 0 | N32: 0 | O32: 0 | P32: 0 | Q32: 0 | R32: 0 | S32: 0 | T32: 300000 | U32: 300000 | V32: 300000 | W32: 300000 | X32: 300000 | Y32: 300000 | Z32: 300000 | AA32: 300000 | AB32: 300000 | AC32: 300000 | AD32: 300000 | AE32: 300000 | AF32: 300000 | AG32: 300000 | AH32: 300000 | AI32: 300000 | AJ32: 300000 | AK32: 300000 | AL32: 500000 | AM32: 500000 | AN32: 500000 | AO32: 500000 | AP32: 500000 | AQ32: 500000 | AR32: 500000 | AS32: 500000 | AT32: 500000 | AU32: 500000 | AV32: 500000 | AW32: 500000 | AX32: 500000 | AY32: 500000 | AZ32: 500000 | BA32: 500000 | BB32: 500000 | BC32: 500000 | BD32: 500000 | BE32: 500000 | BF32: 500000 | BG32: 500000 | BH32: 500000 | BI32: 500000
A33: CS人件費 | B33: 0 | C33: 0 | D33: 0 | E33: 0 | F33: 0 | G33: 0 | H33: ='前提'!$B$22*'前提'!$C$32 -> 200000 | I33: ='前提'!$B$22*'前提'!$C$32 -> 200000 | J33: ='前提'!$B$22*'前提'!$C$32 -> 200000 | K33: ='前提'!$B$22*'前提'!$C$32 -> 200000 | L33: ='前提'!$B$22*'前提'!$C$32 -> 200000 | M33: ='前提'!$B$22*'前提'!$C$32 -> 200000 | N33: ='前提'!$B$22*'前提'!$C$33 -> 200000 | O33: ='前提'!$B$22*'前提'!$C$33 -> 200000 | P33: ='前提'!$B$22*'前提'!$C$33 -> 200000 | Q33: ='前提'!$B$22*'前提'!$C$33 -> 200000 | R33: ='前提'!$B$22*'前提'!$C$33 -> 200000 | S33: ='前提'!$B$22*'前提'!$C$33 -> 200000 | T33: ='前提'!$B$22*'前提'!$C$34 -> 400000 | U33: ='前提'!$B$22*'前提'!$C$34 -> 400000 | V33: ='前提'!$B$22*'前提'!$C$34 -> 400000 | W33: ='前提'!$B$22*'前提'!$C$34 -> 400000 | X33: ='前提'!$B$22*'前提'!$C$34 -> 400000 | Y33: ='前提'!$B$22*'前提'!$C$34 -> 400000 | Z33: ='前提'!$B$22*'前提'!$C$34 -> 400000 | AA33: ='前提'!$B$22*'前提'!$C$34 -> 400000 | ... AK33: ='前提'!$B$22*'前提'!$C$34 -> 400000 | AL33: ='前提'!$B$22*'前提'!$C$35 -> 800000 | AM33: ='前提'!$B$22*'前提'!$C$35 -> 800000 | AN33: ='前提'!$B$22*'前提'!$C$35 -> 800000 | AO33: ='前提'!$B$22*'前提'!$C$35 -> 800000 | AP33: ='前提'!$B$22*'前提'!$C$35 -> 800000 | AQ33: ='前提'!$B$22*'前提'!$C$35 -> 800000 | AR33: ='前提'!$B$22*'前提'!$C$35 -> 800000 | AS33: ='前提'!$B$22*'前提'!$C$35 -> 800000 | ... BI33: ='前提'!$B$22*'前提'!$C$35 -> 800000
A34: 営業人件費（社員） | B34: 0 | C34: 0 | D34: 0 | E34: 0 | F34: 0 | G34: 0 | H34: ='前提'!$B$23*'前提'!$D$32 -> 400000 | I34: ='前提'!$B$23*'前提'!$D$32 -> 400000 | J34: ='前提'!$B$23*'前提'!$D$32 -> 400000 | K34: ='前提'!$B$23*'前提'!$D$32 -> 400000 | L34: ='前提'!$B$23*'前提'!$D$32 -> 400000 | M34: ='前提'!$B$23*'前提'!$D$32 -> 400000 | N34: ='前提'!$B$23*'前提'!$D$33 -> 400000 | O34: ='前提'!$B$23*'前提'!$D$33 -> 400000 | P34: ='前提'!$B$23*'前提'!$D$33 -> 400000 | Q34: ='前提'!$B$23*'前提'!$D$33 -> 400000 | R34: ='前提'!$B$23*'前提'!$D$33 -> 400000 | S34: ='前提'!$B$23*'前提'!$D$33 -> 400000 | T34: ='前提'!$B$23*'前提'!$D$34 -> 800000 | U34: ='前提'!$B$23*'前提'!$D$34 -> 800000 | V34: ='前提'!$B$23*'前提'!$D$34 -> 800000 | W34: ='前提'!$B$23*'前提'!$D$34 -> 800000 | X34: ='前提'!$B$23*'前提'!$D$34 -> 800000 | Y34: ='前提'!$B$23*'前提'!$D$34 -> 800000 | Z34: ='前提'!$B$23*'前提'!$D$34 -> 800000 | AA34: ='前提'!$B$23*'前提'!$D$34 -> 800000 | ... AK34: ='前提'!$B$23*'前提'!$D$34 -> 800000 | AL34: ='前提'!$B$23*'前提'!$D$35 -> 1600000 | AM34: ='前提'!$B$23*'前提'!$D$35 -> 1600000 | AN34: ='前提'!$B$23*'前提'!$D$35 -> 1600000 | AO34: ='前提'!$B$23*'前提'!$D$35 -> 1600000 | AP34: ='前提'!$B$23*'前提'!$D$35 -> 1600000 | AQ34: ='前提'!$B$23*'前提'!$D$35 -> 1600000 | AR34: ='前提'!$B$23*'前提'!$D$35 -> 1600000 | AS34: ='前提'!$B$23*'前提'!$D$35 -> 1600000 | ... BI34: ='前提'!$B$23*'前提'!$D$35 -> 1600000
A35: 営業外注費 | B35: =B9 -> 400000 | C35: =C9 -> 400000 | D35: =D9 -> 400000 | E35: =E9 -> 400000 | F35: =F9 -> 400000 | G35: =G9 -> 400000 | H35: =H9 -> 400000 | I35: =I9 -> 400000 | ... BI35: =BI9 -> 5200000
A36: LLM API変動費 | B36: =B15*'前提'!$B$24 -> 6000 | C36: =C15*'前提'!$B$24 -> 10000 | D36: =D15*'前提'!$B$24 -> 14000 | E36: =E15*'前提'!$B$24 -> 18000 | F36: =F15*'前提'!$B$24 -> 22000 | G36: =G15*'前提'!$B$24 -> 26000 | H36: =H15*'前提'!$B$24 -> 32000 | I36: =I15*'前提'!$B$24 -> 38000 | ... BI36: =BI15*'前提'!$B$24 -> 1134000
A37: 事務長（提案・設計） | B37: 0 | C37: 0 | D37: 0 | E37: 0 | F37: 0 | G37: 0 | H37: 0 | I37: 0 | J37: 0 | K37: 0 | L37: 0 | M37: 0 | N37: 300000 | O37: 300000 | P37: 300000 | Q37: 450000 | R37: 450000 | S37: 450000 | T37: 600000 | U37: 600000 | V37: 600000 | W37: 750000 | X37: 750000 | Y37: 750000 | Z37: 1800000 | AA37: 2100000 | AB37: 2400000 | AC37: 2700000 | AD37: 3000000 | AE37: 3300000 | AF37: 3600000 | AG37: 3900000 | AH37: 4200000 | AI37: 4500000 | AJ37: 4800000 | AK37: 5100000 | AL37: =ROUNDUP(AL16/'前提'!$B$82+AL17/'前提'!$B$83+AL18/'前提'!$B$84,0)*'前提'!$B$27 -> 3300000 | AM37: =ROUNDUP(AM16/'前提'!$B$82+AM17/'前提'!$B$83+AM18/'前提'!$B$84,0)*'前提'!$B$27 -> 3300000 | AN37: =ROUNDUP(AN16/'前提'!$B$82+AN17/'前提'!$B$83+AN18/'前提'!$B$84,0)*'前提'!$B$27 -> 3600000 | AO37: =ROUNDUP(AO16/'前提'!$B$82+AO17/'前提'!$B$83+AO18/'前提'!$B$84,0)*'前提'!$B$27 -> 3900000 | AP37: =ROUNDUP(AP16/'前提'!$B$82+AP17/'前提'!$B$83+AP18/'前提'!$B$84,0)*'前提'!$B$27 -> 3900000 | AQ37: =ROUNDUP(AQ16/'前提'!$B$82+AQ17/'前提'!$B$83+AQ18/'前提'!$B$84,0)*'前提'!$B$27 -> 4200000 | AR37: =ROUNDUP(AR16/'前提'!$B$82+AR17/'前提'!$B$83+AR18/'前提'!$B$84,0)*'前提'!$B$27 -> 4500000 | AS37: =ROUNDUP(AS16/'前提'!$B$82+AS17/'前提'!$B$83+AS18/'前提'!$B$84,0)*'前提'!$B$27 -> 4500000 | ... AW37: =ROUNDUP(AW16/'前提'!$B$82+AW17/'前提'!$B$83+AW18/'前提'!$B$84,0)*'前提'!$B$27 -> 5400000 | AX37: =ROUNDUP(AX16/'前提'!$C$82+AX17/'前提'!$C$83+AX18/'前提'!$C$84,0)*'前提'!$B$27 -> 3300000 | AY37: =ROUNDUP(AY16/'前提'!$C$82+AY17/'前提'!$C$83+AY18/'前提'!$C$84,0)*'前提'!$B$27 -> 3300000 | AZ37: =ROUNDUP(AZ16/'前提'!$C$82+AZ17/'前提'!$C$83+AZ18/'前提'!$C$84,0)*'前提'!$B$27 -> 3600000 | BA37: =ROUNDUP(BA16/'前提'!$C$82+BA17/'前提'!$C$83+BA18/'前提'!$C$84,0)*'前提'!$B$27 -> 3600000 | BB37: =ROUNDUP(BB16/'前提'!$C$82+BB17/'前提'!$C$83+BB18/'前提'!$C$84,0)*'前提'!$B$27 -> 3900000 | BC37: =ROUNDUP(BC16/'前提'!$C$82+BC17/'前提'!$C$83+BC18/'前提'!$C$84,0)*'前提'!$B$27 -> 3900000 | BD37: =ROUNDUP(BD16/'前提'!$C$82+BD17/'前提'!$C$83+BD18/'前提'!$C$84,0)*'前提'!$B$27 -> 3900000 | BE37: =ROUNDUP(BE16/'前提'!$C$82+BE17/'前提'!$C$83+BE18/'前提'!$C$84,0)*'前提'!$B$27 -> 4200000 | ... BI37: =ROUNDUP(BI16/'前提'!$C$82+BI17/'前提'!$C$83+BI18/'前提'!$C$84,0)*'前提'!$B$27 -> 4500000
A38: BPOオペレーター | B38: 0 | C38: 0 | D38: 0 | E38: 0 | F38: 0 | G38: 0 | H38: 0 | I38: 0 | J38: 0 | K38: 0 | L38: 0 | M38: 0 | N38: 0 | O38: 0 | P38: 0 | Q38: 0 | R38: 0 | S38: 0 | T38: 0 | U38: 0 | V38: 0 | W38: 0 | X38: 0 | Y38: 0 | Z38: 450000 | AA38: 600000 | AB38: 750000 | AC38: 900000 | AD38: 1050000 | AE38: 1200000 | AF38: 1350000 | AG38: 1500000 | AH38: 1650000 | AI38: 1800000 | AJ38: 1950000 | AK38: 2100000 | AL38: =IF(AL17+AL18>0,ROUNDUP(AL17/'前提'!$B$89+AL18/'前提'!$B$90,0)*'前提'!$B$28,0) -> 2100000 | AM38: =IF(AM17+AM18>0,ROUNDUP(AM17/'前提'!$B$89+AM18/'前提'!$B$90,0)*'前提'!$B$28,0) -> 2100000 | AN38: =IF(AN17+AN18>0,ROUNDUP(AN17/'前提'!$B$89+AN18/'前提'!$B$90,0)*'前提'!$B$28,0) -> 2250000 | AO38: =IF(AO17+AO18>0,ROUNDUP(AO17/'前提'!$B$89+AO18/'前提'!$B$90,0)*'前提'!$B$28,0) -> 2400000 | AP38: =IF(AP17+AP18>0,ROUNDUP(AP17/'前提'!$B$89+AP18/'前提'!$B$90,0)*'前提'!$B$28,0) -> 2400000 | AQ38: =IF(AQ17+AQ18>0,ROUNDUP(AQ17/'前提'!$B$89+AQ18/'前提'!$B$90,0)*'前提'!$B$28,0) -> 2550000 | AR38: =IF(AR17+AR18>0,ROUNDUP(AR17/'前提'!$B$89+AR18/'前提'!$B$90,0)*'前提'!$B$28,0) -> 2700000 | AS38: =IF(AS17+AS18>0,ROUNDUP(AS17/'前提'!$B$89+AS18/'前提'!$B$90,0)*'前提'!$B$28,0) -> 2850000 | ... AW38: =IF(AW17+AW18>0,ROUNDUP(AW17/'前提'!$B$89+AW18/'前提'!$B$90,0)*'前提'!$B$28,0) -> 3450000 | AX38: =IF(AX17+AX18>0,ROUNDUP(AX17/'前提'!$C$89+AX18/'前提'!$C$90,0)*'前提'!$B$28,0) -> 1950000 | AY38: =IF(AY17+AY18>0,ROUNDUP(AY17/'前提'!$C$89+AY18/'前提'!$C$90,0)*'前提'!$B$28,0) -> 2100000 | AZ38: =IF(AZ17+AZ18>0,ROUNDUP(AZ17/'前提'!$C$89+AZ18/'前提'!$C$90,0)*'前提'!$B$28,0) -> 2100000 | BA38: =IF(BA17+BA18>0,ROUNDUP(BA17/'前提'!$C$89+BA18/'前提'!$C$90,0)*'前提'!$B$28,0) -> 2250000 | BB38: =IF(BB17+BB18>0,ROUNDUP(BB17/'前提'!$C$89+BB18/'前提'!$C$90,0)*'前提'!$B$28,0) -> 2250000 | BC38: =IF(BC17+BC18>0,ROUNDUP(BC17/'前提'!$C$89+BC18/'前提'!$C$90,0)*'前提'!$B$28,0) -> 2400000 | BD38: =IF(BD17+BD18>0,ROUNDUP(BD17/'前提'!$C$89+BD18/'前提'!$C$90,0)*'前提'!$B$28,0) -> 2400000 | BE38: =IF(BE17+BE18>0,ROUNDUP(BE17/'前提'!$C$89+BE18/'前提'!$C$90,0)*'前提'!$B$28,0) -> 2550000 | ... BI38: =IF(BI17+BI18>0,ROUNDUP(BI17/'前提'!$C$89+BI18/'前提'!$C$90,0)*'前提'!$B$28,0) -> 2850000
A39: インフラ・ツール | B39: ='前提'!$B$25 -> 100000 | C39: ='前提'!$B$25 -> 100000 | D39: ='前提'!$B$25 -> 100000 | E39: ='前提'!$B$25 -> 100000 | F39: ='前提'!$B$25 -> 100000 | G39: ='前提'!$B$25 -> 100000 | H39: ='前提'!$B$25 -> 100000 | I39: ='前提'!$B$25 -> 100000 | ... BI39: ='前提'!$B$25 -> 100000
A40: その他固定費 | B40: ='前提'!$B$26 -> 50000 | C40: ='前提'!$B$26 -> 50000 | D40: ='前提'!$B$26 -> 50000 | E40: ='前提'!$B$26 -> 50000 | F40: ='前提'!$B$26 -> 50000 | G40: ='前提'!$B$26 -> 50000 | H40: ='前提'!$B$26 -> 50000 | I40: ='前提'!$B$26 -> 50000 | ... BI40: ='前提'!$B$26 -> 50000
A42: コスト合計 | B42: =B30+B31+B32+B33+B34+B35+B36+B37+B38+B39+B40 -> 1256000 | C42: =C30+C31+C32+C33+C34+C35+C36+C37+C38+C39+C40 -> 1260000 | D42: =D30+D31+D32+D33+D34+D35+D36+D37+D38+D39+D40 -> 1264000 | E42: =E30+E31+E32+E33+E34+E35+E36+E37+E38+E39+E40 -> 1268000 | F42: =F30+F31+F32+F33+F34+F35+F36+F37+F38+F39+F40 -> 1272000 | G42: =G30+G31+G32+G33+G34+G35+G36+G37+G38+G39+G40 -> 1276000 | H42: =H30+H31+H32+H33+H34+H35+H36+H37+H38+H39+H40 -> 2232000 | I42: =I30+I31+I32+I33+I34+I35+I36+I37+I38+I39+I40 -> 2238000 | ... BI42: =BI30+BI31+BI32+BI33+BI34+BI35+BI36+BI37+BI38+BI39+BI40 -> 17784000
A44: 【CS工数試算】
A45: オンボーディング工数 | B45: =B12*'前提'!$B$52 -> 60 | C45: =C12*'前提'!$B$52 -> 60 | D45: =D12*'前提'!$B$52 -> 60 | E45: =E12*'前提'!$B$52 -> 60 | F45: =F12*'前提'!$B$52 -> 60 | G45: =G12*'前提'!$B$52 -> 60 | H45: =H12*'前提'!$B$52 -> 90 | I45: =I12*'前提'!$B$52 -> 90 | ... BI45: =BI12*'前提'!$B$52 -> 750
...

Sheet 年次事業計画
A1: SuguDesk 年次事業計画
B3: 1年目 | C3: 2年目 | D3: 3年目 | E3: 4年目 | F3: 5年目
A4: 【顧客数】
A5: 期末顧客数 | B5: ='月次事業計画'!M15 -> 31 | C5: ='月次事業計画'!Y15 -> 147 | D5: ='月次事業計画'!AK15 -> 260 | E5: ='月次事業計画'!AW15 -> 441 | F5: ='月次事業計画'!BI15 -> 567
A6: ENTRY | B6: ='月次事業計画'!M16 -> 18 | C6: ='月次事業計画'!Y16 -> 73 | D6: ='月次事業計画'!AK16 -> 87 | E6: ='月次事業計画'!AW16 -> 138 | F6: ='月次事業計画'!BI16 -> 140
A7: EXPAND | B7: ='月次事業計画'!M17 -> 13 | C7: ='月次事業計画'!Y17 -> 67 | D7: ='月次事業計画'!AK17 -> 127 | E7: ='月次事業計画'!AW17 -> 198 | F7: ='月次事業計画'!BI17 -> 245
A8: DEEPEN | B8: ='月次事業計画'!M18 -> 0 | C8: ='月次事業計画'!Y18 -> 14 | D8: ='月次事業計画'!AK18 -> 60 | E8: ='月次事業計画'!AW18 -> 123 | F8: ='月次事業計画'!BI18 -> 200
A10: 【売上】
A11: MRR（期末） | B11: ='月次事業計画'!M27 -> 1425000 | C11: ='月次事業計画'!Y27 -> 10350000 | D11: ='月次事業計画'!AK27 -> 26700000 | E11: ='月次事業計画'!AW27 -> 49050000 | F11: ='月次事業計画'!BI27 -> 71875000
A12: ARR（期末） | B12: ='月次事業計画'!M27*12 -> 17100000 | C12: ='月次事業計画'!Y27*12 -> 124200000 | D12: ='月次事業計画'!AK27*12 -> 320400000 | E12: ='月次事業計画'!AW27*12 -> 588600000 | F12: ='月次事業計画'!BI27*12 -> 862500000
A13: 年間売上合計 | B13: =SUM('月次事業計画'!B26:M26) -> 19475000 | C13: =SUM('月次事業計画'!N26:Y26) -> 117675000 | D13: =SUM('月次事業計画'!Z26:AK26) -> 300400000 | E13: =SUM('月次事業計画'!AL26:AW26) -> 582275000 | F13: =SUM('月次事業計画'!AX26:BI26) -> 859175000
A14: 月額売上 | B14: =SUM('月次事業計画'!B24:M24) -> 7475000 | C14: =SUM('月次事業計画'!N24:Y24) -> 62475000 | D14: =SUM('月次事業計画'!Z24:AK24) -> 228400000 | E14: =SUM('月次事業計画'!AL24:AW24) -> 462275000 | F14: =SUM('月次事業計画'!AX24:BI24) -> 739175000
A15: 導入費用 | B15: =SUM('月次事業計画'!B25:M25) -> 12000000 | C15: =SUM('月次事業計画'!N25:Y25) -> 55200000 | D15: =SUM('月次事業計画'!Z25:AK25) -> 72000000 | E15: =SUM('月次事業計画'!AL25:AW25) -> 120000000 | F15: =SUM('月次事業計画'!AX25:BI25) -> 120000000
A17: 【コスト】
A18: 年間コスト合計 | B18: =SUM('月次事業計画'!B42:M42) -> 21078000 | C18: =SUM('月次事業計画'!N42:Y42) -> 54584000 | D18: =SUM('月次事業計画'!Z42:AK42) -> 122980000 | E18: =SUM('月次事業計画'!AL42:AW42) -> 203878000 | F18: =SUM('月次事業計画'!AX42:BI42) -> 199512000
A19: 代表報酬 | B19: =SUM('月次事業計画'!B30:M30) -> 4200000 | C19: =SUM('月次事業計画'!N30:Y30) -> 4200000 | D19: =SUM('月次事業計画'!Z30:AK30) -> 4200000 | E19: =SUM('月次事業計画'!AL30:AW30) -> 4200000 | F19: =SUM('月次事業計画'!AX30:BI30) -> 4200000
A20: エンジニア（正社員） | B20: =SUM('月次事業計画'!B31:M31) -> 6300000 | C20: =SUM('月次事業計画'!N31:Y31) -> 8400000 | D20: =SUM('月次事業計画'!Z31:AK31) -> 8400000 | E20: =SUM('月次事業計画'!AL31:AW31) -> 8400000 | F20: =SUM('月次事業計画'!AX31:BI31) -> 8400000
A21: 開発外注 | B21: =SUM('月次事業計画'!B32:M32) -> 0 | C21: =SUM('月次事業計画'!N32:Y32) -> 1800000 | D21: =SUM('月次事業計画'!Z32:AK32) -> 3600000 | E21: =SUM('月次事業計画'!AL32:AW32) -> 6000000 | F21: =SUM('月次事業計画'!AX32:BI32) -> 6000000
A22: CS人件費 | B22: =SUM('月次事業計画'!B33:M33) -> 1200000 | C22: =SUM('月次事業計画'!N33:Y33) -> 3600000 | D22: =SUM('月次事業計画'!Z33:AK33) -> 4800000 | E22: =SUM('月次事業計画'!AL33:AW33) -> 9600000 | F22: =SUM('月次事業計画'!AX33:BI33) -> 9600000
A23: 営業人件費（社員） | B23: =SUM('月次事業計画'!B34:M34) -> 2400000 | C23: =SUM('月次事業計画'!N34:Y34) -> 7200000 | D23: =SUM('月次事業計画'!Z34:AK34) -> 9600000 | E23: =SUM('月次事業計画'!AL34:AW34) -> 19200000 | F23: =SUM('月次事業計画'!AX34:BI34) -> 19200000
A24: 営業外注費 | B24: =SUM('月次事業計画'!B35:M35) -> 4800000 | C24: =SUM('月次事業計画'!N35:Y35) -> 19200000 | D24: =SUM('月次事業計画'!Z35:AK35) -> 28800000 | E24: =SUM('月次事業計画'!AL35:AW35) -> 62400000 | F24: =SUM('月次事業計画'!AX35:BI35) -> 62400000
A25: LLM API変動費 | B25: =SUM('月次事業計画'!B36:M36) -> 378000 | C25: =SUM('月次事業計画'!N36:Y36) -> 2084000 | D25: =SUM('月次事業計画'!Z36:AK36) -> 5080000 | E25: =SUM('月次事業計画'!AL36:AW36) -> 8728000 | F25: =SUM('月次事業計画'!AX36:BI36) -> 12312000
A26: 事務長（提案・設計） | B26: =SUM('月次事業計画'!B37:M37) -> 0 | C26: =SUM('月次事業計画'!N37:Y37) -> 6300000 | D26: =SUM('月次事業計画'!Z37:AK37) -> 41400000 | E26: =SUM('月次事業計画'!AL37:AW37) -> 51300000 | F26: =SUM('月次事業計画'!AX37:BI37) -> 46800000
A27: BPOオペレーター | B27: =SUM('月次事業計画'!B38:M38) -> 0 | C27: =SUM('月次事業計画'!N38:Y38) -> 0 | D27: =SUM('月次事業計画'!Z38:AK38) -> 15300000 | E27: =SUM('月次事業計画'!AL38:AW38) -> 32250000 | F27: =SUM('月次事業計画'!AX38:BI38) -> 28800000
A28: インフラ・ツール | B28: =SUM('月次事業計画'!B39:M39) -> 1200000 | C28: =SUM('月次事業計画'!N39:Y39) -> 1200000 | D28: =SUM('月次事業計画'!Z39:AK39) -> 1200000 | E28: =SUM('月次事業計画'!AL39:AW39) -> 1200000 | F28: =SUM('月次事業計画'!AX39:BI39) -> 1200000
A29: その他固定費 | B29: =SUM('月次事業計画'!B40:M40) -> 600000 | C29: =SUM('月次事業計画'!N40:Y40) -> 600000 | D29: =SUM('月次事業計画'!Z40:AK40) -> 600000 | E29: =SUM('月次事業計画'!AL40:AW40) -> 600000 | F29: =SUM('月次事業計画'!AX40:BI40) -> 600000
A31: 【損益】
A32: 年間営業利益 | B32: =SUM('月次事業計画'!B55:M55) -> -1603000 | C32: =SUM('月次事業計画'!N55:Y55) -> 63091000 | D32: =SUM('月次事業計画'!Z55:AK55) -> 177420000 | E32: =SUM('月次事業計画'!AL55:AW55) -> 378397000 | F32: =SUM('月次事業計画'!AX55:BI55) -> 659663000
A33: 営業利益率 | B33: =IF(B13<>0,B32/B13,0) -> -0.082310655 | C33: =IF(C13<>0,C32/C13,0) -> 0.53614617 | D33: =IF(D13<>0,D32/D13,0) -> 0.59061252 | E33: =IF(E13<>0,E32/E13,0) -> 0.6498596 | F33: =IF(F13<>0,F32/F13,0) -> 0.76778654
A34: 累積損益 | B34: ='月次事業計画'!M58 -> -1603000 | C34: ='月次事業計画'!Y58 -> 61488000 | D34: ='月次事業計画'!AK58 -> 238908000 | E34: ='月次事業計画'!AW58 -> 617305000 | F34: ='月次事業計画'!BI58 -> 1276968000
A36: 【バーンレート】
A37: シリーズA入金 | B37: =SUM('月次事業計画'!B65:M65) -> 0 | C37: =SUM('月次事業計画'!N65:Y65) -> 50000000 | D37: =SUM('月次事業計画'!Z65:AK65) -> 0 | E37: =SUM('月次事業計画'!AL65:AW65) -> 0 | F37: =SUM('月次事業計画'!AX65:BI65) -> 0
A38: 公庫返済合計 | B38: =SUM('月次事業計画'!B66:M66) -> 0 | C38: =SUM('月次事業計画'!N66:Y66) -> 0 | D38: =SUM('月次事業計画'!Z66:AK66) -> 0 | E38: =SUM('月次事業計画'!AL66:AW66) -> 0 | F38: =SUM('月次事業計画'!AX66:BI66) -> 0
A39: 年間ネットバーン | B39: =SUM('月次事業計画'!B61:M61) -> 1603000 | C39: =SUM('月次事業計画'!N61:Y61) -> -63091000 | D39: =SUM('月次事業計画'!Z61:AK61) -> -177420000 | E39: =SUM('月次事業計画'!AL61:AW61) -> -378397000 | F39: =SUM('月次事業計画'!AX61:BI61) -> -659663000
A40: 月平均ネットバーン | B40: =AVERAGE('月次事業計画'!B61:M61) -> 133583.33 | C40: =AVERAGE('月次事業計画'!N61:Y61) -> -5257583.3 | D40: =AVERAGE('月次事業計画'!Z61:AK61) -> -14785000 | E40: =AVERAGE('月次事業計画'!AL61:AW61) -> -31533083 | F40: =AVERAGE('月次事業計画'!AX61:BI61) -> -54971917
A41: 期末キャッシュ残高 | B41: ='月次事業計画'!M67 -> #REF! | C41: ='月次事業計画'!Y67 -> #REF! | D41: ='月次事業計画'!AK67 -> #REF! | E41: ='月次事業計画'!AW67 -> #REF! | F41: ='月次事業計画'!BI67 -> #REF!
A42: 期末ランウェイ（月） | B42: ='月次事業計画'!M68 -> #REF! | C42: ='月次事業計画'!Y68 -> #REF! | D42: ='月次事業計画'!AK68 -> #REF! | E42: ='月次事業計画'!AW68 -> #REF! | F42: ='月次事業計画'!BI68 -> #REF!
A44: 【期末人員数】
A45: 期末合計人数 | B45: ='月次事業計画'!M80 -> 5 | C45: ='月次事業計画'!Y80 -> 17.428571 | D45: ='月次事業計画'!AK80 -> 43.428571 | E45: ='月次事業計画'!AW80 -> 64.714286 | F45: ='月次事業計画'!BI80 -> 57.714286
A46: 代表 | B46: ='月次事業計画'!M71 -> 1 | C46: ='月次事業計画'!Y71 -> 1 | D46: ='月次事業計画'!AK71 -> 1 | E46: ='月次事業計画'!AW71 -> 1 | F46: ='月次事業計画'!BI71 -> 1
...

Sheet 資本政策表
A1: SuguDesk 資本政策表
B3: 設立 | C3: J-KISS | D3: Seed（シード） | E3: Series A
A4: プレバリュー | B4: - | C4: - | D4: ='前提'!$B$65 -> 170000000 | E4: ='前提'!$B$69 -> 500000000
A5: 調達額 | B5: ='前提'!$B$61 -> 1000000 | C5: ='前提'!$B$63+'前提'!$B$64 -> 2500000 | D5: ='前提'!$B$66 -> 30000000 | E5: ='前提'!$B$70 -> 50000000
A6: ポストバリュー | B6: - | C6: - | D6: =D4+D5 -> 200000000 | E6: =E4+E5 -> 550000000
A7: 公庫借入（デット） | D7: ='前提'!$B$68
A9: 【株式数】
A10: J-KISS転換株価 | C10: ='前提'!$B$62/'前提'!$B$60 -> 100
A11: J-KISS転換株数 | C11: =ROUNDDOWN(C5/C10,0) -> 25000
A12: J-KISS転換後 発行済株数 | C12: ='前提'!$B$60+C11 -> 1025000
A13: Seed株価 | D13: =D4/C12 -> 165.85366
A14: Seed新規発行株数 | D14: =ROUNDDOWN(D5/D13,0) -> 180882
A15: Seed後 発行済株数 | D15: =C12+D14 -> 1205882
A16: Series A 株価 | E16: =E4/D15 -> 414.63427
A17: Series A 新規発行株数 | E17: =ROUNDDOWN(E5/E16,0) -> 120588
A18: SOPプール株数 | E18: =ROUNDDOWN((D15+E17)*'前提'!$B$71/(1-'前提'!$B$71),0) -> 95255
A19: Series A後 発行済株数 | E19: =D15+E17+E18 -> 1421725
A21: 【持分比率】
A22: Anna（代表） | B22: 100.0% | C22: ='前提'!$B$60/C12 -> 0.97560976 | D22: ='前提'!$B$60/D15 -> 0.82926854 | E22: ='前提'!$B$60/E19 -> 0.70337091
A23: J-KISS投資家 | B23: - | C23: =C11/C12 -> 0.024390244 | D23: =C11/D15 -> 0.020731713 | E23: =C11/E19 -> 0.017584273
A24: 佐藤さん | C24: =ROUNDDOWN('前提'!$B$63/C10,0)/C12 -> 0.019512195 | D24: =ROUNDDOWN('前提'!$B$63/C10,0)/D15 -> 0.016585371 | E24: =ROUNDDOWN('前提'!$B$63/C10,0)/E19 -> 0.014067418
A25: ようすけさん | C25: =ROUNDDOWN('前提'!$B$64/C10,0)/C12 -> 0.0048780488 | D25: =ROUNDDOWN('前提'!$B$64/C10,0)/D15 -> 0.0041463427 | E25: =ROUNDDOWN('前提'!$B$64/C10,0)/E19 -> 0.0035168545
A26: シード | B26: - | C26: - | D26: =D14/D15 -> 0.14999975 | E26: =D14/E19 -> 0.12722714
A27: SOPプール | B27: - | C27: - | D27: - | E27: =E18/E19 -> 0.066999596
A28: Series A 投資家 | B28: - | C28: - | D28: - | E28: =E17/E19 -> 0.084818091
A30: 合計チェック | E30: =E22+E23+E26+E27+E28 -> 1
A32: 【感度分析】Series Aプレバリュー別 Founder持分
B33: 保守的 ¥3億 | C33: 現実的 ¥5億 | D33: 中間 ¥7億 | E33: 現計画 ¥10億 | F33: 強気 ¥15億
A34: Series A プレバリュー | B34: 300000000 | C34: 500000000 | D34: 700000000 | E34: 1000000000 | F34: 1500000000
A35: 調達額（固定） | B35: ='前提'!$B$70 -> 50000000 | C35: ='前提'!$B$70 -> 50000000 | D35: ='前提'!$B$70 -> 50000000 | E35: ='前提'!$B$70 -> 50000000 | F35: ='前提'!$B$70 -> 50000000
A36: Series A 株価 | B36: =B34/$D$15 -> 248.78056 | C36: =C34/$D$15 -> 414.63427 | D36: =D34/$D$15 -> 580.48797 | E36: =E34/$D$15 -> 829.26854 | F36: =F34/$D$15 -> 1243.9028
A37: 新規発行株数 | B37: =ROUNDDOWN(B35/B36,0) -> 200980 | C37: =ROUNDDOWN(C35/C36,0) -> 120588 | D37: =ROUNDDOWN(D35/D36,0) -> 86134 | E37: =ROUNDDOWN(E35/E36,0) -> 60294 | F37: =ROUNDDOWN(F35/F36,0) -> 40196
A38: SOPプール株数 | B38: =ROUNDDOWN(($D$15+B37)*'前提'!$B$71/(1-'前提'!$B$71),0) -> 101028 | C38: =ROUNDDOWN(($D$15+C37)*'前提'!$B$71/(1-'前提'!$B$71),0) -> 95255 | D38: =ROUNDDOWN(($D$15+D37)*'前提'!$B$71/(1-'前提'!$B$71),0) -> 92781 | E38: =ROUNDDOWN(($D$15+E37)*'前提'!$B$71/(1-'前提'!$B$71),0) -> 90925 | F38: =ROUNDDOWN(($D$15+F37)*'前提'!$B$71/(1-'前提'!$B$71),0) -> 89482
A39: 発行済株数合計 | B39: =$D$15+B37+B38 -> 1507890 | C39: =$D$15+C37+C38 -> 1421725 | D39: =$D$15+D37+D38 -> 1384797 | E39: =$D$15+E37+E38 -> 1357101 | F39: =$D$15+F37+F38 -> 1335560
A41: Anna持分 | B41: ='前提'!$B$60/B39 -> 0.66317835 | C41: ='前提'!$B$60/C39 -> 0.70337091 | D41: ='前提'!$B$60/D39 -> 0.7221275 | E41: ='前提'!$B$60/E39 -> 0.73686483 | F41: ='前提'!$B$60/F39 -> 0.74874959
A42: J-KISS投資家 | B42: =$C$11/B39 -> 0.016579459 | C42: =$C$11/C39 -> 0.017584273 | D42: =$C$11/D39 -> 0.018053188 | E42: =$C$11/E39 -> 0.018421621 | F42: =$C$11/F39 -> 0.01871874
A43: シード | B43: =$D$14/B39 -> 0.11995703 | C43: =$D$14/C39 -> 0.12722714 | D43: =$D$14/D39 -> 0.13061987 | E43: =$D$14/E39 -> 0.13328558 | F43: =$D$14/F39 -> 0.13543532
A44: SOPプール | B44: =B38/B39 -> 0.066999582 | C44: =C38/C39 -> 0.066999596 | D44: =D38/D39 -> 0.066999712 | E44: =E38/E39 -> 0.066999435 | F44: =F38/F39 -> 0.066999611
A45: Series A 投資家 | B45: =B37/B39 -> 0.13328558 | C45: =C37/C39 -> 0.084818091 | D45: =D37/D39 -> 0.06219973 | E45: =E37/E39 -> 0.044428528 | F45: =F37/F39 -> 0.030096738
A47: Founder 50%超? | B47: =IF(B41>=0.5,"OK","NG") -> OK | C47: =IF(C41>=0.5,"OK","NG") -> OK | D47: =IF(D41>=0.5,"OK","NG") -> OK | E47: =IF(E41>=0.5,"OK","NG") -> OK | F47: =IF(F41>=0.5,"OK","NG") -> OK
...

Sheet 資金使途
A1: シードラウンド 資金使途
A2: 調達額合計 | B2: ='前提'!B63+'前提'!B64+#REF!+'前提'!B66+'前提'!B68 -> #REF! | C2: （J-KISS+エクイティ+デット）
A4: 【やりたいこと → 資金使途】
A5: 項目 | B5: 月額 | C5: 年額（想定） | D5: 備考
A6: エンジニア正社員（AI駆動開発） | B6: ='前提'!B21 -> 700000 | C6: =B6*12 -> 8400000 | D6: Dify APIアップセル・基盤開発・BPO検証・チャットUI改善
A7: CS（業務委託） | B7: ='前提'!B22 -> 200000 | C7: =B7*12 -> 2400000 | D7: FAQ構築・クライアント対応
A8: Anna代表報酬 | B8: ='前提'!B20 -> 350000 | C8: =B8*12 -> 4200000 | D8: 営業・経営・資金調達に集中
A9: 営業（M7以降） | B9: ='前提'!B23 -> 400000 | C9: =B9*6 -> 2400000 | D9: M7から採用（年の半分）
A10: 営業外注費（平均） | B10: =AVERAGE('月次事業計画'!B9:'月次事業計画'!M9) -> 400000 | C10: =B10*12 -> 4800000 | D10: ファネル逆算に基づく外注費
A11: インフラ・ツール | B11: ='前提'!B25 -> 100000 | C11: =B11*12 -> 1200000 | D11: Dify API, AWS, Claude, SaaS等
A12: その他固定費 | B12: ='前提'!B26 -> 50000 | C12: =B12*12 -> 600000 | D12: 法務・会計・雑費
A13: デザイン（スポット） | B13: - | C13: 400000 | D13: チャットUI/UXデザイン改善
A14: 年間合計 | B14: =SUM(B6:B13) -> 2200000 | C14: =SUM(C6:C13) -> 24400000
A16: 【ランウェイ試算】
A17: Phase1 前半バーンレート（月） | B17: =AVERAGE('月次事業計画'!B42:'月次事業計画'!G42) -> 1266000 | C17: M1-M6平均コスト
A18: Phase1 後半バーンレート（月） | B18: =AVERAGE('月次事業計画'!H42:'月次事業計画'!M42) -> 2247000 | C18: M7-M12平均コスト
A19: Phase1 月間コスト平均 | B19: =AVERAGE('月次事業計画'!B63:'月次事業計画'!M63) -> 1756500 | C19: M1-M12平均コスト（売上無視）
A21: 初期キャッシュ | B21: ='前提'!$B$63+'前提'!$B$64+#REF!+'前提'!$B$66+'前提'!$B$68 -> #REF!
A22: ランウェイ（コスト基準） | B22: =IF(B19>0,B21/B19,"") -> #REF! | C22: 月（売上ゼロでも持つ期間）
A23: M12末キャッシュ残高 | B23: ='月次事業計画'!M67 -> #REF!
A24: M24末キャッシュ残高 | B24: ='月次事業計画'!Y67 -> #REF!
