Workbook

Sheet 前提
A1: SuguDesk 事業計画v5 前提条件
A3: 【価格前提】
A4: SuguDesk ARPA（月額） | B4: 11500 | D4: ライト/スタンダード平均
A5: SuguDesk 導入費（初期） | B5: 225000 | D5: 1院あたり平均
A6: BPO事務長代行 ARPA（月額） | B6: 150000 | D6: 算定業務＋事務長代行
A7: BPO採用/集患 ARPA（月額） | B7: 50000 | D7: BPO#2、M13以降
A8: SuguDeskチャーン率（月次） | B8: 0.02
A9: BPOチャーン率（月次） | B9: 0.01 | D9: 粘着性高い
A11: 【売上計上前提】
A12: 新規契約 月内係数 | B12: 0.5 | D12: 期中入金想定で半月分計上
A13: 導入費 計上係数 | B13: 1 | D13: 契約月に全額
A15: 【SuguDesk直接原価（変動費）】
A16: FAQ構築原価/新規件 | B16: 36000 | D16: 30h×¥1,200（pricing.md）
A17: 月額メンテ原価/件 | B17: 4800 | D17: 4h×¥1,200
A18: LLM API/件・月 | B18: 12 | D18: Gemini Flash実績
A20: 【インフラ（顧客数連動）】
A21: Cloud SQL 〜50院 | B21: 8000
A22: Cloud SQL 50-200院 | B22: 15000
A23: Cloud SQL 200院超 | B23: 25000
A24: Cloud Run 〜50院 | B24: 2000
A25: Cloud Run 50-200院 | B25: 5000
A26: Cloud Run 200院超 | B26: 15000
A28: 【人員担当比率（レバー）】
A29: BPO事務長 担当社数/人 | B29: 10 | D29: ★変数：下げると人件費増、上げると減
A30: BPOオペ 担当社数/人 | B30: 15 | D30: ★変数
A31: CS 担当社数/人 | B31: 20 | D31: ★変数
A33: 【人件費単価（月額）】
A34: CEO報酬 | B34: 300000
A35: エンジニア時給（業務委託） | B35: 5000
A36: エンジニア月間稼働h(P1) | B36: 64.5
A37: エンジニア月間稼働h(P2) | B37: 40
A38: エンジニア正社員 単価/人 | B38: 700000
A39: BPO事務長 単価/人 | B39: 400000
A40: BPOオペ 単価/人 | B40: 200000
A41: 営業サポート 単価/人 | B41: 200000
A42: CS 単価/人 | B42: 350000
A43: 社会保険料率（正社員のみ） | B43: 0.15 | D43: CEO・エンジニア正社員に適用
A44: 福利厚生/人・月（全員） | B44: 5000
A46: 【固定費・販管費（月額）】
A47: オフィス家賃（Phase1-3） | B47: 50000 | D47: コワーキング想定
...

Sheet 月次事業計画
A1: 月次事業計画（5年=60ヶ月）
A2: フェーズ | B2: P1 | C2: P1 | D2: P1 | E2: P1 | F2: P1 | G2: P1 | H2: P2 | I2: P2 | J2: P2 | K2: P2 | L2: P2 | M2: P2 | N2: P3 | O2: P3 | P2: P3 | Q2: P3 | R2: P3 | S2: P3 | T2: P4 | U2: P4 | V2: P4 | W2: P4 | X2: P4 | Y2: P4 | Z2: P5 | AA2: P5 | AB2: P5 | AC2: P5 | AD2: P5 | AE2: P5 | AF2: P5 | AG2: P5 | AH2: P5 | AI2: P5 | AJ2: P5 | AK2: P5 | AL2: P6 | AM2: P6 | AN2: P6 | AO2: P6 | AP2: P6 | AQ2: P6 | AR2: P6 | AS2: P6 | AT2: P6 | AU2: P6 | AV2: P6 | AW2: P6 | AX2: P7 | AY2: P7 | AZ2: P7 | BA2: P7 | BB2: P7 | BC2: P7 | BD2: P7 | BE2: P7 | BF2: P7 | BG2: P7 | BH2: P7 | BI2: P7
A3: 月 | B3: M1 | C3: M2 | D3: M3 | E3: M4 | F3: M5 | G3: M6 | H3: M7 | I3: M8 | J3: M9 | K3: M10 | L3: M11 | M3: M12 | N3: M13 | O3: M14 | P3: M15 | Q3: M16 | R3: M17 | S3: M18 | T3: M19 | U3: M20 | V3: M21 | W3: M22 | X3: M23 | Y3: M24 | Z3: M25 | AA3: M26 | AB3: M27 | AC3: M28 | AD3: M29 | AE3: M30 | AF3: M31 | AG3: M32 | AH3: M33 | AI3: M34 | AJ3: M35 | AK3: M36 | AL3: M37 | AM3: M38 | AN3: M39 | AO3: M40 | AP3: M41 | AQ3: M42 | AR3: M43 | AS3: M44 | AT3: M45 | AU3: M46 | AV3: M47 | AW3: M48 | AX3: M49 | AY3: M50 | AZ3: M51 | BA3: M52 | BB3: M53 | BC3: M54 | BD3: M55 | BE3: M56 | BF3: M57 | BG3: M58 | BH3: M59 | BI3: M60
A4: 【営業活動】
A5: 月間新規SuguDesk契約数 | B5: =IF(1<=6,'前提'!$B$58,IF(1<=12,'前提'!$B$59,IF(1<=18,'前提'!$B$60,IF(1<=24,'前提'!$B$61,IF(1<=36,'前提'!$B$62,IF(1<=48,'前提'!$B$63,'前提'!$B$64)))))) | C5: =IF(2<=6,'前提'!$B$58,IF(2<=12,'前提'!$B$59,IF(2<=18,'前提'!$B$60,IF(2<=24,'前提'!$B$61,IF(2<=36,'前提'!$B$62,IF(2<=48,'前提'!$B$63,'前提'!$B$64)))))) | D5: =IF(3<=6,'前提'!$B$58,IF(3<=12,'前提'!$B$59,IF(3<=18,'前提'!$B$60,IF(3<=24,'前提'!$B$61,IF(3<=36,'前提'!$B$62,IF(3<=48,'前提'!$B$63,'前提'!$B$64)))))) | E5: =IF(4<=6,'前提'!$B$58,IF(4<=12,'前提'!$B$59,IF(4<=18,'前提'!$B$60,IF(4<=24,'前提'!$B$61,IF(4<=36,'前提'!$B$62,IF(4<=48,'前提'!$B$63,'前提'!$B$64)))))) | F5: =IF(5<=6,'前提'!$B$58,IF(5<=12,'前提'!$B$59,IF(5<=18,'前提'!$B$60,IF(5<=24,'前提'!$B$61,IF(5<=36,'前提'!$B$62,IF(5<=48,'前提'!$B$63,'前提'!$B$64)))))) | G5: =IF(6<=6,'前提'!$B$58,IF(6<=12,'前提'!$B$59,IF(6<=18,'前提'!$B$60,IF(6<=24,'前提'!$B$61,IF(6<=36,'前提'!$B$62,IF(6<=48,'前提'!$B$63,'前提'!$B$64)))))) | H5: =IF(7<=6,'前提'!$B$58,IF(7<=12,'前提'!$B$59,IF(7<=18,'前提'!$B$60,IF(7<=24,'前提'!$B$61,IF(7<=36,'前提'!$B$62,IF(7<=48,'前提'!$B$63,'前提'!$B$64)))))) | I5: =IF(8<=6,'前提'!$B$58,IF(8<=12,'前提'!$B$59,IF(8<=18,'前提'!$B$60,IF(8<=24,'前提'!$B$61,IF(8<=36,'前提'!$B$62,IF(8<=48,'前提'!$B$63,'前提'!$B$64)))))) | J5: =IF(9<=6,'前提'!$B$58,IF(9<=12,'前提'!$B$59,IF(9<=18,'前提'!$B$60,IF(9<=24,'前提'!$B$61,IF(9<=36,'前提'!$B$62,IF(9<=48,'前提'!$B$63,'前提'!$B$64)))))) | K5: =IF(10<=6,'前提'!$B$58,IF(10<=12,'前提'!$B$59,IF(10<=18,'前提'!$B$60,IF(10<=24,'前提'!$B$61,IF(10<=36,'前提'!$B$62,IF(10<=48,'前提'!$B$63,'前提'!$B$64)))))) | L5: =IF(11<=6,'前提'!$B$58,IF(11<=12,'前提'!$B$59,IF(11<=18,'前提'!$B$60,IF(11<=24,'前提'!$B$61,IF(11<=36,'前提'!$B$62,IF(11<=48,'前提'!$B$63,'前提'!$B$64)))))) | M5: =IF(12<=6,'前提'!$B$58,IF(12<=12,'前提'!$B$59,IF(12<=18,'前提'!$B$60,IF(12<=24,'前提'!$B$61,IF(12<=36,'前提'!$B$62,IF(12<=48,'前提'!$B$63,'前提'!$B$64)))))) | N5: =IF(13<=6,'前提'!$B$58,IF(13<=12,'前提'!$B$59,IF(13<=18,'前提'!$B$60,IF(13<=24,'前提'!$B$61,IF(13<=36,'前提'!$B$62,IF(13<=48,'前提'!$B$63,'前提'!$B$64)))))) | O5: =IF(14<=6,'前提'!$B$58,IF(14<=12,'前提'!$B$59,IF(14<=18,'前提'!$B$60,IF(14<=24,'前提'!$B$61,IF(14<=36,'前提'!$B$62,IF(14<=48,'前提'!$B$63,'前提'!$B$64)))))) | P5: =IF(15<=6,'前提'!$B$58,IF(15<=12,'前提'!$B$59,IF(15<=18,'前提'!$B$60,IF(15<=24,'前提'!$B$61,IF(15<=36,'前提'!$B$62,IF(15<=48,'前提'!$B$63,'前提'!$B$64)))))) | Q5: =IF(16<=6,'前提'!$B$58,IF(16<=12,'前提'!$B$59,IF(16<=18,'前提'!$B$60,IF(16<=24,'前提'!$B$61,IF(16<=36,'前提'!$B$62,IF(16<=48,'前提'!$B$63,'前提'!$B$64)))))) | R5: =IF(17<=6,'前提'!$B$58,IF(17<=12,'前提'!$B$59,IF(17<=18,'前提'!$B$60,IF(17<=24,'前提'!$B$61,IF(17<=36,'前提'!$B$62,IF(17<=48,'前提'!$B$63,'前提'!$B$64)))))) | S5: =IF(18<=6,'前提'!$B$58,IF(18<=12,'前提'!$B$59,IF(18<=18,'前提'!$B$60,IF(18<=24,'前提'!$B$61,IF(18<=36,'前提'!$B$62,IF(18<=48,'前提'!$B$63,'前提'!$B$64)))))) | T5: =IF(19<=6,'前提'!$B$58,IF(19<=12,'前提'!$B$59,IF(19<=18,'前提'!$B$60,IF(19<=24,'前提'!$B$61,IF(19<=36,'前提'!$B$62,IF(19<=48,'前提'!$B$63,'前提'!$B$64)))))) | U5: =IF(20<=6,'前提'!$B$58,IF(20<=12,'前提'!$B$59,IF(20<=18,'前提'!$B$60,IF(20<=24,'前提'!$B$61,IF(20<=36,'前提'!$B$62,IF(20<=48,'前提'!$B$63,'前提'!$B$64)))))) | V5: =IF(21<=6,'前提'!$B$58,IF(21<=12,'前提'!$B$59,IF(21<=18,'前提'!$B$60,IF(21<=24,'前提'!$B$61,IF(21<=36,'前提'!$B$62,IF(21<=48,'前提'!$B$63,'前提'!$B$64)))))) | W5: =IF(22<=6,'前提'!$B$58,IF(22<=12,'前提'!$B$59,IF(22<=18,'前提'!$B$60,IF(22<=24,'前提'!$B$61,IF(22<=36,'前提'!$B$62,IF(22<=48,'前提'!$B$63,'前提'!$B$64)))))) | X5: =IF(23<=6,'前提'!$B$58,IF(23<=12,'前提'!$B$59,IF(23<=18,'前提'!$B$60,IF(23<=24,'前提'!$B$61,IF(23<=36,'前提'!$B$62,IF(23<=48,'前提'!$B$63,'前提'!$B$64)))))) | Y5: =IF(24<=6,'前提'!$B$58,IF(24<=12,'前提'!$B$59,IF(24<=18,'前提'!$B$60,IF(24<=24,'前提'!$B$61,IF(24<=36,'前提'!$B$62,IF(24<=48,'前提'!$B$63,'前提'!$B$64)))))) | Z5: =IF(25<=6,'前提'!$B$58,IF(25<=12,'前提'!$B$59,IF(25<=18,'前提'!$B$60,IF(25<=24,'前提'!$B$61,IF(25<=36,'前提'!$B$62,IF(25<=48,'前提'!$B$63,'前提'!$B$64)))))) | AA5: =IF(26<=6,'前提'!$B$58,IF(26<=12,'前提'!$B$59,IF(26<=18,'前提'!$B$60,IF(26<=24,'前提'!$B$61,IF(26<=36,'前提'!$B$62,IF(26<=48,'前提'!$B$63,'前提'!$B$64)))))) | AB5: =IF(27<=6,'前提'!$B$58,IF(27<=12,'前提'!$B$59,IF(27<=18,'前提'!$B$60,IF(27<=24,'前提'!$B$61,IF(27<=36,'前提'!$B$62,IF(27<=48,'前提'!$B$63,'前提'!$B$64)))))) | AC5: =IF(28<=6,'前提'!$B$58,IF(28<=12,'前提'!$B$59,IF(28<=18,'前提'!$B$60,IF(28<=24,'前提'!$B$61,IF(28<=36,'前提'!$B$62,IF(28<=48,'前提'!$B$63,'前提'!$B$64)))))) | AD5: =IF(29<=6,'前提'!$B$58,IF(29<=12,'前提'!$B$59,IF(29<=18,'前提'!$B$60,IF(29<=24,'前提'!$B$61,IF(29<=36,'前提'!$B$62,IF(29<=48,'前提'!$B$63,'前提'!$B$64)))))) | AE5: =IF(30<=6,'前提'!$B$58,IF(30<=12,'前提'!$B$59,IF(30<=18,'前提'!$B$60,IF(30<=24,'前提'!$B$61,IF(30<=36,'前提'!$B$62,IF(30<=48,'前提'!$B$63,'前提'!$B$64)))))) | AF5: =IF(31<=6,'前提'!$B$58,IF(31<=12,'前提'!$B$59,IF(31<=18,'前提'!$B$60,IF(31<=24,'前提'!$B$61,IF(31<=36,'前提'!$B$62,IF(31<=48,'前提'!$B$63,'前提'!$B$64)))))) | AG5: =IF(32<=6,'前提'!$B$58,IF(32<=12,'前提'!$B$59,IF(32<=18,'前提'!$B$60,IF(32<=24,'前提'!$B$61,IF(32<=36,'前提'!$B$62,IF(32<=48,'前提'!$B$63,'前提'!$B$64)))))) | AH5: =IF(33<=6,'前提'!$B$58,IF(33<=12,'前提'!$B$59,IF(33<=18,'前提'!$B$60,IF(33<=24,'前提'!$B$61,IF(33<=36,'前提'!$B$62,IF(33<=48,'前提'!$B$63,'前提'!$B$64)))))) | AI5: =IF(34<=6,'前提'!$B$58,IF(34<=12,'前提'!$B$59,IF(34<=18,'前提'!$B$60,IF(34<=24,'前提'!$B$61,IF(34<=36,'前提'!$B$62,IF(34<=48,'前提'!$B$63,'前提'!$B$64)))))) | AJ5: =IF(35<=6,'前提'!$B$58,IF(35<=12,'前提'!$B$59,IF(35<=18,'前提'!$B$60,IF(35<=24,'前提'!$B$61,IF(35<=36,'前提'!$B$62,IF(35<=48,'前提'!$B$63,'前提'!$B$64)))))) | AK5: =IF(36<=6,'前提'!$B$58,IF(36<=12,'前提'!$B$59,IF(36<=18,'前提'!$B$60,IF(36<=24,'前提'!$B$61,IF(36<=36,'前提'!$B$62,IF(36<=48,'前提'!$B$63,'前提'!$B$64)))))) | AL5: =IF(37<=6,'前提'!$B$58,IF(37<=12,'前提'!$B$59,IF(37<=18,'前提'!$B$60,IF(37<=24,'前提'!$B$61,IF(37<=36,'前提'!$B$62,IF(37<=48,'前提'!$B$63,'前提'!$B$64)))))) | AM5: =IF(38<=6,'前提'!$B$58,IF(38<=12,'前提'!$B$59,IF(38<=18,'前提'!$B$60,IF(38<=24,'前提'!$B$61,IF(38<=36,'前提'!$B$62,IF(38<=48,'前提'!$B$63,'前提'!$B$64)))))) | AN5: =IF(39<=6,'前提'!$B$58,IF(39<=12,'前提'!$B$59,IF(39<=18,'前提'!$B$60,IF(39<=24,'前提'!$B$61,IF(39<=36,'前提'!$B$62,IF(39<=48,'前提'!$B$63,'前提'!$B$64)))))) | AO5: =IF(40<=6,'前提'!$B$58,IF(40<=12,'前提'!$B$59,IF(40<=18,'前提'!$B$60,IF(40<=24,'前提'!$B$61,IF(40<=36,'前提'!$B$62,IF(40<=48,'前提'!$B$63,'前提'!$B$64)))))) | AP5: =IF(41<=6,'前提'!$B$58,IF(41<=12,'前提'!$B$59,IF(41<=18,'前提'!$B$60,IF(41<=24,'前提'!$B$61,IF(41<=36,'前提'!$B$62,IF(41<=48,'前提'!$B$63,'前提'!$B$64)))))) | AQ5: =IF(42<=6,'前提'!$B$58,IF(42<=12,'前提'!$B$59,IF(42<=18,'前提'!$B$60,IF(42<=24,'前提'!$B$61,IF(42<=36,'前提'!$B$62,IF(42<=48,'前提'!$B$63,'前提'!$B$64)))))) | AR5: =IF(43<=6,'前提'!$B$58,IF(43<=12,'前提'!$B$59,IF(43<=18,'前提'!$B$60,IF(43<=24,'前提'!$B$61,IF(43<=36,'前提'!$B$62,IF(43<=48,'前提'!$B$63,'前提'!$B$64)))))) | AS5: =IF(44<=6,'前提'!$B$58,IF(44<=12,'前提'!$B$59,IF(44<=18,'前提'!$B$60,IF(44<=24,'前提'!$B$61,IF(44<=36,'前提'!$B$62,IF(44<=48,'前提'!$B$63,'前提'!$B$64)))))) | AT5: =IF(45<=6,'前提'!$B$58,IF(45<=12,'前提'!$B$59,IF(45<=18,'前提'!$B$60,IF(45<=24,'前提'!$B$61,IF(45<=36,'前提'!$B$62,IF(45<=48,'前提'!$B$63,'前提'!$B$64)))))) | AU5: =IF(46<=6,'前提'!$B$58,IF(46<=12,'前提'!$B$59,IF(46<=18,'前提'!$B$60,IF(46<=24,'前提'!$B$61,IF(46<=36,'前提'!$B$62,IF(46<=48,'前提'!$B$63,'前提'!$B$64)))))) | AV5: =IF(47<=6,'前提'!$B$58,IF(47<=12,'前提'!$B$59,IF(47<=18,'前提'!$B$60,IF(47<=24,'前提'!$B$61,IF(47<=36,'前提'!$B$62,IF(47<=48,'前提'!$B$63,'前提'!$B$64)))))) | AW5: =IF(48<=6,'前提'!$B$58,IF(48<=12,'前提'!$B$59,IF(48<=18,'前提'!$B$60,IF(48<=24,'前提'!$B$61,IF(48<=36,'前提'!$B$62,IF(48<=48,'前提'!$B$63,'前提'!$B$64)))))) | AX5: =IF(49<=6,'前提'!$B$58,IF(49<=12,'前提'!$B$59,IF(49<=18,'前提'!$B$60,IF(49<=24,'前提'!$B$61,IF(49<=36,'前提'!$B$62,IF(49<=48,'前提'!$B$63,'前提'!$B$64)))))) | AY5: =IF(50<=6,'前提'!$B$58,IF(50<=12,'前提'!$B$59,IF(50<=18,'前提'!$B$60,IF(50<=24,'前提'!$B$61,IF(50<=36,'前提'!$B$62,IF(50<=48,'前提'!$B$63,'前提'!$B$64)))))) | AZ5: =IF(51<=6,'前提'!$B$58,IF(51<=12,'前提'!$B$59,IF(51<=18,'前提'!$B$60,IF(51<=24,'前提'!$B$61,IF(51<=36,'前提'!$B$62,IF(51<=48,'前提'!$B$63,'前提'!$B$64)))))) | BA5: =IF(52<=6,'前提'!$B$58,IF(52<=12,'前提'!$B$59,IF(52<=18,'前提'!$B$60,IF(52<=24,'前提'!$B$61,IF(52<=36,'前提'!$B$62,IF(52<=48,'前提'!$B$63,'前提'!$B$64)))))) | BB5: =IF(53<=6,'前提'!$B$58,IF(53<=12,'前提'!$B$59,IF(53<=18,'前提'!$B$60,IF(53<=24,'前提'!$B$61,IF(53<=36,'前提'!$B$62,IF(53<=48,'前提'!$B$63,'前提'!$B$64)))))) | BC5: =IF(54<=6,'前提'!$B$58,IF(54<=12,'前提'!$B$59,IF(54<=18,'前提'!$B$60,IF(54<=24,'前提'!$B$61,IF(54<=36,'前提'!$B$62,IF(54<=48,'前提'!$B$63,'前提'!$B$64)))))) | BD5: =IF(55<=6,'前提'!$B$58,IF(55<=12,'前提'!$B$59,IF(55<=18,'前提'!$B$60,IF(55<=24,'前提'!$B$61,IF(55<=36,'前提'!$B$62,IF(55<=48,'前提'!$B$63,'前提'!$B$64)))))) | BE5: =IF(56<=6,'前提'!$B$58,IF(56<=12,'前提'!$B$59,IF(56<=18,'前提'!$B$60,IF(56<=24,'前提'!$B$61,IF(56<=36,'前提'!$B$62,IF(56<=48,'前提'!$B$63,'前提'!$B$64)))))) | BF5: =IF(57<=6,'前提'!$B$58,IF(57<=12,'前提'!$B$59,IF(57<=18,'前提'!$B$60,IF(57<=24,'前提'!$B$61,IF(57<=36,'前提'!$B$62,IF(57<=48,'前提'!$B$63,'前提'!$B$64)))))) | BG5: =IF(58<=6,'前提'!$B$58,IF(58<=12,'前提'!$B$59,IF(58<=18,'前提'!$B$60,IF(58<=24,'前提'!$B$61,IF(58<=36,'前提'!$B$62,IF(58<=48,'前提'!$B$63,'前提'!$B$64)))))) | BH5: =IF(59<=6,'前提'!$B$58,IF(59<=12,'前提'!$B$59,IF(59<=18,'前提'!$B$60,IF(59<=24,'前提'!$B$61,IF(59<=36,'前提'!$B$62,IF(59<=48,'前提'!$B$63,'前提'!$B$64)))))) | BI5: =IF(60<=6,'前提'!$B$58,IF(60<=12,'前提'!$B$59,IF(60<=18,'前提'!$B$60,IF(60<=24,'前提'!$B$61,IF(60<=36,'前提'!$B$62,IF(60<=48,'前提'!$B$63,'前提'!$B$64))))))
A7: 【顧客数】
A8: SuguDesk期首 | B8: 1 | C8: =B10 | D8: =C10 | E8: =D10 | F8: =E10 | G8: =F10 | H8: =G10 | I8: =H10 | J8: =I10 | ... BI8: =BH10
A9: SuguDesk解約 | B9: =ROUNDDOWN(B8*'前提'!$B$8,0) | C9: =ROUNDDOWN(C8*'前提'!$B$8,0) | D9: =ROUNDDOWN(D8*'前提'!$B$8,0) | E9: =ROUNDDOWN(E8*'前提'!$B$8,0) | F9: =ROUNDDOWN(F8*'前提'!$B$8,0) | G9: =ROUNDDOWN(G8*'前提'!$B$8,0) | H9: =ROUNDDOWN(H8*'前提'!$B$8,0) | I9: =ROUNDDOWN(I8*'前提'!$B$8,0) | ... BI9: =ROUNDDOWN(BI8*'前提'!$B$8,0)
A10: SuguDesk期末 | B10: =B8+B5-B9 | C10: =C8+C5-C9 | D10: =D8+D5-D9 | E10: =E8+E5-E9 | F10: =F8+F5-F9 | G10: =G8+G5-G9 | H10: =H8+H5-H9 | I10: =I8+I5-I9 | ... BI10: =BI8+BI5-BI9
A11: BPO新規転換 | B11: =IF(1>=7,ROUNDDOWN(B10*(IF(1<=6,'前提'!$B$67,IF(1<=12,'前提'!$B$68,IF(1<=18,'前提'!$B$69,IF(1<=24,'前提'!$B$70,IF(1<=36,'前提'!$B$71,IF(1<=48,'前提'!$B$72,'前提'!$B$73))))))),0),0) | C11: =IF(2>=7,ROUNDDOWN(C10*(IF(2<=6,'前提'!$B$67,IF(2<=12,'前提'!$B$68,IF(2<=18,'前提'!$B$69,IF(2<=24,'前提'!$B$70,IF(2<=36,'前提'!$B$71,IF(2<=48,'前提'!$B$72,'前提'!$B$73))))))),0),0) | D11: =IF(3>=7,ROUNDDOWN(D10*(IF(3<=6,'前提'!$B$67,IF(3<=12,'前提'!$B$68,IF(3<=18,'前提'!$B$69,IF(3<=24,'前提'!$B$70,IF(3<=36,'前提'!$B$71,IF(3<=48,'前提'!$B$72,'前提'!$B$73))))))),0),0) | E11: =IF(4>=7,ROUNDDOWN(E10*(IF(4<=6,'前提'!$B$67,IF(4<=12,'前提'!$B$68,IF(4<=18,'前提'!$B$69,IF(4<=24,'前提'!$B$70,IF(4<=36,'前提'!$B$71,IF(4<=48,'前提'!$B$72,'前提'!$B$73))))))),0),0) | F11: =IF(5>=7,ROUNDDOWN(F10*(IF(5<=6,'前提'!$B$67,IF(5<=12,'前提'!$B$68,IF(5<=18,'前提'!$B$69,IF(5<=24,'前提'!$B$70,IF(5<=36,'前提'!$B$71,IF(5<=48,'前提'!$B$72,'前提'!$B$73))))))),0),0) | G11: =IF(6>=7,ROUNDDOWN(G10*(IF(6<=6,'前提'!$B$67,IF(6<=12,'前提'!$B$68,IF(6<=18,'前提'!$B$69,IF(6<=24,'前提'!$B$70,IF(6<=36,'前提'!$B$71,IF(6<=48,'前提'!$B$72,'前提'!$B$73))))))),0),0) | H11: =IF(7>=7,ROUNDDOWN(H10*(IF(7<=6,'前提'!$B$67,IF(7<=12,'前提'!$B$68,IF(7<=18,'前提'!$B$69,IF(7<=24,'前提'!$B$70,IF(7<=36,'前提'!$B$71,IF(7<=48,'前提'!$B$72,'前提'!$B$73))))))),0),0) | I11: =IF(8>=7,ROUNDDOWN(I10*(IF(8<=6,'前提'!$B$67,IF(8<=12,'前提'!$B$68,IF(8<=18,'前提'!$B$69,IF(8<=24,'前提'!$B$70,IF(8<=36,'前提'!$B$71,IF(8<=48,'前提'!$B$72,'前提'!$B$73))))))),0),0) | J11: =IF(9>=7,ROUNDDOWN(J10*(IF(9<=6,'前提'!$B$67,IF(9<=12,'前提'!$B$68,IF(9<=18,'前提'!$B$69,IF(9<=24,'前提'!$B$70,IF(9<=36,'前提'!$B$71,IF(9<=48,'前提'!$B$72,'前提'!$B$73))))))),0),0) | K11: =IF(10>=7,ROUNDDOWN(K10*(IF(10<=6,'前提'!$B$67,IF(10<=12,'前提'!$B$68,IF(10<=18,'前提'!$B$69,IF(10<=24,'前提'!$B$70,IF(10<=36,'前提'!$B$71,IF(10<=48,'前提'!$B$72,'前提'!$B$73))))))),0),0) | L11: =IF(11>=7,ROUNDDOWN(L10*(IF(11<=6,'前提'!$B$67,IF(11<=12,'前提'!$B$68,IF(11<=18,'前提'!$B$69,IF(11<=24,'前提'!$B$70,IF(11<=36,'前提'!$B$71,IF(11<=48,'前提'!$B$72,'前提'!$B$73))))))),0),0) | M11: =IF(12>=7,ROUNDDOWN(M10*(IF(12<=6,'前提'!$B$67,IF(12<=12,'前提'!$B$68,IF(12<=18,'前提'!$B$69,IF(12<=24,'前提'!$B$70,IF(12<=36,'前提'!$B$71,IF(12<=48,'前提'!$B$72,'前提'!$B$73))))))),0),0) | N11: =IF(13>=7,ROUNDDOWN(N10*(IF(13<=6,'前提'!$B$67,IF(13<=12,'前提'!$B$68,IF(13<=18,'前提'!$B$69,IF(13<=24,'前提'!$B$70,IF(13<=36,'前提'!$B$71,IF(13<=48,'前提'!$B$72,'前提'!$B$73))))))),0),0) | O11: =IF(14>=7,ROUNDDOWN(O10*(IF(14<=6,'前提'!$B$67,IF(14<=12,'前提'!$B$68,IF(14<=18,'前提'!$B$69,IF(14<=24,'前提'!$B$70,IF(14<=36,'前提'!$B$71,IF(14<=48,'前提'!$B$72,'前提'!$B$73))))))),0),0) | P11: =IF(15>=7,ROUNDDOWN(P10*(IF(15<=6,'前提'!$B$67,IF(15<=12,'前提'!$B$68,IF(15<=18,'前提'!$B$69,IF(15<=24,'前提'!$B$70,IF(15<=36,'前提'!$B$71,IF(15<=48,'前提'!$B$72,'前提'!$B$73))))))),0),0) | Q11: =IF(16>=7,ROUNDDOWN(Q10*(IF(16<=6,'前提'!$B$67,IF(16<=12,'前提'!$B$68,IF(16<=18,'前提'!$B$69,IF(16<=24,'前提'!$B$70,IF(16<=36,'前提'!$B$71,IF(16<=48,'前提'!$B$72,'前提'!$B$73))))))),0),0) | R11: =IF(17>=7,ROUNDDOWN(R10*(IF(17<=6,'前提'!$B$67,IF(17<=12,'前提'!$B$68,IF(17<=18,'前提'!$B$69,IF(17<=24,'前提'!$B$70,IF(17<=36,'前提'!$B$71,IF(17<=48,'前提'!$B$72,'前提'!$B$73))))))),0),0) | S11: =IF(18>=7,ROUNDDOWN(S10*(IF(18<=6,'前提'!$B$67,IF(18<=12,'前提'!$B$68,IF(18<=18,'前提'!$B$69,IF(18<=24,'前提'!$B$70,IF(18<=36,'前提'!$B$71,IF(18<=48,'前提'!$B$72,'前提'!$B$73))))))),0),0) | T11: =IF(19>=7,ROUNDDOWN(T10*(IF(19<=6,'前提'!$B$67,IF(19<=12,'前提'!$B$68,IF(19<=18,'前提'!$B$69,IF(19<=24,'前提'!$B$70,IF(19<=36,'前提'!$B$71,IF(19<=48,'前提'!$B$72,'前提'!$B$73))))))),0),0) | U11: =IF(20>=7,ROUNDDOWN(U10*(IF(20<=6,'前提'!$B$67,IF(20<=12,'前提'!$B$68,IF(20<=18,'前提'!$B$69,IF(20<=24,'前提'!$B$70,IF(20<=36,'前提'!$B$71,IF(20<=48,'前提'!$B$72,'前提'!$B$73))))))),0),0) | V11: =IF(21>=7,ROUNDDOWN(V10*(IF(21<=6,'前提'!$B$67,IF(21<=12,'前提'!$B$68,IF(21<=18,'前提'!$B$69,IF(21<=24,'前提'!$B$70,IF(21<=36,'前提'!$B$71,IF(21<=48,'前提'!$B$72,'前提'!$B$73))))))),0),0) | W11: =IF(22>=7,ROUNDDOWN(W10*(IF(22<=6,'前提'!$B$67,IF(22<=12,'前提'!$B$68,IF(22<=18,'前提'!$B$69,IF(22<=24,'前提'!$B$70,IF(22<=36,'前提'!$B$71,IF(22<=48,'前提'!$B$72,'前提'!$B$73))))))),0),0) | X11: =IF(23>=7,ROUNDDOWN(X10*(IF(23<=6,'前提'!$B$67,IF(23<=12,'前提'!$B$68,IF(23<=18,'前提'!$B$69,IF(23<=24,'前提'!$B$70,IF(23<=36,'前提'!$B$71,IF(23<=48,'前提'!$B$72,'前提'!$B$73))))))),0),0) | Y11: =IF(24>=7,ROUNDDOWN(Y10*(IF(24<=6,'前提'!$B$67,IF(24<=12,'前提'!$B$68,IF(24<=18,'前提'!$B$69,IF(24<=24,'前提'!$B$70,IF(24<=36,'前提'!$B$71,IF(24<=48,'前提'!$B$72,'前提'!$B$73))))))),0),0) | Z11: =IF(25>=7,ROUNDDOWN(Z10*(IF(25<=6,'前提'!$B$67,IF(25<=12,'前提'!$B$68,IF(25<=18,'前提'!$B$69,IF(25<=24,'前提'!$B$70,IF(25<=36,'前提'!$B$71,IF(25<=48,'前提'!$B$72,'前提'!$B$73))))))),0),0) | AA11: =IF(26>=7,ROUNDDOWN(AA10*(IF(26<=6,'前提'!$B$67,IF(26<=12,'前提'!$B$68,IF(26<=18,'前提'!$B$69,IF(26<=24,'前提'!$B$70,IF(26<=36,'前提'!$B$71,IF(26<=48,'前提'!$B$72,'前提'!$B$73))))))),0),0) | AB11: =IF(27>=7,ROUNDDOWN(AB10*(IF(27<=6,'前提'!$B$67,IF(27<=12,'前提'!$B$68,IF(27<=18,'前提'!$B$69,IF(27<=24,'前提'!$B$70,IF(27<=36,'前提'!$B$71,IF(27<=48,'前提'!$B$72,'前提'!$B$73))))))),0),0) | AC11: =IF(28>=7,ROUNDDOWN(AC10*(IF(28<=6,'前提'!$B$67,IF(28<=12,'前提'!$B$68,IF(28<=18,'前提'!$B$69,IF(28<=24,'前提'!$B$70,IF(28<=36,'前提'!$B$71,IF(28<=48,'前提'!$B$72,'前提'!$B$73))))))),0),0) | AD11: =IF(29>=7,ROUNDDOWN(AD10*(IF(29<=6,'前提'!$B$67,IF(29<=12,'前提'!$B$68,IF(29<=18,'前提'!$B$69,IF(29<=24,'前提'!$B$70,IF(29<=36,'前提'!$B$71,IF(29<=48,'前提'!$B$72,'前提'!$B$73))))))),0),0) | AE11: =IF(30>=7,ROUNDDOWN(AE10*(IF(30<=6,'前提'!$B$67,IF(30<=12,'前提'!$B$68,IF(30<=18,'前提'!$B$69,IF(30<=24,'前提'!$B$70,IF(30<=36,'前提'!$B$71,IF(30<=48,'前提'!$B$72,'前提'!$B$73))))))),0),0) | AF11: =IF(31>=7,ROUNDDOWN(AF10*(IF(31<=6,'前提'!$B$67,IF(31<=12,'前提'!$B$68,IF(31<=18,'前提'!$B$69,IF(31<=24,'前提'!$B$70,IF(31<=36,'前提'!$B$71,IF(31<=48,'前提'!$B$72,'前提'!$B$73))))))),0),0) | AG11: =IF(32>=7,ROUNDDOWN(AG10*(IF(32<=6,'前提'!$B$67,IF(32<=12,'前提'!$B$68,IF(32<=18,'前提'!$B$69,IF(32<=24,'前提'!$B$70,IF(32<=36,'前提'!$B$71,IF(32<=48,'前提'!$B$72,'前提'!$B$73))))))),0),0) | AH11: =IF(33>=7,ROUNDDOWN(AH10*(IF(33<=6,'前提'!$B$67,IF(33<=12,'前提'!$B$68,IF(33<=18,'前提'!$B$69,IF(33<=24,'前提'!$B$70,IF(33<=36,'前提'!$B$71,IF(33<=48,'前提'!$B$72,'前提'!$B$73))))))),0),0) | AI11: =IF(34>=7,ROUNDDOWN(AI10*(IF(34<=6,'前提'!$B$67,IF(34<=12,'前提'!$B$68,IF(34<=18,'前提'!$B$69,IF(34<=24,'前提'!$B$70,IF(34<=36,'前提'!$B$71,IF(34<=48,'前提'!$B$72,'前提'!$B$73))))))),0),0) | AJ11: =IF(35>=7,ROUNDDOWN(AJ10*(IF(35<=6,'前提'!$B$67,IF(35<=12,'前提'!$B$68,IF(35<=18,'前提'!$B$69,IF(35<=24,'前提'!$B$70,IF(35<=36,'前提'!$B$71,IF(35<=48,'前提'!$B$72,'前提'!$B$73))))))),0),0) | AK11: =IF(36>=7,ROUNDDOWN(AK10*(IF(36<=6,'前提'!$B$67,IF(36<=12,'前提'!$B$68,IF(36<=18,'前提'!$B$69,IF(36<=24,'前提'!$B$70,IF(36<=36,'前提'!$B$71,IF(36<=48,'前提'!$B$72,'前提'!$B$73))))))),0),0) | AL11: =IF(37>=7,ROUNDDOWN(AL10*(IF(37<=6,'前提'!$B$67,IF(37<=12,'前提'!$B$68,IF(37<=18,'前提'!$B$69,IF(37<=24,'前提'!$B$70,IF(37<=36,'前提'!$B$71,IF(37<=48,'前提'!$B$72,'前提'!$B$73))))))),0),0) | AM11: =IF(38>=7,ROUNDDOWN(AM10*(IF(38<=6,'前提'!$B$67,IF(38<=12,'前提'!$B$68,IF(38<=18,'前提'!$B$69,IF(38<=24,'前提'!$B$70,IF(38<=36,'前提'!$B$71,IF(38<=48,'前提'!$B$72,'前提'!$B$73))))))),0),0) | AN11: =IF(39>=7,ROUNDDOWN(AN10*(IF(39<=6,'前提'!$B$67,IF(39<=12,'前提'!$B$68,IF(39<=18,'前提'!$B$69,IF(39<=24,'前提'!$B$70,IF(39<=36,'前提'!$B$71,IF(39<=48,'前提'!$B$72,'前提'!$B$73))))))),0),0) | AO11: =IF(40>=7,ROUNDDOWN(AO10*(IF(40<=6,'前提'!$B$67,IF(40<=12,'前提'!$B$68,IF(40<=18,'前提'!$B$69,IF(40<=24,'前提'!$B$70,IF(40<=36,'前提'!$B$71,IF(40<=48,'前提'!$B$72,'前提'!$B$73))))))),0),0) | AP11: =IF(41>=7,ROUNDDOWN(AP10*(IF(41<=6,'前提'!$B$67,IF(41<=12,'前提'!$B$68,IF(41<=18,'前提'!$B$69,IF(41<=24,'前提'!$B$70,IF(41<=36,'前提'!$B$71,IF(41<=48,'前提'!$B$72,'前提'!$B$73))))))),0),0) | AQ11: =IF(42>=7,ROUNDDOWN(AQ10*(IF(42<=6,'前提'!$B$67,IF(42<=12,'前提'!$B$68,IF(42<=18,'前提'!$B$69,IF(42<=24,'前提'!$B$70,IF(42<=36,'前提'!$B$71,IF(42<=48,'前提'!$B$72,'前提'!$B$73))))))),0),0) | AR11: =IF(43>=7,ROUNDDOWN(AR10*(IF(43<=6,'前提'!$B$67,IF(43<=12,'前提'!$B$68,IF(43<=18,'前提'!$B$69,IF(43<=24,'前提'!$B$70,IF(43<=36,'前提'!$B$71,IF(43<=48,'前提'!$B$72,'前提'!$B$73))))))),0),0) | AS11: =IF(44>=7,ROUNDDOWN(AS10*(IF(44<=6,'前提'!$B$67,IF(44<=12,'前提'!$B$68,IF(44<=18,'前提'!$B$69,IF(44<=24,'前提'!$B$70,IF(44<=36,'前提'!$B$71,IF(44<=48,'前提'!$B$72,'前提'!$B$73))))))),0),0) | AT11: =IF(45>=7,ROUNDDOWN(AT10*(IF(45<=6,'前提'!$B$67,IF(45<=12,'前提'!$B$68,IF(45<=18,'前提'!$B$69,IF(45<=24,'前提'!$B$70,IF(45<=36,'前提'!$B$71,IF(45<=48,'前提'!$B$72,'前提'!$B$73))))))),0),0) | AU11: =IF(46>=7,ROUNDDOWN(AU10*(IF(46<=6,'前提'!$B$67,IF(46<=12,'前提'!$B$68,IF(46<=18,'前提'!$B$69,IF(46<=24,'前提'!$B$70,IF(46<=36,'前提'!$B$71,IF(46<=48,'前提'!$B$72,'前提'!$B$73))))))),0),0) | AV11: =IF(47>=7,ROUNDDOWN(AV10*(IF(47<=6,'前提'!$B$67,IF(47<=12,'前提'!$B$68,IF(47<=18,'前提'!$B$69,IF(47<=24,'前提'!$B$70,IF(47<=36,'前提'!$B$71,IF(47<=48,'前提'!$B$72,'前提'!$B$73))))))),0),0) | AW11: =IF(48>=7,ROUNDDOWN(AW10*(IF(48<=6,'前提'!$B$67,IF(48<=12,'前提'!$B$68,IF(48<=18,'前提'!$B$69,IF(48<=24,'前提'!$B$70,IF(48<=36,'前提'!$B$71,IF(48<=48,'前提'!$B$72,'前提'!$B$73))))))),0),0) | AX11: =IF(49>=7,ROUNDDOWN(AX10*(IF(49<=6,'前提'!$B$67,IF(49<=12,'前提'!$B$68,IF(49<=18,'前提'!$B$69,IF(49<=24,'前提'!$B$70,IF(49<=36,'前提'!$B$71,IF(49<=48,'前提'!$B$72,'前提'!$B$73))))))),0),0) | AY11: =IF(50>=7,ROUNDDOWN(AY10*(IF(50<=6,'前提'!$B$67,IF(50<=12,'前提'!$B$68,IF(50<=18,'前提'!$B$69,IF(50<=24,'前提'!$B$70,IF(50<=36,'前提'!$B$71,IF(50<=48,'前提'!$B$72,'前提'!$B$73))))))),0),0) | AZ11: =IF(51>=7,ROUNDDOWN(AZ10*(IF(51<=6,'前提'!$B$67,IF(51<=12,'前提'!$B$68,IF(51<=18,'前提'!$B$69,IF(51<=24,'前提'!$B$70,IF(51<=36,'前提'!$B$71,IF(51<=48,'前提'!$B$72,'前提'!$B$73))))))),0),0) | BA11: =IF(52>=7,ROUNDDOWN(BA10*(IF(52<=6,'前提'!$B$67,IF(52<=12,'前提'!$B$68,IF(52<=18,'前提'!$B$69,IF(52<=24,'前提'!$B$70,IF(52<=36,'前提'!$B$71,IF(52<=48,'前提'!$B$72,'前提'!$B$73))))))),0),0) | BB11: =IF(53>=7,ROUNDDOWN(BB10*(IF(53<=6,'前提'!$B$67,IF(53<=12,'前提'!$B$68,IF(53<=18,'前提'!$B$69,IF(53<=24,'前提'!$B$70,IF(53<=36,'前提'!$B$71,IF(53<=48,'前提'!$B$72,'前提'!$B$73))))))),0),0) | BC11: =IF(54>=7,ROUNDDOWN(BC10*(IF(54<=6,'前提'!$B$67,IF(54<=12,'前提'!$B$68,IF(54<=18,'前提'!$B$69,IF(54<=24,'前提'!$B$70,IF(54<=36,'前提'!$B$71,IF(54<=48,'前提'!$B$72,'前提'!$B$73))))))),0),0) | BD11: =IF(55>=7,ROUNDDOWN(BD10*(IF(55<=6,'前提'!$B$67,IF(55<=12,'前提'!$B$68,IF(55<=18,'前提'!$B$69,IF(55<=24,'前提'!$B$70,IF(55<=36,'前提'!$B$71,IF(55<=48,'前提'!$B$72,'前提'!$B$73))))))),0),0) | BE11: =IF(56>=7,ROUNDDOWN(BE10*(IF(56<=6,'前提'!$B$67,IF(56<=12,'前提'!$B$68,IF(56<=18,'前提'!$B$69,IF(56<=24,'前提'!$B$70,IF(56<=36,'前提'!$B$71,IF(56<=48,'前提'!$B$72,'前提'!$B$73))))))),0),0) | BF11: =IF(57>=7,ROUNDDOWN(BF10*(IF(57<=6,'前提'!$B$67,IF(57<=12,'前提'!$B$68,IF(57<=18,'前提'!$B$69,IF(57<=24,'前提'!$B$70,IF(57<=36,'前提'!$B$71,IF(57<=48,'前提'!$B$72,'前提'!$B$73))))))),0),0) | BG11: =IF(58>=7,ROUNDDOWN(BG10*(IF(58<=6,'前提'!$B$67,IF(58<=12,'前提'!$B$68,IF(58<=18,'前提'!$B$69,IF(58<=24,'前提'!$B$70,IF(58<=36,'前提'!$B$71,IF(58<=48,'前提'!$B$72,'前提'!$B$73))))))),0),0) | BH11: =IF(59>=7,ROUNDDOWN(BH10*(IF(59<=6,'前提'!$B$67,IF(59<=12,'前提'!$B$68,IF(59<=18,'前提'!$B$69,IF(59<=24,'前提'!$B$70,IF(59<=36,'前提'!$B$71,IF(59<=48,'前提'!$B$72,'前提'!$B$73))))))),0),0) | BI11: =IF(60>=7,ROUNDDOWN(BI10*(IF(60<=6,'前提'!$B$67,IF(60<=12,'前提'!$B$68,IF(60<=18,'前提'!$B$69,IF(60<=24,'前提'!$B$70,IF(60<=36,'前提'!$B$71,IF(60<=48,'前提'!$B$72,'前提'!$B$73))))))),0),0)
A12: BPO解約 | B12: =ROUNDDOWN(B13*'前提'!$B$9,0) | C12: =ROUNDDOWN(C13*'前提'!$B$9,0) | D12: =ROUNDDOWN(D13*'前提'!$B$9,0) | E12: =ROUNDDOWN(E13*'前提'!$B$9,0) | F12: =ROUNDDOWN(F13*'前提'!$B$9,0) | G12: =ROUNDDOWN(G13*'前提'!$B$9,0) | H12: =ROUNDDOWN(H13*'前提'!$B$9,0) | I12: =ROUNDDOWN(I13*'前提'!$B$9,0) | ... BI12: =ROUNDDOWN(BI13*'前提'!$B$9,0)
A13: BPO期首 | B13: 0 | C13: =B14 | D13: =C14 | E13: =D14 | F13: =E14 | G13: =F14 | H13: =G14 | I13: =H14 | J13: =I14 | ... BI13: =BH14
A14: BPO期末 | B14: =B13+B11-B12 | C14: =C13+C11-C12 | D14: =D13+D11-D12 | E14: =E13+E11-E12 | F14: =F13+F11-F12 | G14: =G13+G11-G12 | H14: =H13+H11-H12 | I14: =I13+I11-I12 | ... BI14: =BI13+BI11-BI12
A16: 【売上】
A17: SuguDesk月額売上 | B17: =(B8+B5*'前提'!$B$12-B9*'前提'!$B$12)*'前提'!$B$4 | C17: =(C8+C5*'前提'!$B$12-C9*'前提'!$B$12)*'前提'!$B$4 | D17: =(D8+D5*'前提'!$B$12-D9*'前提'!$B$12)*'前提'!$B$4 | E17: =(E8+E5*'前提'!$B$12-E9*'前提'!$B$12)*'前提'!$B$4 | F17: =(F8+F5*'前提'!$B$12-F9*'前提'!$B$12)*'前提'!$B$4 | G17: =(G8+G5*'前提'!$B$12-G9*'前提'!$B$12)*'前提'!$B$4 | H17: =(H8+H5*'前提'!$B$12-H9*'前提'!$B$12)*'前提'!$B$4 | I17: =(I8+I5*'前提'!$B$12-I9*'前提'!$B$12)*'前提'!$B$4 | ... BI17: =(BI8+BI5*'前提'!$B$12-BI9*'前提'!$B$12)*'前提'!$B$4
A18: BPO事務長代行売上 | B18: =(B13+B11*'前提'!$B$12-B12*'前提'!$B$12)*'前提'!$B$6 | C18: =(C13+C11*'前提'!$B$12-C12*'前提'!$B$12)*'前提'!$B$6 | D18: =(D13+D11*'前提'!$B$12-D12*'前提'!$B$12)*'前提'!$B$6 | E18: =(E13+E11*'前提'!$B$12-E12*'前提'!$B$12)*'前提'!$B$6 | F18: =(F13+F11*'前提'!$B$12-F12*'前提'!$B$12)*'前提'!$B$6 | G18: =(G13+G11*'前提'!$B$12-G12*'前提'!$B$12)*'前提'!$B$6 | H18: =(H13+H11*'前提'!$B$12-H12*'前提'!$B$12)*'前提'!$B$6 | I18: =(I13+I11*'前提'!$B$12-I12*'前提'!$B$12)*'前提'!$B$6 | ... BI18: =(BI13+BI11*'前提'!$B$12-BI12*'前提'!$B$12)*'前提'!$B$6
A19: BPO採用/集患売上（M13+） | B19: =IF(1>=13,(B13+B11*'前提'!$B$12-B12*'前提'!$B$12)*'前提'!$B$7,0) | C19: =IF(2>=13,(C13+C11*'前提'!$B$12-C12*'前提'!$B$12)*'前提'!$B$7,0) | D19: =IF(3>=13,(D13+D11*'前提'!$B$12-D12*'前提'!$B$12)*'前提'!$B$7,0) | E19: =IF(4>=13,(E13+E11*'前提'!$B$12-E12*'前提'!$B$12)*'前提'!$B$7,0) | F19: =IF(5>=13,(F13+F11*'前提'!$B$12-F12*'前提'!$B$12)*'前提'!$B$7,0) | G19: =IF(6>=13,(G13+G11*'前提'!$B$12-G12*'前提'!$B$12)*'前提'!$B$7,0) | H19: =IF(7>=13,(H13+H11*'前提'!$B$12-H12*'前提'!$B$12)*'前提'!$B$7,0) | I19: =IF(8>=13,(I13+I11*'前提'!$B$12-I12*'前提'!$B$12)*'前提'!$B$7,0) | J19: =IF(9>=13,(J13+J11*'前提'!$B$12-J12*'前提'!$B$12)*'前提'!$B$7,0) | K19: =IF(10>=13,(K13+K11*'前提'!$B$12-K12*'前提'!$B$12)*'前提'!$B$7,0) | L19: =IF(11>=13,(L13+L11*'前提'!$B$12-L12*'前提'!$B$12)*'前提'!$B$7,0) | M19: =IF(12>=13,(M13+M11*'前提'!$B$12-M12*'前提'!$B$12)*'前提'!$B$7,0) | N19: =IF(13>=13,(N13+N11*'前提'!$B$12-N12*'前提'!$B$12)*'前提'!$B$7,0) | O19: =IF(14>=13,(O13+O11*'前提'!$B$12-O12*'前提'!$B$12)*'前提'!$B$7,0) | P19: =IF(15>=13,(P13+P11*'前提'!$B$12-P12*'前提'!$B$12)*'前提'!$B$7,0) | Q19: =IF(16>=13,(Q13+Q11*'前提'!$B$12-Q12*'前提'!$B$12)*'前提'!$B$7,0) | R19: =IF(17>=13,(R13+R11*'前提'!$B$12-R12*'前提'!$B$12)*'前提'!$B$7,0) | S19: =IF(18>=13,(S13+S11*'前提'!$B$12-S12*'前提'!$B$12)*'前提'!$B$7,0) | T19: =IF(19>=13,(T13+T11*'前提'!$B$12-T12*'前提'!$B$12)*'前提'!$B$7,0) | U19: =IF(20>=13,(U13+U11*'前提'!$B$12-U12*'前提'!$B$12)*'前提'!$B$7,0) | V19: =IF(21>=13,(V13+V11*'前提'!$B$12-V12*'前提'!$B$12)*'前提'!$B$7,0) | W19: =IF(22>=13,(W13+W11*'前提'!$B$12-W12*'前提'!$B$12)*'前提'!$B$7,0) | X19: =IF(23>=13,(X13+X11*'前提'!$B$12-X12*'前提'!$B$12)*'前提'!$B$7,0) | Y19: =IF(24>=13,(Y13+Y11*'前提'!$B$12-Y12*'前提'!$B$12)*'前提'!$B$7,0) | Z19: =IF(25>=13,(Z13+Z11*'前提'!$B$12-Z12*'前提'!$B$12)*'前提'!$B$7,0) | AA19: =IF(26>=13,(AA13+AA11*'前提'!$B$12-AA12*'前提'!$B$12)*'前提'!$B$7,0) | AB19: =IF(27>=13,(AB13+AB11*'前提'!$B$12-AB12*'前提'!$B$12)*'前提'!$B$7,0) | AC19: =IF(28>=13,(AC13+AC11*'前提'!$B$12-AC12*'前提'!$B$12)*'前提'!$B$7,0) | AD19: =IF(29>=13,(AD13+AD11*'前提'!$B$12-AD12*'前提'!$B$12)*'前提'!$B$7,0) | AE19: =IF(30>=13,(AE13+AE11*'前提'!$B$12-AE12*'前提'!$B$12)*'前提'!$B$7,0) | AF19: =IF(31>=13,(AF13+AF11*'前提'!$B$12-AF12*'前提'!$B$12)*'前提'!$B$7,0) | AG19: =IF(32>=13,(AG13+AG11*'前提'!$B$12-AG12*'前提'!$B$12)*'前提'!$B$7,0) | AH19: =IF(33>=13,(AH13+AH11*'前提'!$B$12-AH12*'前提'!$B$12)*'前提'!$B$7,0) | AI19: =IF(34>=13,(AI13+AI11*'前提'!$B$12-AI12*'前提'!$B$12)*'前提'!$B$7,0) | AJ19: =IF(35>=13,(AJ13+AJ11*'前提'!$B$12-AJ12*'前提'!$B$12)*'前提'!$B$7,0) | AK19: =IF(36>=13,(AK13+AK11*'前提'!$B$12-AK12*'前提'!$B$12)*'前提'!$B$7,0) | AL19: =IF(37>=13,(AL13+AL11*'前提'!$B$12-AL12*'前提'!$B$12)*'前提'!$B$7,0) | AM19: =IF(38>=13,(AM13+AM11*'前提'!$B$12-AM12*'前提'!$B$12)*'前提'!$B$7,0) | AN19: =IF(39>=13,(AN13+AN11*'前提'!$B$12-AN12*'前提'!$B$12)*'前提'!$B$7,0) | AO19: =IF(40>=13,(AO13+AO11*'前提'!$B$12-AO12*'前提'!$B$12)*'前提'!$B$7,0) | AP19: =IF(41>=13,(AP13+AP11*'前提'!$B$12-AP12*'前提'!$B$12)*'前提'!$B$7,0) | AQ19: =IF(42>=13,(AQ13+AQ11*'前提'!$B$12-AQ12*'前提'!$B$12)*'前提'!$B$7,0) | AR19: =IF(43>=13,(AR13+AR11*'前提'!$B$12-AR12*'前提'!$B$12)*'前提'!$B$7,0) | AS19: =IF(44>=13,(AS13+AS11*'前提'!$B$12-AS12*'前提'!$B$12)*'前提'!$B$7,0) | AT19: =IF(45>=13,(AT13+AT11*'前提'!$B$12-AT12*'前提'!$B$12)*'前提'!$B$7,0) | AU19: =IF(46>=13,(AU13+AU11*'前提'!$B$12-AU12*'前提'!$B$12)*'前提'!$B$7,0) | AV19: =IF(47>=13,(AV13+AV11*'前提'!$B$12-AV12*'前提'!$B$12)*'前提'!$B$7,0) | AW19: =IF(48>=13,(AW13+AW11*'前提'!$B$12-AW12*'前提'!$B$12)*'前提'!$B$7,0) | AX19: =IF(49>=13,(AX13+AX11*'前提'!$B$12-AX12*'前提'!$B$12)*'前提'!$B$7,0) | AY19: =IF(50>=13,(AY13+AY11*'前提'!$B$12-AY12*'前提'!$B$12)*'前提'!$B$7,0) | AZ19: =IF(51>=13,(AZ13+AZ11*'前提'!$B$12-AZ12*'前提'!$B$12)*'前提'!$B$7,0) | BA19: =IF(52>=13,(BA13+BA11*'前提'!$B$12-BA12*'前提'!$B$12)*'前提'!$B$7,0) | BB19: =IF(53>=13,(BB13+BB11*'前提'!$B$12-BB12*'前提'!$B$12)*'前提'!$B$7,0) | BC19: =IF(54>=13,(BC13+BC11*'前提'!$B$12-BC12*'前提'!$B$12)*'前提'!$B$7,0) | BD19: =IF(55>=13,(BD13+BD11*'前提'!$B$12-BD12*'前提'!$B$12)*'前提'!$B$7,0) | BE19: =IF(56>=13,(BE13+BE11*'前提'!$B$12-BE12*'前提'!$B$12)*'前提'!$B$7,0) | BF19: =IF(57>=13,(BF13+BF11*'前提'!$B$12-BF12*'前提'!$B$12)*'前提'!$B$7,0) | BG19: =IF(58>=13,(BG13+BG11*'前提'!$B$12-BG12*'前提'!$B$12)*'前提'!$B$7,0) | BH19: =IF(59>=13,(BH13+BH11*'前提'!$B$12-BH12*'前提'!$B$12)*'前提'!$B$7,0) | BI19: =IF(60>=13,(BI13+BI11*'前提'!$B$12-BI12*'前提'!$B$12)*'前提'!$B$7,0)
A20: 導入費用 | B20: =B5*'前提'!$B$5*'前提'!$B$13 | C20: =C5*'前提'!$B$5*'前提'!$B$13 | D20: =D5*'前提'!$B$5*'前提'!$B$13 | E20: =E5*'前提'!$B$5*'前提'!$B$13 | F20: =F5*'前提'!$B$5*'前提'!$B$13 | G20: =G5*'前提'!$B$5*'前提'!$B$13 | H20: =H5*'前提'!$B$5*'前提'!$B$13 | I20: =I5*'前提'!$B$5*'前提'!$B$13 | ... BI20: =BI5*'前提'!$B$5*'前提'!$B$13
A21: MRR | B21: =B17+B18+B19 | C21: =C17+C18+C19 | D21: =D17+D18+D19 | E21: =E17+E18+E19 | F21: =F17+F18+F19 | G21: =G17+G18+G19 | H21: =H17+H18+H19 | I21: =I17+I18+I19 | ... BI21: =BI17+BI18+BI19
A22: 売上合計 | B22: =B21+B20 | C22: =C21+C20 | D22: =D21+D20 | E22: =E21+E20 | F22: =F21+F20 | G22: =G21+G20 | H22: =H21+H20 | I22: =I21+I20 | ... BI22: =BI21+BI20
A24: 【直接原価（変動費）】
A25: FAQ構築原価（新規件連動） | B25: =B5*'前提'!$B$16 | C25: =C5*'前提'!$B$16 | D25: =D5*'前提'!$B$16 | E25: =E5*'前提'!$B$16 | F25: =F5*'前提'!$B$16 | G25: =G5*'前提'!$B$16 | H25: =H5*'前提'!$B$16 | I25: =I5*'前提'!$B$16 | ... BI25: =BI5*'前提'!$B$16
A26: 月額メンテ原価（既存件連動） | B26: =B10*'前提'!$B$17 | C26: =C10*'前提'!$B$17 | D26: =D10*'前提'!$B$17 | E26: =E10*'前提'!$B$17 | F26: =F10*'前提'!$B$17 | G26: =G10*'前提'!$B$17 | H26: =H10*'前提'!$B$17 | I26: =I10*'前提'!$B$17 | ... BI26: =BI10*'前提'!$B$17
A27: LLM API変動費 | B27: =(B10+B14)*'前提'!$B$18 | C27: =(C10+C14)*'前提'!$B$18 | D27: =(D10+D14)*'前提'!$B$18 | E27: =(E10+E14)*'前提'!$B$18 | F27: =(F10+F14)*'前提'!$B$18 | G27: =(G10+G14)*'前提'!$B$18 | H27: =(H10+H14)*'前提'!$B$18 | I27: =(I10+I14)*'前提'!$B$18 | ... BI27: =(BI10+BI14)*'前提'!$B$18
A28: インフラ（Cloud SQL+Run） | B28: =IF((B10+B14)<=50,'前提'!$B$21,IF((B10+B14)<=200,'前提'!$B$22,'前提'!$B$23))+IF((B10+B14)<=50,'前提'!$B$24,IF((B10+B14)<=200,'前提'!$B$25,'前提'!$B$26)) | C28: =IF((C10+C14)<=50,'前提'!$B$21,IF((C10+C14)<=200,'前提'!$B$22,'前提'!$B$23))+IF((C10+C14)<=50,'前提'!$B$24,IF((C10+C14)<=200,'前提'!$B$25,'前提'!$B$26)) | D28: =IF((D10+D14)<=50,'前提'!$B$21,IF((D10+D14)<=200,'前提'!$B$22,'前提'!$B$23))+IF((D10+D14)<=50,'前提'!$B$24,IF((D10+D14)<=200,'前提'!$B$25,'前提'!$B$26)) | E28: =IF((E10+E14)<=50,'前提'!$B$21,IF((E10+E14)<=200,'前提'!$B$22,'前提'!$B$23))+IF((E10+E14)<=50,'前提'!$B$24,IF((E10+E14)<=200,'前提'!$B$25,'前提'!$B$26)) | F28: =IF((F10+F14)<=50,'前提'!$B$21,IF((F10+F14)<=200,'前提'!$B$22,'前提'!$B$23))+IF((F10+F14)<=50,'前提'!$B$24,IF((F10+F14)<=200,'前提'!$B$25,'前提'!$B$26)) | G28: =IF((G10+G14)<=50,'前提'!$B$21,IF((G10+G14)<=200,'前提'!$B$22,'前提'!$B$23))+IF((G10+G14)<=50,'前提'!$B$24,IF((G10+G14)<=200,'前提'!$B$25,'前提'!$B$26)) | H28: =IF((H10+H14)<=50,'前提'!$B$21,IF((H10+H14)<=200,'前提'!$B$22,'前提'!$B$23))+IF((H10+H14)<=50,'前提'!$B$24,IF((H10+H14)<=200,'前提'!$B$25,'前提'!$B$26)) | I28: =IF((I10+I14)<=50,'前提'!$B$21,IF((I10+I14)<=200,'前提'!$B$22,'前提'!$B$23))+IF((I10+I14)<=50,'前提'!$B$24,IF((I10+I14)<=200,'前提'!$B$25,'前提'!$B$26)) | ... BI28: =IF((BI10+BI14)<=50,'前提'!$B$21,IF((BI10+BI14)<=200,'前提'!$B$22,'前提'!$B$23))+IF((BI10+BI14)<=50,'前提'!$B$24,IF((BI10+BI14)<=200,'前提'!$B$25,'前提'!$B$26))
A29: 決済手数料 | B29: =B22*'前提'!$B$54 | C29: =C22*'前提'!$B$54 | D29: =D22*'前提'!$B$54 | E29: =E22*'前提'!$B$54 | F29: =F22*'前提'!$B$54 | G29: =G22*'前提'!$B$54 | H29: =H22*'前提'!$B$54 | I29: =I22*'前提'!$B$54 | ... BI29: =BI22*'前提'!$B$54
A31: 【人件費】
A32: CEO報酬 | B32: ='前提'!$B$34 | C32: ='前提'!$B$34 | D32: ='前提'!$B$34 | E32: ='前提'!$B$34 | F32: ='前提'!$B$34 | G32: ='前提'!$B$34 | H32: ='前提'!$B$34 | I32: ='前提'!$B$34 | ... BI32: ='前提'!$B$34
A33: エンジニア | B33: =IF(1<=6,'前提'!$B$35*'前提'!$B$36,IF(1<=12,'前提'!$B$35*'前提'!$B$37,'前提'!$B$38*(IF(1<=6,'前提'!$B$85,IF(1<=12,'前提'!$B$86,IF(1<=18,'前提'!$B$87,IF(1<=24,'前提'!$B$88,IF(1<=36,'前提'!$B$89,IF(1<=48,'前提'!$B$90,'前提'!$B$91))))))))) | C33: =IF(2<=6,'前提'!$B$35*'前提'!$B$36,IF(2<=12,'前提'!$B$35*'前提'!$B$37,'前提'!$B$38*(IF(2<=6,'前提'!$B$85,IF(2<=12,'前提'!$B$86,IF(2<=18,'前提'!$B$87,IF(2<=24,'前提'!$B$88,IF(2<=36,'前提'!$B$89,IF(2<=48,'前提'!$B$90,'前提'!$B$91))))))))) | D33: =IF(3<=6,'前提'!$B$35*'前提'!$B$36,IF(3<=12,'前提'!$B$35*'前提'!$B$37,'前提'!$B$38*(IF(3<=6,'前提'!$B$85,IF(3<=12,'前提'!$B$86,IF(3<=18,'前提'!$B$87,IF(3<=24,'前提'!$B$88,IF(3<=36,'前提'!$B$89,IF(3<=48,'前提'!$B$90,'前提'!$B$91))))))))) | E33: =IF(4<=6,'前提'!$B$35*'前提'!$B$36,IF(4<=12,'前提'!$B$35*'前提'!$B$37,'前提'!$B$38*(IF(4<=6,'前提'!$B$85,IF(4<=12,'前提'!$B$86,IF(4<=18,'前提'!$B$87,IF(4<=24,'前提'!$B$88,IF(4<=36,'前提'!$B$89,IF(4<=48,'前提'!$B$90,'前提'!$B$91))))))))) | F33: =IF(5<=6,'前提'!$B$35*'前提'!$B$36,IF(5<=12,'前提'!$B$35*'前提'!$B$37,'前提'!$B$38*(IF(5<=6,'前提'!$B$85,IF(5<=12,'前提'!$B$86,IF(5<=18,'前提'!$B$87,IF(5<=24,'前提'!$B$88,IF(5<=36,'前提'!$B$89,IF(5<=48,'前提'!$B$90,'前提'!$B$91))))))))) | G33: =IF(6<=6,'前提'!$B$35*'前提'!$B$36,IF(6<=12,'前提'!$B$35*'前提'!$B$37,'前提'!$B$38*(IF(6<=6,'前提'!$B$85,IF(6<=12,'前提'!$B$86,IF(6<=18,'前提'!$B$87,IF(6<=24,'前提'!$B$88,IF(6<=36,'前提'!$B$89,IF(6<=48,'前提'!$B$90,'前提'!$B$91))))))))) | H33: =IF(7<=6,'前提'!$B$35*'前提'!$B$36,IF(7<=12,'前提'!$B$35*'前提'!$B$37,'前提'!$B$38*(IF(7<=6,'前提'!$B$85,IF(7<=12,'前提'!$B$86,IF(7<=18,'前提'!$B$87,IF(7<=24,'前提'!$B$88,IF(7<=36,'前提'!$B$89,IF(7<=48,'前提'!$B$90,'前提'!$B$91))))))))) | I33: =IF(8<=6,'前提'!$B$35*'前提'!$B$36,IF(8<=12,'前提'!$B$35*'前提'!$B$37,'前提'!$B$38*(IF(8<=6,'前提'!$B$85,IF(8<=12,'前提'!$B$86,IF(8<=18,'前提'!$B$87,IF(8<=24,'前提'!$B$88,IF(8<=36,'前提'!$B$89,IF(8<=48,'前提'!$B$90,'前提'!$B$91))))))))) | J33: =IF(9<=6,'前提'!$B$35*'前提'!$B$36,IF(9<=12,'前提'!$B$35*'前提'!$B$37,'前提'!$B$38*(IF(9<=6,'前提'!$B$85,IF(9<=12,'前提'!$B$86,IF(9<=18,'前提'!$B$87,IF(9<=24,'前提'!$B$88,IF(9<=36,'前提'!$B$89,IF(9<=48,'前提'!$B$90,'前提'!$B$91))))))))) | K33: =IF(10<=6,'前提'!$B$35*'前提'!$B$36,IF(10<=12,'前提'!$B$35*'前提'!$B$37,'前提'!$B$38*(IF(10<=6,'前提'!$B$85,IF(10<=12,'前提'!$B$86,IF(10<=18,'前提'!$B$87,IF(10<=24,'前提'!$B$88,IF(10<=36,'前提'!$B$89,IF(10<=48,'前提'!$B$90,'前提'!$B$91))))))))) | L33: =IF(11<=6,'前提'!$B$35*'前提'!$B$36,IF(11<=12,'前提'!$B$35*'前提'!$B$37,'前提'!$B$38*(IF(11<=6,'前提'!$B$85,IF(11<=12,'前提'!$B$86,IF(11<=18,'前提'!$B$87,IF(11<=24,'前提'!$B$88,IF(11<=36,'前提'!$B$89,IF(11<=48,'前提'!$B$90,'前提'!$B$91))))))))) | M33: =IF(12<=6,'前提'!$B$35*'前提'!$B$36,IF(12<=12,'前提'!$B$35*'前提'!$B$37,'前提'!$B$38*(IF(12<=6,'前提'!$B$85,IF(12<=12,'前提'!$B$86,IF(12<=18,'前提'!$B$87,IF(12<=24,'前提'!$B$88,IF(12<=36,'前提'!$B$89,IF(12<=48,'前提'!$B$90,'前提'!$B$91))))))))) | N33: =IF(13<=6,'前提'!$B$35*'前提'!$B$36,IF(13<=12,'前提'!$B$35*'前提'!$B$37,'前提'!$B$38*(IF(13<=6,'前提'!$B$85,IF(13<=12,'前提'!$B$86,IF(13<=18,'前提'!$B$87,IF(13<=24,'前提'!$B$88,IF(13<=36,'前提'!$B$89,IF(13<=48,'前提'!$B$90,'前提'!$B$91))))))))) | O33: =IF(14<=6,'前提'!$B$35*'前提'!$B$36,IF(14<=12,'前提'!$B$35*'前提'!$B$37,'前提'!$B$38*(IF(14<=6,'前提'!$B$85,IF(14<=12,'前提'!$B$86,IF(14<=18,'前提'!$B$87,IF(14<=24,'前提'!$B$88,IF(14<=36,'前提'!$B$89,IF(14<=48,'前提'!$B$90,'前提'!$B$91))))))))) | P33: =IF(15<=6,'前提'!$B$35*'前提'!$B$36,IF(15<=12,'前提'!$B$35*'前提'!$B$37,'前提'!$B$38*(IF(15<=6,'前提'!$B$85,IF(15<=12,'前提'!$B$86,IF(15<=18,'前提'!$B$87,IF(15<=24,'前提'!$B$88,IF(15<=36,'前提'!$B$89,IF(15<=48,'前提'!$B$90,'前提'!$B$91))))))))) | Q33: =IF(16<=6,'前提'!$B$35*'前提'!$B$36,IF(16<=12,'前提'!$B$35*'前提'!$B$37,'前提'!$B$38*(IF(16<=6,'前提'!$B$85,IF(16<=12,'前提'!$B$86,IF(16<=18,'前提'!$B$87,IF(16<=24,'前提'!$B$88,IF(16<=36,'前提'!$B$89,IF(16<=48,'前提'!$B$90,'前提'!$B$91))))))))) | R33: =IF(17<=6,'前提'!$B$35*'前提'!$B$36,IF(17<=12,'前提'!$B$35*'前提'!$B$37,'前提'!$B$38*(IF(17<=6,'前提'!$B$85,IF(17<=12,'前提'!$B$86,IF(17<=18,'前提'!$B$87,IF(17<=24,'前提'!$B$88,IF(17<=36,'前提'!$B$89,IF(17<=48,'前提'!$B$90,'前提'!$B$91))))))))) | S33: =IF(18<=6,'前提'!$B$35*'前提'!$B$36,IF(18<=12,'前提'!$B$35*'前提'!$B$37,'前提'!$B$38*(IF(18<=6,'前提'!$B$85,IF(18<=12,'前提'!$B$86,IF(18<=18,'前提'!$B$87,IF(18<=24,'前提'!$B$88,IF(18<=36,'前提'!$B$89,IF(18<=48,'前提'!$B$90,'前提'!$B$91))))))))) | T33: =IF(19<=6,'前提'!$B$35*'前提'!$B$36,IF(19<=12,'前提'!$B$35*'前提'!$B$37,'前提'!$B$38*(IF(19<=6,'前提'!$B$85,IF(19<=12,'前提'!$B$86,IF(19<=18,'前提'!$B$87,IF(19<=24,'前提'!$B$88,IF(19<=36,'前提'!$B$89,IF(19<=48,'前提'!$B$90,'前提'!$B$91))))))))) | U33: =IF(20<=6,'前提'!$B$35*'前提'!$B$36,IF(20<=12,'前提'!$B$35*'前提'!$B$37,'前提'!$B$38*(IF(20<=6,'前提'!$B$85,IF(20<=12,'前提'!$B$86,IF(20<=18,'前提'!$B$87,IF(20<=24,'前提'!$B$88,IF(20<=36,'前提'!$B$89,IF(20<=48,'前提'!$B$90,'前提'!$B$91))))))))) | V33: =IF(21<=6,'前提'!$B$35*'前提'!$B$36,IF(21<=12,'前提'!$B$35*'前提'!$B$37,'前提'!$B$38*(IF(21<=6,'前提'!$B$85,IF(21<=12,'前提'!$B$86,IF(21<=18,'前提'!$B$87,IF(21<=24,'前提'!$B$88,IF(21<=36,'前提'!$B$89,IF(21<=48,'前提'!$B$90,'前提'!$B$91))))))))) | W33: =IF(22<=6,'前提'!$B$35*'前提'!$B$36,IF(22<=12,'前提'!$B$35*'前提'!$B$37,'前提'!$B$38*(IF(22<=6,'前提'!$B$85,IF(22<=12,'前提'!$B$86,IF(22<=18,'前提'!$B$87,IF(22<=24,'前提'!$B$88,IF(22<=36,'前提'!$B$89,IF(22<=48,'前提'!$B$90,'前提'!$B$91))))))))) | X33: =IF(23<=6,'前提'!$B$35*'前提'!$B$36,IF(23<=12,'前提'!$B$35*'前提'!$B$37,'前提'!$B$38*(IF(23<=6,'前提'!$B$85,IF(23<=12,'前提'!$B$86,IF(23<=18,'前提'!$B$87,IF(23<=24,'前提'!$B$88,IF(23<=36,'前提'!$B$89,IF(23<=48,'前提'!$B$90,'前提'!$B$91))))))))) | Y33: =IF(24<=6,'前提'!$B$35*'前提'!$B$36,IF(24<=12,'前提'!$B$35*'前提'!$B$37,'前提'!$B$38*(IF(24<=6,'前提'!$B$85,IF(24<=12,'前提'!$B$86,IF(24<=18,'前提'!$B$87,IF(24<=24,'前提'!$B$88,IF(24<=36,'前提'!$B$89,IF(24<=48,'前提'!$B$90,'前提'!$B$91))))))))) | Z33: =IF(25<=6,'前提'!$B$35*'前提'!$B$36,IF(25<=12,'前提'!$B$35*'前提'!$B$37,'前提'!$B$38*(IF(25<=6,'前提'!$B$85,IF(25<=12,'前提'!$B$86,IF(25<=18,'前提'!$B$87,IF(25<=24,'前提'!$B$88,IF(25<=36,'前提'!$B$89,IF(25<=48,'前提'!$B$90,'前提'!$B$91))))))))) | AA33: =IF(26<=6,'前提'!$B$35*'前提'!$B$36,IF(26<=12,'前提'!$B$35*'前提'!$B$37,'前提'!$B$38*(IF(26<=6,'前提'!$B$85,IF(26<=12,'前提'!$B$86,IF(26<=18,'前提'!$B$87,IF(26<=24,'前提'!$B$88,IF(26<=36,'前提'!$B$89,IF(26<=48,'前提'!$B$90,'前提'!$B$91))))))))) | AB33: =IF(27<=6,'前提'!$B$35*'前提'!$B$36,IF(27<=12,'前提'!$B$35*'前提'!$B$37,'前提'!$B$38*(IF(27<=6,'前提'!$B$85,IF(27<=12,'前提'!$B$86,IF(27<=18,'前提'!$B$87,IF(27<=24,'前提'!$B$88,IF(27<=36,'前提'!$B$89,IF(27<=48,'前提'!$B$90,'前提'!$B$91))))))))) | AC33: =IF(28<=6,'前提'!$B$35*'前提'!$B$36,IF(28<=12,'前提'!$B$35*'前提'!$B$37,'前提'!$B$38*(IF(28<=6,'前提'!$B$85,IF(28<=12,'前提'!$B$86,IF(28<=18,'前提'!$B$87,IF(28<=24,'前提'!$B$88,IF(28<=36,'前提'!$B$89,IF(28<=48,'前提'!$B$90,'前提'!$B$91))))))))) | AD33: =IF(29<=6,'前提'!$B$35*'前提'!$B$36,IF(29<=12,'前提'!$B$35*'前提'!$B$37,'前提'!$B$38*(IF(29<=6,'前提'!$B$85,IF(29<=12,'前提'!$B$86,IF(29<=18,'前提'!$B$87,IF(29<=24,'前提'!$B$88,IF(29<=36,'前提'!$B$89,IF(29<=48,'前提'!$B$90,'前提'!$B$91))))))))) | AE33: =IF(30<=6,'前提'!$B$35*'前提'!$B$36,IF(30<=12,'前提'!$B$35*'前提'!$B$37,'前提'!$B$38*(IF(30<=6,'前提'!$B$85,IF(30<=12,'前提'!$B$86,IF(30<=18,'前提'!$B$87,IF(30<=24,'前提'!$B$88,IF(30<=36,'前提'!$B$89,IF(30<=48,'前提'!$B$90,'前提'!$B$91))))))))) | AF33: =IF(31<=6,'前提'!$B$35*'前提'!$B$36,IF(31<=12,'前提'!$B$35*'前提'!$B$37,'前提'!$B$38*(IF(31<=6,'前提'!$B$85,IF(31<=12,'前提'!$B$86,IF(31<=18,'前提'!$B$87,IF(31<=24,'前提'!$B$88,IF(31<=36,'前提'!$B$89,IF(31<=48,'前提'!$B$90,'前提'!$B$91))))))))) | AG33: =IF(32<=6,'前提'!$B$35*'前提'!$B$36,IF(32<=12,'前提'!$B$35*'前提'!$B$37,'前提'!$B$38*(IF(32<=6,'前提'!$B$85,IF(32<=12,'前提'!$B$86,IF(32<=18,'前提'!$B$87,IF(32<=24,'前提'!$B$88,IF(32<=36,'前提'!$B$89,IF(32<=48,'前提'!$B$90,'前提'!$B$91))))))))) | AH33: =IF(33<=6,'前提'!$B$35*'前提'!$B$36,IF(33<=12,'前提'!$B$35*'前提'!$B$37,'前提'!$B$38*(IF(33<=6,'前提'!$B$85,IF(33<=12,'前提'!$B$86,IF(33<=18,'前提'!$B$87,IF(33<=24,'前提'!$B$88,IF(33<=36,'前提'!$B$89,IF(33<=48,'前提'!$B$90,'前提'!$B$91))))))))) | AI33: =IF(34<=6,'前提'!$B$35*'前提'!$B$36,IF(34<=12,'前提'!$B$35*'前提'!$B$37,'前提'!$B$38*(IF(34<=6,'前提'!$B$85,IF(34<=12,'前提'!$B$86,IF(34<=18,'前提'!$B$87,IF(34<=24,'前提'!$B$88,IF(34<=36,'前提'!$B$89,IF(34<=48,'前提'!$B$90,'前提'!$B$91))))))))) | AJ33: =IF(35<=6,'前提'!$B$35*'前提'!$B$36,IF(35<=12,'前提'!$B$35*'前提'!$B$37,'前提'!$B$38*(IF(35<=6,'前提'!$B$85,IF(35<=12,'前提'!$B$86,IF(35<=18,'前提'!$B$87,IF(35<=24,'前提'!$B$88,IF(35<=36,'前提'!$B$89,IF(35<=48,'前提'!$B$90,'前提'!$B$91))))))))) | AK33: =IF(36<=6,'前提'!$B$35*'前提'!$B$36,IF(36<=12,'前提'!$B$35*'前提'!$B$37,'前提'!$B$38*(IF(36<=6,'前提'!$B$85,IF(36<=12,'前提'!$B$86,IF(36<=18,'前提'!$B$87,IF(36<=24,'前提'!$B$88,IF(36<=36,'前提'!$B$89,IF(36<=48,'前提'!$B$90,'前提'!$B$91))))))))) | AL33: =IF(37<=6,'前提'!$B$35*'前提'!$B$36,IF(37<=12,'前提'!$B$35*'前提'!$B$37,'前提'!$B$38*(IF(37<=6,'前提'!$B$85,IF(37<=12,'前提'!$B$86,IF(37<=18,'前提'!$B$87,IF(37<=24,'前提'!$B$88,IF(37<=36,'前提'!$B$89,IF(37<=48,'前提'!$B$90,'前提'!$B$91))))))))) | AM33: =IF(38<=6,'前提'!$B$35*'前提'!$B$36,IF(38<=12,'前提'!$B$35*'前提'!$B$37,'前提'!$B$38*(IF(38<=6,'前提'!$B$85,IF(38<=12,'前提'!$B$86,IF(38<=18,'前提'!$B$87,IF(38<=24,'前提'!$B$88,IF(38<=36,'前提'!$B$89,IF(38<=48,'前提'!$B$90,'前提'!$B$91))))))))) | AN33: =IF(39<=6,'前提'!$B$35*'前提'!$B$36,IF(39<=12,'前提'!$B$35*'前提'!$B$37,'前提'!$B$38*(IF(39<=6,'前提'!$B$85,IF(39<=12,'前提'!$B$86,IF(39<=18,'前提'!$B$87,IF(39<=24,'前提'!$B$88,IF(39<=36,'前提'!$B$89,IF(39<=48,'前提'!$B$90,'前提'!$B$91))))))))) | AO33: =IF(40<=6,'前提'!$B$35*'前提'!$B$36,IF(40<=12,'前提'!$B$35*'前提'!$B$37,'前提'!$B$38*(IF(40<=6,'前提'!$B$85,IF(40<=12,'前提'!$B$86,IF(40<=18,'前提'!$B$87,IF(40<=24,'前提'!$B$88,IF(40<=36,'前提'!$B$89,IF(40<=48,'前提'!$B$90,'前提'!$B$91))))))))) | AP33: =IF(41<=6,'前提'!$B$35*'前提'!$B$36,IF(41<=12,'前提'!$B$35*'前提'!$B$37,'前提'!$B$38*(IF(41<=6,'前提'!$B$85,IF(41<=12,'前提'!$B$86,IF(41<=18,'前提'!$B$87,IF(41<=24,'前提'!$B$88,IF(41<=36,'前提'!$B$89,IF(41<=48,'前提'!$B$90,'前提'!$B$91))))))))) | AQ33: =IF(42<=6,'前提'!$B$35*'前提'!$B$36,IF(42<=12,'前提'!$B$35*'前提'!$B$37,'前提'!$B$38*(IF(42<=6,'前提'!$B$85,IF(42<=12,'前提'!$B$86,IF(42<=18,'前提'!$B$87,IF(42<=24,'前提'!$B$88,IF(42<=36,'前提'!$B$89,IF(42<=48,'前提'!$B$90,'前提'!$B$91))))))))) | AR33: =IF(43<=6,'前提'!$B$35*'前提'!$B$36,IF(43<=12,'前提'!$B$35*'前提'!$B$37,'前提'!$B$38*(IF(43<=6,'前提'!$B$85,IF(43<=12,'前提'!$B$86,IF(43<=18,'前提'!$B$87,IF(43<=24,'前提'!$B$88,IF(43<=36,'前提'!$B$89,IF(43<=48,'前提'!$B$90,'前提'!$B$91))))))))) | AS33: =IF(44<=6,'前提'!$B$35*'前提'!$B$36,IF(44<=12,'前提'!$B$35*'前提'!$B$37,'前提'!$B$38*(IF(44<=6,'前提'!$B$85,IF(44<=12,'前提'!$B$86,IF(44<=18,'前提'!$B$87,IF(44<=24,'前提'!$B$88,IF(44<=36,'前提'!$B$89,IF(44<=48,'前提'!$B$90,'前提'!$B$91))))))))) | AT33: =IF(45<=6,'前提'!$B$35*'前提'!$B$36,IF(45<=12,'前提'!$B$35*'前提'!$B$37,'前提'!$B$38*(IF(45<=6,'前提'!$B$85,IF(45<=12,'前提'!$B$86,IF(45<=18,'前提'!$B$87,IF(45<=24,'前提'!$B$88,IF(45<=36,'前提'!$B$89,IF(45<=48,'前提'!$B$90,'前提'!$B$91))))))))) | AU33: =IF(46<=6,'前提'!$B$35*'前提'!$B$36,IF(46<=12,'前提'!$B$35*'前提'!$B$37,'前提'!$B$38*(IF(46<=6,'前提'!$B$85,IF(46<=12,'前提'!$B$86,IF(46<=18,'前提'!$B$87,IF(46<=24,'前提'!$B$88,IF(46<=36,'前提'!$B$89,IF(46<=48,'前提'!$B$90,'前提'!$B$91))))))))) | AV33: =IF(47<=6,'前提'!$B$35*'前提'!$B$36,IF(47<=12,'前提'!$B$35*'前提'!$B$37,'前提'!$B$38*(IF(47<=6,'前提'!$B$85,IF(47<=12,'前提'!$B$86,IF(47<=18,'前提'!$B$87,IF(47<=24,'前提'!$B$88,IF(47<=36,'前提'!$B$89,IF(47<=48,'前提'!$B$90,'前提'!$B$91))))))))) | AW33: =IF(48<=6,'前提'!$B$35*'前提'!$B$36,IF(48<=12,'前提'!$B$35*'前提'!$B$37,'前提'!$B$38*(IF(48<=6,'前提'!$B$85,IF(48<=12,'前提'!$B$86,IF(48<=18,'前提'!$B$87,IF(48<=24,'前提'!$B$88,IF(48<=36,'前提'!$B$89,IF(48<=48,'前提'!$B$90,'前提'!$B$91))))))))) | AX33: =IF(49<=6,'前提'!$B$35*'前提'!$B$36,IF(49<=12,'前提'!$B$35*'前提'!$B$37,'前提'!$B$38*(IF(49<=6,'前提'!$B$85,IF(49<=12,'前提'!$B$86,IF(49<=18,'前提'!$B$87,IF(49<=24,'前提'!$B$88,IF(49<=36,'前提'!$B$89,IF(49<=48,'前提'!$B$90,'前提'!$B$91))))))))) | AY33: =IF(50<=6,'前提'!$B$35*'前提'!$B$36,IF(50<=12,'前提'!$B$35*'前提'!$B$37,'前提'!$B$38*(IF(50<=6,'前提'!$B$85,IF(50<=12,'前提'!$B$86,IF(50<=18,'前提'!$B$87,IF(50<=24,'前提'!$B$88,IF(50<=36,'前提'!$B$89,IF(50<=48,'前提'!$B$90,'前提'!$B$91))))))))) | AZ33: =IF(51<=6,'前提'!$B$35*'前提'!$B$36,IF(51<=12,'前提'!$B$35*'前提'!$B$37,'前提'!$B$38*(IF(51<=6,'前提'!$B$85,IF(51<=12,'前提'!$B$86,IF(51<=18,'前提'!$B$87,IF(51<=24,'前提'!$B$88,IF(51<=36,'前提'!$B$89,IF(51<=48,'前提'!$B$90,'前提'!$B$91))))))))) | BA33: =IF(52<=6,'前提'!$B$35*'前提'!$B$36,IF(52<=12,'前提'!$B$35*'前提'!$B$37,'前提'!$B$38*(IF(52<=6,'前提'!$B$85,IF(52<=12,'前提'!$B$86,IF(52<=18,'前提'!$B$87,IF(52<=24,'前提'!$B$88,IF(52<=36,'前提'!$B$89,IF(52<=48,'前提'!$B$90,'前提'!$B$91))))))))) | BB33: =IF(53<=6,'前提'!$B$35*'前提'!$B$36,IF(53<=12,'前提'!$B$35*'前提'!$B$37,'前提'!$B$38*(IF(53<=6,'前提'!$B$85,IF(53<=12,'前提'!$B$86,IF(53<=18,'前提'!$B$87,IF(53<=24,'前提'!$B$88,IF(53<=36,'前提'!$B$89,IF(53<=48,'前提'!$B$90,'前提'!$B$91))))))))) | BC33: =IF(54<=6,'前提'!$B$35*'前提'!$B$36,IF(54<=12,'前提'!$B$35*'前提'!$B$37,'前提'!$B$38*(IF(54<=6,'前提'!$B$85,IF(54<=12,'前提'!$B$86,IF(54<=18,'前提'!$B$87,IF(54<=24,'前提'!$B$88,IF(54<=36,'前提'!$B$89,IF(54<=48,'前提'!$B$90,'前提'!$B$91))))))))) | BD33: =IF(55<=6,'前提'!$B$35*'前提'!$B$36,IF(55<=12,'前提'!$B$35*'前提'!$B$37,'前提'!$B$38*(IF(55<=6,'前提'!$B$85,IF(55<=12,'前提'!$B$86,IF(55<=18,'前提'!$B$87,IF(55<=24,'前提'!$B$88,IF(55<=36,'前提'!$B$89,IF(55<=48,'前提'!$B$90,'前提'!$B$91))))))))) | BE33: =IF(56<=6,'前提'!$B$35*'前提'!$B$36,IF(56<=12,'前提'!$B$35*'前提'!$B$37,'前提'!$B$38*(IF(56<=6,'前提'!$B$85,IF(56<=12,'前提'!$B$86,IF(56<=18,'前提'!$B$87,IF(56<=24,'前提'!$B$88,IF(56<=36,'前提'!$B$89,IF(56<=48,'前提'!$B$90,'前提'!$B$91))))))))) | BF33: =IF(57<=6,'前提'!$B$35*'前提'!$B$36,IF(57<=12,'前提'!$B$35*'前提'!$B$37,'前提'!$B$38*(IF(57<=6,'前提'!$B$85,IF(57<=12,'前提'!$B$86,IF(57<=18,'前提'!$B$87,IF(57<=24,'前提'!$B$88,IF(57<=36,'前提'!$B$89,IF(57<=48,'前提'!$B$90,'前提'!$B$91))))))))) | BG33: =IF(58<=6,'前提'!$B$35*'前提'!$B$36,IF(58<=12,'前提'!$B$35*'前提'!$B$37,'前提'!$B$38*(IF(58<=6,'前提'!$B$85,IF(58<=12,'前提'!$B$86,IF(58<=18,'前提'!$B$87,IF(58<=24,'前提'!$B$88,IF(58<=36,'前提'!$B$89,IF(58<=48,'前提'!$B$90,'前提'!$B$91))))))))) | BH33: =IF(59<=6,'前提'!$B$35*'前提'!$B$36,IF(59<=12,'前提'!$B$35*'前提'!$B$37,'前提'!$B$38*(IF(59<=6,'前提'!$B$85,IF(59<=12,'前提'!$B$86,IF(59<=18,'前提'!$B$87,IF(59<=24,'前提'!$B$88,IF(59<=36,'前提'!$B$89,IF(59<=48,'前提'!$B$90,'前提'!$B$91))))))))) | BI33: =IF(60<=6,'前提'!$B$35*'前提'!$B$36,IF(60<=12,'前提'!$B$35*'前提'!$B$37,'前提'!$B$38*(IF(60<=6,'前提'!$B$85,IF(60<=12,'前提'!$B$86,IF(60<=18,'前提'!$B$87,IF(60<=24,'前提'!$B$88,IF(60<=36,'前提'!$B$89,IF(60<=48,'前提'!$B$90,'前提'!$B$91)))))))))
A34: 営業サポート | B34: ='前提'!$B$41*(IF(1<=6,'前提'!$B$94,IF(1<=12,'前提'!$B$95,IF(1<=18,'前提'!$B$96,IF(1<=24,'前提'!$B$97,IF(1<=36,'前提'!$B$98,IF(1<=48,'前提'!$B$99,'前提'!$B$100))))))) | C34: ='前提'!$B$41*(IF(2<=6,'前提'!$B$94,IF(2<=12,'前提'!$B$95,IF(2<=18,'前提'!$B$96,IF(2<=24,'前提'!$B$97,IF(2<=36,'前提'!$B$98,IF(2<=48,'前提'!$B$99,'前提'!$B$100))))))) | D34: ='前提'!$B$41*(IF(3<=6,'前提'!$B$94,IF(3<=12,'前提'!$B$95,IF(3<=18,'前提'!$B$96,IF(3<=24,'前提'!$B$97,IF(3<=36,'前提'!$B$98,IF(3<=48,'前提'!$B$99,'前提'!$B$100))))))) | E34: ='前提'!$B$41*(IF(4<=6,'前提'!$B$94,IF(4<=12,'前提'!$B$95,IF(4<=18,'前提'!$B$96,IF(4<=24,'前提'!$B$97,IF(4<=36,'前提'!$B$98,IF(4<=48,'前提'!$B$99,'前提'!$B$100))))))) | F34: ='前提'!$B$41*(IF(5<=6,'前提'!$B$94,IF(5<=12,'前提'!$B$95,IF(5<=18,'前提'!$B$96,IF(5<=24,'前提'!$B$97,IF(5<=36,'前提'!$B$98,IF(5<=48,'前提'!$B$99,'前提'!$B$100))))))) | G34: ='前提'!$B$41*(IF(6<=6,'前提'!$B$94,IF(6<=12,'前提'!$B$95,IF(6<=18,'前提'!$B$96,IF(6<=24,'前提'!$B$97,IF(6<=36,'前提'!$B$98,IF(6<=48,'前提'!$B$99,'前提'!$B$100))))))) | H34: ='前提'!$B$41*(IF(7<=6,'前提'!$B$94,IF(7<=12,'前提'!$B$95,IF(7<=18,'前提'!$B$96,IF(7<=24,'前提'!$B$97,IF(7<=36,'前提'!$B$98,IF(7<=48,'前提'!$B$99,'前提'!$B$100))))))) | I34: ='前提'!$B$41*(IF(8<=6,'前提'!$B$94,IF(8<=12,'前提'!$B$95,IF(8<=18,'前提'!$B$96,IF(8<=24,'前提'!$B$97,IF(8<=36,'前提'!$B$98,IF(8<=48,'前提'!$B$99,'前提'!$B$100))))))) | J34: ='前提'!$B$41*(IF(9<=6,'前提'!$B$94,IF(9<=12,'前提'!$B$95,IF(9<=18,'前提'!$B$96,IF(9<=24,'前提'!$B$97,IF(9<=36,'前提'!$B$98,IF(9<=48,'前提'!$B$99,'前提'!$B$100))))))) | K34: ='前提'!$B$41*(IF(10<=6,'前提'!$B$94,IF(10<=12,'前提'!$B$95,IF(10<=18,'前提'!$B$96,IF(10<=24,'前提'!$B$97,IF(10<=36,'前提'!$B$98,IF(10<=48,'前提'!$B$99,'前提'!$B$100))))))) | L34: ='前提'!$B$41*(IF(11<=6,'前提'!$B$94,IF(11<=12,'前提'!$B$95,IF(11<=18,'前提'!$B$96,IF(11<=24,'前提'!$B$97,IF(11<=36,'前提'!$B$98,IF(11<=48,'前提'!$B$99,'前提'!$B$100))))))) | M34: ='前提'!$B$41*(IF(12<=6,'前提'!$B$94,IF(12<=12,'前提'!$B$95,IF(12<=18,'前提'!$B$96,IF(12<=24,'前提'!$B$97,IF(12<=36,'前提'!$B$98,IF(12<=48,'前提'!$B$99,'前提'!$B$100))))))) | N34: ='前提'!$B$41*(IF(13<=6,'前提'!$B$94,IF(13<=12,'前提'!$B$95,IF(13<=18,'前提'!$B$96,IF(13<=24,'前提'!$B$97,IF(13<=36,'前提'!$B$98,IF(13<=48,'前提'!$B$99,'前提'!$B$100))))))) | O34: ='前提'!$B$41*(IF(14<=6,'前提'!$B$94,IF(14<=12,'前提'!$B$95,IF(14<=18,'前提'!$B$96,IF(14<=24,'前提'!$B$97,IF(14<=36,'前提'!$B$98,IF(14<=48,'前提'!$B$99,'前提'!$B$100))))))) | P34: ='前提'!$B$41*(IF(15<=6,'前提'!$B$94,IF(15<=12,'前提'!$B$95,IF(15<=18,'前提'!$B$96,IF(15<=24,'前提'!$B$97,IF(15<=36,'前提'!$B$98,IF(15<=48,'前提'!$B$99,'前提'!$B$100))))))) | Q34: ='前提'!$B$41*(IF(16<=6,'前提'!$B$94,IF(16<=12,'前提'!$B$95,IF(16<=18,'前提'!$B$96,IF(16<=24,'前提'!$B$97,IF(16<=36,'前提'!$B$98,IF(16<=48,'前提'!$B$99,'前提'!$B$100))))))) | R34: ='前提'!$B$41*(IF(17<=6,'前提'!$B$94,IF(17<=12,'前提'!$B$95,IF(17<=18,'前提'!$B$96,IF(17<=24,'前提'!$B$97,IF(17<=36,'前提'!$B$98,IF(17<=48,'前提'!$B$99,'前提'!$B$100))))))) | S34: ='前提'!$B$41*(IF(18<=6,'前提'!$B$94,IF(18<=12,'前提'!$B$95,IF(18<=18,'前提'!$B$96,IF(18<=24,'前提'!$B$97,IF(18<=36,'前提'!$B$98,IF(18<=48,'前提'!$B$99,'前提'!$B$100))))))) | T34: ='前提'!$B$41*(IF(19<=6,'前提'!$B$94,IF(19<=12,'前提'!$B$95,IF(19<=18,'前提'!$B$96,IF(19<=24,'前提'!$B$97,IF(19<=36,'前提'!$B$98,IF(19<=48,'前提'!$B$99,'前提'!$B$100))))))) | U34: ='前提'!$B$41*(IF(20<=6,'前提'!$B$94,IF(20<=12,'前提'!$B$95,IF(20<=18,'前提'!$B$96,IF(20<=24,'前提'!$B$97,IF(20<=36,'前提'!$B$98,IF(20<=48,'前提'!$B$99,'前提'!$B$100))))))) | V34: ='前提'!$B$41*(IF(21<=6,'前提'!$B$94,IF(21<=12,'前提'!$B$95,IF(21<=18,'前提'!$B$96,IF(21<=24,'前提'!$B$97,IF(21<=36,'前提'!$B$98,IF(21<=48,'前提'!$B$99,'前提'!$B$100))))))) | W34: ='前提'!$B$41*(IF(22<=6,'前提'!$B$94,IF(22<=12,'前提'!$B$95,IF(22<=18,'前提'!$B$96,IF(22<=24,'前提'!$B$97,IF(22<=36,'前提'!$B$98,IF(22<=48,'前提'!$B$99,'前提'!$B$100))))))) | X34: ='前提'!$B$41*(IF(23<=6,'前提'!$B$94,IF(23<=12,'前提'!$B$95,IF(23<=18,'前提'!$B$96,IF(23<=24,'前提'!$B$97,IF(23<=36,'前提'!$B$98,IF(23<=48,'前提'!$B$99,'前提'!$B$100))))))) | Y34: ='前提'!$B$41*(IF(24<=6,'前提'!$B$94,IF(24<=12,'前提'!$B$95,IF(24<=18,'前提'!$B$96,IF(24<=24,'前提'!$B$97,IF(24<=36,'前提'!$B$98,IF(24<=48,'前提'!$B$99,'前提'!$B$100))))))) | Z34: ='前提'!$B$41*(IF(25<=6,'前提'!$B$94,IF(25<=12,'前提'!$B$95,IF(25<=18,'前提'!$B$96,IF(25<=24,'前提'!$B$97,IF(25<=36,'前提'!$B$98,IF(25<=48,'前提'!$B$99,'前提'!$B$100))))))) | AA34: ='前提'!$B$41*(IF(26<=6,'前提'!$B$94,IF(26<=12,'前提'!$B$95,IF(26<=18,'前提'!$B$96,IF(26<=24,'前提'!$B$97,IF(26<=36,'前提'!$B$98,IF(26<=48,'前提'!$B$99,'前提'!$B$100))))))) | AB34: ='前提'!$B$41*(IF(27<=6,'前提'!$B$94,IF(27<=12,'前提'!$B$95,IF(27<=18,'前提'!$B$96,IF(27<=24,'前提'!$B$97,IF(27<=36,'前提'!$B$98,IF(27<=48,'前提'!$B$99,'前提'!$B$100))))))) | AC34: ='前提'!$B$41*(IF(28<=6,'前提'!$B$94,IF(28<=12,'前提'!$B$95,IF(28<=18,'前提'!$B$96,IF(28<=24,'前提'!$B$97,IF(28<=36,'前提'!$B$98,IF(28<=48,'前提'!$B$99,'前提'!$B$100))))))) | AD34: ='前提'!$B$41*(IF(29<=6,'前提'!$B$94,IF(29<=12,'前提'!$B$95,IF(29<=18,'前提'!$B$96,IF(29<=24,'前提'!$B$97,IF(29<=36,'前提'!$B$98,IF(29<=48,'前提'!$B$99,'前提'!$B$100))))))) | AE34: ='前提'!$B$41*(IF(30<=6,'前提'!$B$94,IF(30<=12,'前提'!$B$95,IF(30<=18,'前提'!$B$96,IF(30<=24,'前提'!$B$97,IF(30<=36,'前提'!$B$98,IF(30<=48,'前提'!$B$99,'前提'!$B$100))))))) | AF34: ='前提'!$B$41*(IF(31<=6,'前提'!$B$94,IF(31<=12,'前提'!$B$95,IF(31<=18,'前提'!$B$96,IF(31<=24,'前提'!$B$97,IF(31<=36,'前提'!$B$98,IF(31<=48,'前提'!$B$99,'前提'!$B$100))))))) | AG34: ='前提'!$B$41*(IF(32<=6,'前提'!$B$94,IF(32<=12,'前提'!$B$95,IF(32<=18,'前提'!$B$96,IF(32<=24,'前提'!$B$97,IF(32<=36,'前提'!$B$98,IF(32<=48,'前提'!$B$99,'前提'!$B$100))))))) | AH34: ='前提'!$B$41*(IF(33<=6,'前提'!$B$94,IF(33<=12,'前提'!$B$95,IF(33<=18,'前提'!$B$96,IF(33<=24,'前提'!$B$97,IF(33<=36,'前提'!$B$98,IF(33<=48,'前提'!$B$99,'前提'!$B$100))))))) | AI34: ='前提'!$B$41*(IF(34<=6,'前提'!$B$94,IF(34<=12,'前提'!$B$95,IF(34<=18,'前提'!$B$96,IF(34<=24,'前提'!$B$97,IF(34<=36,'前提'!$B$98,IF(34<=48,'前提'!$B$99,'前提'!$B$100))))))) | AJ34: ='前提'!$B$41*(IF(35<=6,'前提'!$B$94,IF(35<=12,'前提'!$B$95,IF(35<=18,'前提'!$B$96,IF(35<=24,'前提'!$B$97,IF(35<=36,'前提'!$B$98,IF(35<=48,'前提'!$B$99,'前提'!$B$100))))))) | AK34: ='前提'!$B$41*(IF(36<=6,'前提'!$B$94,IF(36<=12,'前提'!$B$95,IF(36<=18,'前提'!$B$96,IF(36<=24,'前提'!$B$97,IF(36<=36,'前提'!$B$98,IF(36<=48,'前提'!$B$99,'前提'!$B$100))))))) | AL34: ='前提'!$B$41*(IF(37<=6,'前提'!$B$94,IF(37<=12,'前提'!$B$95,IF(37<=18,'前提'!$B$96,IF(37<=24,'前提'!$B$97,IF(37<=36,'前提'!$B$98,IF(37<=48,'前提'!$B$99,'前提'!$B$100))))))) | AM34: ='前提'!$B$41*(IF(38<=6,'前提'!$B$94,IF(38<=12,'前提'!$B$95,IF(38<=18,'前提'!$B$96,IF(38<=24,'前提'!$B$97,IF(38<=36,'前提'!$B$98,IF(38<=48,'前提'!$B$99,'前提'!$B$100))))))) | AN34: ='前提'!$B$41*(IF(39<=6,'前提'!$B$94,IF(39<=12,'前提'!$B$95,IF(39<=18,'前提'!$B$96,IF(39<=24,'前提'!$B$97,IF(39<=36,'前提'!$B$98,IF(39<=48,'前提'!$B$99,'前提'!$B$100))))))) | AO34: ='前提'!$B$41*(IF(40<=6,'前提'!$B$94,IF(40<=12,'前提'!$B$95,IF(40<=18,'前提'!$B$96,IF(40<=24,'前提'!$B$97,IF(40<=36,'前提'!$B$98,IF(40<=48,'前提'!$B$99,'前提'!$B$100))))))) | AP34: ='前提'!$B$41*(IF(41<=6,'前提'!$B$94,IF(41<=12,'前提'!$B$95,IF(41<=18,'前提'!$B$96,IF(41<=24,'前提'!$B$97,IF(41<=36,'前提'!$B$98,IF(41<=48,'前提'!$B$99,'前提'!$B$100))))))) | AQ34: ='前提'!$B$41*(IF(42<=6,'前提'!$B$94,IF(42<=12,'前提'!$B$95,IF(42<=18,'前提'!$B$96,IF(42<=24,'前提'!$B$97,IF(42<=36,'前提'!$B$98,IF(42<=48,'前提'!$B$99,'前提'!$B$100))))))) | AR34: ='前提'!$B$41*(IF(43<=6,'前提'!$B$94,IF(43<=12,'前提'!$B$95,IF(43<=18,'前提'!$B$96,IF(43<=24,'前提'!$B$97,IF(43<=36,'前提'!$B$98,IF(43<=48,'前提'!$B$99,'前提'!$B$100))))))) | AS34: ='前提'!$B$41*(IF(44<=6,'前提'!$B$94,IF(44<=12,'前提'!$B$95,IF(44<=18,'前提'!$B$96,IF(44<=24,'前提'!$B$97,IF(44<=36,'前提'!$B$98,IF(44<=48,'前提'!$B$99,'前提'!$B$100))))))) | AT34: ='前提'!$B$41*(IF(45<=6,'前提'!$B$94,IF(45<=12,'前提'!$B$95,IF(45<=18,'前提'!$B$96,IF(45<=24,'前提'!$B$97,IF(45<=36,'前提'!$B$98,IF(45<=48,'前提'!$B$99,'前提'!$B$100))))))) | AU34: ='前提'!$B$41*(IF(46<=6,'前提'!$B$94,IF(46<=12,'前提'!$B$95,IF(46<=18,'前提'!$B$96,IF(46<=24,'前提'!$B$97,IF(46<=36,'前提'!$B$98,IF(46<=48,'前提'!$B$99,'前提'!$B$100))))))) | AV34: ='前提'!$B$41*(IF(47<=6,'前提'!$B$94,IF(47<=12,'前提'!$B$95,IF(47<=18,'前提'!$B$96,IF(47<=24,'前提'!$B$97,IF(47<=36,'前提'!$B$98,IF(47<=48,'前提'!$B$99,'前提'!$B$100))))))) | AW34: ='前提'!$B$41*(IF(48<=6,'前提'!$B$94,IF(48<=12,'前提'!$B$95,IF(48<=18,'前提'!$B$96,IF(48<=24,'前提'!$B$97,IF(48<=36,'前提'!$B$98,IF(48<=48,'前提'!$B$99,'前提'!$B$100))))))) | AX34: ='前提'!$B$41*(IF(49<=6,'前提'!$B$94,IF(49<=12,'前提'!$B$95,IF(49<=18,'前提'!$B$96,IF(49<=24,'前提'!$B$97,IF(49<=36,'前提'!$B$98,IF(49<=48,'前提'!$B$99,'前提'!$B$100))))))) | AY34: ='前提'!$B$41*(IF(50<=6,'前提'!$B$94,IF(50<=12,'前提'!$B$95,IF(50<=18,'前提'!$B$96,IF(50<=24,'前提'!$B$97,IF(50<=36,'前提'!$B$98,IF(50<=48,'前提'!$B$99,'前提'!$B$100))))))) | AZ34: ='前提'!$B$41*(IF(51<=6,'前提'!$B$94,IF(51<=12,'前提'!$B$95,IF(51<=18,'前提'!$B$96,IF(51<=24,'前提'!$B$97,IF(51<=36,'前提'!$B$98,IF(51<=48,'前提'!$B$99,'前提'!$B$100))))))) | BA34: ='前提'!$B$41*(IF(52<=6,'前提'!$B$94,IF(52<=12,'前提'!$B$95,IF(52<=18,'前提'!$B$96,IF(52<=24,'前提'!$B$97,IF(52<=36,'前提'!$B$98,IF(52<=48,'前提'!$B$99,'前提'!$B$100))))))) | BB34: ='前提'!$B$41*(IF(53<=6,'前提'!$B$94,IF(53<=12,'前提'!$B$95,IF(53<=18,'前提'!$B$96,IF(53<=24,'前提'!$B$97,IF(53<=36,'前提'!$B$98,IF(53<=48,'前提'!$B$99,'前提'!$B$100))))))) | BC34: ='前提'!$B$41*(IF(54<=6,'前提'!$B$94,IF(54<=12,'前提'!$B$95,IF(54<=18,'前提'!$B$96,IF(54<=24,'前提'!$B$97,IF(54<=36,'前提'!$B$98,IF(54<=48,'前提'!$B$99,'前提'!$B$100))))))) | BD34: ='前提'!$B$41*(IF(55<=6,'前提'!$B$94,IF(55<=12,'前提'!$B$95,IF(55<=18,'前提'!$B$96,IF(55<=24,'前提'!$B$97,IF(55<=36,'前提'!$B$98,IF(55<=48,'前提'!$B$99,'前提'!$B$100))))))) | BE34: ='前提'!$B$41*(IF(56<=6,'前提'!$B$94,IF(56<=12,'前提'!$B$95,IF(56<=18,'前提'!$B$96,IF(56<=24,'前提'!$B$97,IF(56<=36,'前提'!$B$98,IF(56<=48,'前提'!$B$99,'前提'!$B$100))))))) | BF34: ='前提'!$B$41*(IF(57<=6,'前提'!$B$94,IF(57<=12,'前提'!$B$95,IF(57<=18,'前提'!$B$96,IF(57<=24,'前提'!$B$97,IF(57<=36,'前提'!$B$98,IF(57<=48,'前提'!$B$99,'前提'!$B$100))))))) | BG34: ='前提'!$B$41*(IF(58<=6,'前提'!$B$94,IF(58<=12,'前提'!$B$95,IF(58<=18,'前提'!$B$96,IF(58<=24,'前提'!$B$97,IF(58<=36,'前提'!$B$98,IF(58<=48,'前提'!$B$99,'前提'!$B$100))))))) | BH34: ='前提'!$B$41*(IF(59<=6,'前提'!$B$94,IF(59<=12,'前提'!$B$95,IF(59<=18,'前提'!$B$96,IF(59<=24,'前提'!$B$97,IF(59<=36,'前提'!$B$98,IF(59<=48,'前提'!$B$99,'前提'!$B$100))))))) | BI34: ='前提'!$B$41*(IF(60<=6,'前提'!$B$94,IF(60<=12,'前提'!$B$95,IF(60<=18,'前提'!$B$96,IF(60<=24,'前提'!$B$97,IF(60<=36,'前提'!$B$98,IF(60<=48,'前提'!$B$99,'前提'!$B$100)))))))
A35: BPO事務長 | B35: =IF(1>=7,CEILING(B14/'前提'!$B$29,1)*'前提'!$B$39,0) | C35: =IF(2>=7,CEILING(C14/'前提'!$B$29,1)*'前提'!$B$39,0) | D35: =IF(3>=7,CEILING(D14/'前提'!$B$29,1)*'前提'!$B$39,0) | E35: =IF(4>=7,CEILING(E14/'前提'!$B$29,1)*'前提'!$B$39,0) | F35: =IF(5>=7,CEILING(F14/'前提'!$B$29,1)*'前提'!$B$39,0) | G35: =IF(6>=7,CEILING(G14/'前提'!$B$29,1)*'前提'!$B$39,0) | H35: =IF(7>=7,CEILING(H14/'前提'!$B$29,1)*'前提'!$B$39,0) | I35: =IF(8>=7,CEILING(I14/'前提'!$B$29,1)*'前提'!$B$39,0) | J35: =IF(9>=7,CEILING(J14/'前提'!$B$29,1)*'前提'!$B$39,0) | K35: =IF(10>=7,CEILING(K14/'前提'!$B$29,1)*'前提'!$B$39,0) | L35: =IF(11>=7,CEILING(L14/'前提'!$B$29,1)*'前提'!$B$39,0) | M35: =IF(12>=7,CEILING(M14/'前提'!$B$29,1)*'前提'!$B$39,0) | N35: =IF(13>=7,CEILING(N14/'前提'!$B$29,1)*'前提'!$B$39,0) | O35: =IF(14>=7,CEILING(O14/'前提'!$B$29,1)*'前提'!$B$39,0) | P35: =IF(15>=7,CEILING(P14/'前提'!$B$29,1)*'前提'!$B$39,0) | Q35: =IF(16>=7,CEILING(Q14/'前提'!$B$29,1)*'前提'!$B$39,0) | R35: =IF(17>=7,CEILING(R14/'前提'!$B$29,1)*'前提'!$B$39,0) | S35: =IF(18>=7,CEILING(S14/'前提'!$B$29,1)*'前提'!$B$39,0) | T35: =IF(19>=7,CEILING(T14/'前提'!$B$29,1)*'前提'!$B$39,0) | U35: =IF(20>=7,CEILING(U14/'前提'!$B$29,1)*'前提'!$B$39,0) | V35: =IF(21>=7,CEILING(V14/'前提'!$B$29,1)*'前提'!$B$39,0) | W35: =IF(22>=7,CEILING(W14/'前提'!$B$29,1)*'前提'!$B$39,0) | X35: =IF(23>=7,CEILING(X14/'前提'!$B$29,1)*'前提'!$B$39,0) | Y35: =IF(24>=7,CEILING(Y14/'前提'!$B$29,1)*'前提'!$B$39,0) | Z35: =IF(25>=7,CEILING(Z14/'前提'!$B$29,1)*'前提'!$B$39,0) | AA35: =IF(26>=7,CEILING(AA14/'前提'!$B$29,1)*'前提'!$B$39,0) | AB35: =IF(27>=7,CEILING(AB14/'前提'!$B$29,1)*'前提'!$B$39,0) | AC35: =IF(28>=7,CEILING(AC14/'前提'!$B$29,1)*'前提'!$B$39,0) | AD35: =IF(29>=7,CEILING(AD14/'前提'!$B$29,1)*'前提'!$B$39,0) | AE35: =IF(30>=7,CEILING(AE14/'前提'!$B$29,1)*'前提'!$B$39,0) | AF35: =IF(31>=7,CEILING(AF14/'前提'!$B$29,1)*'前提'!$B$39,0) | AG35: =IF(32>=7,CEILING(AG14/'前提'!$B$29,1)*'前提'!$B$39,0) | AH35: =IF(33>=7,CEILING(AH14/'前提'!$B$29,1)*'前提'!$B$39,0) | AI35: =IF(34>=7,CEILING(AI14/'前提'!$B$29,1)*'前提'!$B$39,0) | AJ35: =IF(35>=7,CEILING(AJ14/'前提'!$B$29,1)*'前提'!$B$39,0) | AK35: =IF(36>=7,CEILING(AK14/'前提'!$B$29,1)*'前提'!$B$39,0) | AL35: =IF(37>=7,CEILING(AL14/'前提'!$B$29,1)*'前提'!$B$39,0) | AM35: =IF(38>=7,CEILING(AM14/'前提'!$B$29,1)*'前提'!$B$39,0) | AN35: =IF(39>=7,CEILING(AN14/'前提'!$B$29,1)*'前提'!$B$39,0) | AO35: =IF(40>=7,CEILING(AO14/'前提'!$B$29,1)*'前提'!$B$39,0) | AP35: =IF(41>=7,CEILING(AP14/'前提'!$B$29,1)*'前提'!$B$39,0) | AQ35: =IF(42>=7,CEILING(AQ14/'前提'!$B$29,1)*'前提'!$B$39,0) | AR35: =IF(43>=7,CEILING(AR14/'前提'!$B$29,1)*'前提'!$B$39,0) | AS35: =IF(44>=7,CEILING(AS14/'前提'!$B$29,1)*'前提'!$B$39,0) | AT35: =IF(45>=7,CEILING(AT14/'前提'!$B$29,1)*'前提'!$B$39,0) | AU35: =IF(46>=7,CEILING(AU14/'前提'!$B$29,1)*'前提'!$B$39,0) | AV35: =IF(47>=7,CEILING(AV14/'前提'!$B$29,1)*'前提'!$B$39,0) | AW35: =IF(48>=7,CEILING(AW14/'前提'!$B$29,1)*'前提'!$B$39,0) | AX35: =IF(49>=7,CEILING(AX14/'前提'!$B$29,1)*'前提'!$B$39,0) | AY35: =IF(50>=7,CEILING(AY14/'前提'!$B$29,1)*'前提'!$B$39,0) | AZ35: =IF(51>=7,CEILING(AZ14/'前提'!$B$29,1)*'前提'!$B$39,0) | BA35: =IF(52>=7,CEILING(BA14/'前提'!$B$29,1)*'前提'!$B$39,0) | BB35: =IF(53>=7,CEILING(BB14/'前提'!$B$29,1)*'前提'!$B$39,0) | BC35: =IF(54>=7,CEILING(BC14/'前提'!$B$29,1)*'前提'!$B$39,0) | BD35: =IF(55>=7,CEILING(BD14/'前提'!$B$29,1)*'前提'!$B$39,0) | BE35: =IF(56>=7,CEILING(BE14/'前提'!$B$29,1)*'前提'!$B$39,0) | BF35: =IF(57>=7,CEILING(BF14/'前提'!$B$29,1)*'前提'!$B$39,0) | BG35: =IF(58>=7,CEILING(BG14/'前提'!$B$29,1)*'前提'!$B$39,0) | BH35: =IF(59>=7,CEILING(BH14/'前提'!$B$29,1)*'前提'!$B$39,0) | BI35: =IF(60>=7,CEILING(BI14/'前提'!$B$29,1)*'前提'!$B$39,0)
